<robot
  name="PONGBOT_Q_V1">
  <link
    name="REAR_BODY">
    <inertial>
      <origin
        xyz="0.1148 0.002 0.0148"
        rpy="0 0 0" />
      <mass
        value="11.1272" />
      <inertia
        ixx="0.1226"
        ixy="0.0038"
        ixz="-0.0088"
        iyy="0.1436"
        iyz="-0.0012"
        izz="0.2321" />
    </inertial>
    <visual>
      <origin
        xyz="0 0 0"
        rpy="0 0 0" />
      <geometry>
        <mesh
          filename="package://PONGBOT_Q_V1/meshes/REAR_BODY.STL" />
      </geometry>
      <material
        name="">
        <color
          rgba="0.79216 0.81961 0.93333 1" />
      </material>
    </visual>
    <collision>
      <origin
        xyz="0 0 0"
        rpy="0 0 0" />
      <geometry>
        <mesh
          filename="package://PONGBOT_Q_V1/meshes/REAR_BODY.STL" />
      </geometry>
    </collision>
  </link>
  <link
    name="FRONT_BODY">
    <inertial>
      <origin
        xyz="0.2333 -0.0003 -0.0078"
        rpy="0 0 0" />
      <mass
        value="12.2749" />
      <inertia
        ixx="0.1398"
        ixy="0.0001"
        ixz="-0.0097"
        iyy="0.1334"
        iyz="0"
        izz="0.2186" />
    </inertial>
    <visual>
      <origin
        xyz="0 0 0"
        rpy="0 0 0" />
      <geometry>
        <mesh
          filename="package://PONGBOT_Q_V1/meshes/FRONT_BODY.STL" />
      </geometry>
      <material
        name="">
        <color
          rgba="0.19608 0.19608 0.19608 1" />
      </material>
    </visual>
    <collision>
      <origin
        xyz="0 0 0"
        rpy="0 0 0" />
      <geometry>
        <mesh
          filename="package://PONGBOT_Q_V1/meshes/FRONT_BODY.STL" />
      </geometry>
    </collision>
  </link>
  <joint
    name="WAIST_JOINT"
    type="continuous">
    <origin
      xyz="0.349999861844157 0 0.0352383027140765"
      rpy="9.86076131526265E-32 -1.06745632209058E-30 3.94430452610506E-31" />
    <parent
      link="REAR_BODY" />
    <child
      link="FRONT_BODY" />
    <axis
      xyz="0 0 0.999999999992314" />
  </joint>
  <link
    name="FL_HIP">
    <inertial>
      <origin
        xyz="0.0009 0.0001 -0.0002"
        rpy="0 0 0" />
      <mass
        value="1.1163" />
      <inertia
        ixx="0.0011"
        ixy="0"
        ixz="0"
        iyy="0.0012"
        iyz="0"
        izz="0.0012" />
    </inertial>
    <visual>
      <origin
        xyz="0 0 0"
        rpy="0 0 0" />
      <geometry>
        <mesh
          filename="package://PONGBOT_Q_V1/meshes/FL_HIP.STL" />
      </geometry>
      <material
        name="">
        <color
          rgba="0.75294 0.75294 0.75294 1" />
      </material>
    </visual>
    <collision>
      <origin
        xyz="0 0 0"
        rpy="0 0 0" />
      <geometry>
        <mesh
          filename="package://PONGBOT_Q_V1/meshes/FL_HIP.STL" />
      </geometry>
    </collision>
  </link>
  <joint
    name="FL_HIP_JOINT"
    type="continuous">
    <origin
      xyz="0.350000139384095 0.11502409051225 -0.0355502055156764"
      rpy="0 8.47032947254301E-22 2.10366195349206E-15" />
    <parent
      link="FRONT_BODY" />
    <child
      link="FL_HIP" />
    <axis
      xyz="-0.999999999992314 0 0" />
  </joint>
  <link
    name="FL_THIGH">
    <inertial>
      <origin
        xyz="0 -0.0162 -0.0264"
        rpy="0 0 0" />
      <mass
        value="1.8748" />
      <inertia
        ixx="0.0112"
        ixy="0"
        ixz="0"
        iyy="0.0117"
        iyz="-0.0008"
        izz="0.0017" />
    </inertial>
    <visual>
      <origin
        xyz="0 0 0"
        rpy="0 0 0" />
      <geometry>
        <mesh
          filename="package://PONGBOT_Q_V1/meshes/FL_THIGH.STL" />
      </geometry>
      <material
        name="">
        <color
          rgba="0.6 0.6 0.6 1" />
      </material>
    </visual>
    <collision>
      <origin
        xyz="0 0 0"
        rpy="0 0 0" />
      <geometry>
        <mesh
          filename="package://PONGBOT_Q_V1/meshes/FL_THIGH.STL" />
      </geometry>
    </collision>
  </link>
  <joint
    name="FL_THIGH_JOINT"
    type="continuous">
    <origin
      xyz="0 0.105 0"
      rpy="0 -8.47032948321757E-22 -2.10366195349206E-15" />
    <parent
      link="FL_HIP" />
    <child
      link="FL_THIGH" />
    <axis
      xyz="0 1 0" />
  </joint>
  <link
    name="FL_ROTATOR1">
    <inertial>
      <origin
        xyz="0.0021 -0.0028 -0.0058"
        rpy="0 0 0" />
      <mass
        value="0.072" />
      <inertia
        ixx="0.0001"
        ixy="0"
        ixz="0"
        iyy="0.0001"
        iyz="0"
        izz="0" />
    </inertial>
    <visual>
      <origin
        xyz="0 0 0"
        rpy="0 0 0" />
      <geometry>
        <mesh
          filename="package://PONGBOT_Q_V1/meshes/FL_ROTATOR1.STL" />
      </geometry>
      <material
        name="">
        <color
          rgba="0.89804 0.91765 0.92941 1" />
      </material>
    </visual>
    <collision>
      <origin
        xyz="0 0 0"
        rpy="0 0 0" />
      <geometry>
        <mesh
          filename="package://PONGBOT_Q_V1/meshes/FL_ROTATOR1.STL" />
      </geometry>
    </collision>
  </link>
  <joint
    name="FL_ROTATOR1_JOINT"
    type="continuous">
    <origin
      xyz="0 0.0276499999999884 0"
      rpy="9.86076131526265E-32 -1.06745632209058E-30 0" />
    <parent
      link="FL_THIGH" />
    <child
      link="FL_ROTATOR1" />
    <axis
      xyz="0 1 0" />
  </joint>
  <link
    name="FL_ROTATOR2">
    <inertial>
      <origin
        xyz="0 0 -0.1525"
        rpy="0 0 0" />
      <mass
        value="0.2047" />
      <inertia
        ixx="0.0018"
        ixy="0"
        ixz="0"
        iyy="0.0018"
        iyz="0"
        izz="0" />
    </inertial>
    <visual>
      <origin
        xyz="0 0 0"
        rpy="0 0 0" />
      <geometry>
        <mesh
          filename="package://PONGBOT_Q_V1/meshes/FL_ROTATOR2.STL" />
      </geometry>
      <material
        name="">
        <color
          rgba="0.64706 0.61961 0.58824 1" />
      </material>
    </visual>
    <collision>
      <origin
        xyz="0 0 0"
        rpy="0 0 0" />
      <geometry>
        <mesh
          filename="package://PONGBOT_Q_V1/meshes/FL_ROTATOR2.STL" />
      </geometry>
    </collision>
  </link>
  <joint
    name="FL_ROTATOR2_JOINT"
    type="continuous">
    <origin
      xyz="0.0171011913784916 0.00684999999999722 -0.0469845639911272"
      rpy="9.86076131526265E-32 -1.06745632209058E-30 0" />
    <parent
      link="FL_ROTATOR1" />
    <child
      link="FL_ROTATOR2" />
    <axis
      xyz="0 1 0" />
  </joint>
  <link
    name="FL_ROTATOR3">
    <inertial>
      <origin
        xyz="-0.0183 -0.0326 -0.0427"
        rpy="0 0 0" />
      <mass
        value="0.402" />
      <inertia
        ixx="0.0052"
        ixy="0"
        ixz="0.0002"
        iyy="0.0051"
        iyz="0"
        izz="0.0002" />
    </inertial>
    <visual>
      <origin
        xyz="0 0 0"
        rpy="0 0 0" />
      <geometry>
        <mesh
          filename="package://PONGBOT_Q_V1/meshes/FL_ROTATOR3.STL" />
      </geometry>
      <material
        name="">
        <color
          rgba="0.22353 0.22353 0.22353 1" />
      </material>
    </visual>
    <collision>
      <origin
        xyz="0 0 0"
        rpy="0 0 0" />
      <geometry>
        <mesh
          filename="package://PONGBOT_Q_V1/meshes/FL_ROTATOR3.STL" />
      </geometry>
    </collision>
  </link>
  <joint
    name="FL_ROTATOR3_JOINT"
    type="continuous">
    <origin
      xyz="0 0 -0.304999999997681"
      rpy="9.86076131526265E-32 -1.06745632209058E-30 0" />
    <parent
      link="FL_ROTATOR2" />
    <child
      link="FL_ROTATOR3" />
    <axis
      xyz="0 1 0" />
  </joint>
  <link
    name="FR_HIP">
    <inertial>
      <origin
        xyz="0.0009 -0.0001 0.0002"
        rpy="0 0 0" />
      <mass
        value="1.1163" />
      <inertia
        ixx="0.0011"
        ixy="0"
        ixz="0"
        iyy="0.0012"
        iyz="0"
        izz="0.0012" />
    </inertial>
    <visual>
      <origin
        xyz="0 0 0"
        rpy="0 0 0" />
      <geometry>
        <mesh
          filename="package://PONGBOT_Q_V1/meshes/FR_HIP.STL" />
      </geometry>
      <material
        name="">
        <color
          rgba="0.75294 0.75294 0.75294 1" />
      </material>
    </visual>
    <collision>
      <origin
        xyz="0 0 0"
        rpy="0 0 0" />
      <geometry>
        <mesh
          filename="package://PONGBOT_Q_V1/meshes/FR_HIP.STL" />
      </geometry>
    </collision>
  </link>
  <joint
    name="FR_HIP_JOINT"
    type="continuous">
    <origin
      xyz="0.350000139384098 -0.115024090512249 -0.0355502055156748"
      rpy="9.86076131526265E-32 -1.06745632209058E-30 -3.94430452610506E-31" />
    <parent
      link="FRONT_BODY" />
    <child
      link="FR_HIP" />
    <axis
      xyz="-0.999999999992314 0 0" />
  </joint>
  <link
    name="FR_THIGH">
    <inertial>
      <origin
        xyz="0 0.0162 -0.0264"
        rpy="0 0 0" />
      <mass
        value="1.8748" />
      <inertia
        ixx="0.0112"
        ixy="0"
        ixz="0"
        iyy="0.0117"
        iyz="0.0008"
        izz="0.0017" />
    </inertial>
    <visual>
      <origin
        xyz="0 0 0"
        rpy="0 0 0" />
      <geometry>
        <mesh
          filename="package://PONGBOT_Q_V1/meshes/FR_THIGH.STL" />
      </geometry>
      <material
        name="">
        <color
          rgba="0.75294 0.75294 0.75294 1" />
      </material>
    </visual>
    <collision>
      <origin
        xyz="0 0 0"
        rpy="0 0 0" />
      <geometry>
        <mesh
          filename="package://PONGBOT_Q_V1/meshes/FR_THIGH.STL" />
      </geometry>
    </collision>
  </link>
  <joint
    name="FR_THIGH_JOINT"
    type="continuous">
    <origin
      xyz="0 -0.104999999999998 0"
      rpy="9.86076131526265E-32 -1.06745632209058E-30 0" />
    <parent
      link="FR_HIP" />
    <child
      link="FR_THIGH" />
    <axis
      xyz="0 1 0" />
  </joint>
  <link
    name="FR_ROTATOR1">
    <inertial>
      <origin
        xyz="0.0021 0.0028 -0.0058"
        rpy="0 0 0" />
      <mass
        value="0.072" />
      <inertia
        ixx="0.0001"
        ixy="0"
        ixz="0"
        iyy="0.0001"
        iyz="0"
        izz="0" />
    </inertial>
    <visual>
      <origin
        xyz="0 0 0"
        rpy="0 0 0" />
      <geometry>
        <mesh
          filename="package://PONGBOT_Q_V1/meshes/FR_ROTATOR1.STL" />
      </geometry>
      <material
        name="">
        <color
          rgba="0.89804 0.91765 0.92941 1" />
      </material>
    </visual>
    <collision>
      <origin
        xyz="0 0 0"
        rpy="0 0 0" />
      <geometry>
        <mesh
          filename="package://PONGBOT_Q_V1/meshes/FR_ROTATOR1.STL" />
      </geometry>
    </collision>
  </link>
  <joint
    name="FR_ROTATOR1_JOINT"
    type="continuous">
    <origin
      xyz="0 -0.0276499999999846 0"
      rpy="9.86076131526265E-32 -1.06745632209058E-30 3.94430452610506E-31" />
    <parent
      link="FR_THIGH" />
    <child
      link="FR_ROTATOR1" />
    <axis
      xyz="0 1 0" />
  </joint>
  <link
    name="FR_ROTATOR2">
    <inertial>
      <origin
        xyz="0 0 -0.1525"
        rpy="0 0 0" />
      <mass
        value="0.2047" />
      <inertia
        ixx="0.0018"
        ixy="0"
        ixz="0"
        iyy="0.0018"
        iyz="0"
        izz="0" />
    </inertial>
    <visual>
      <origin
        xyz="0 0 0"
        rpy="0 0 0" />
      <geometry>
        <mesh
          filename="package://PONGBOT_Q_V1/meshes/FR_ROTATOR2.STL" />
      </geometry>
      <material
        name="">
        <color
          rgba="0.64706 0.61961 0.58824 1" />
      </material>
    </visual>
    <collision>
      <origin
        xyz="0 0 0"
        rpy="0 0 0" />
      <geometry>
        <mesh
          filename="package://PONGBOT_Q_V1/meshes/FR_ROTATOR2.STL" />
      </geometry>
    </collision>
  </link>
  <joint
    name="FR_ROTATOR2_JOINT"
    type="continuous">
    <origin
      xyz="0.0171011913784889 -0.00684999999999969 -0.0469845639911275"
      rpy="9.86076131526265E-32 -1.06745632209058E-30 -3.94430452610506E-31" />
    <parent
      link="FR_ROTATOR1" />
    <child
      link="FR_ROTATOR2" />
    <axis
      xyz="0 1 0" />
  </joint>
  <link
    name="FR_ROTATOR3">
    <inertial>
      <origin
        xyz="-0.0179 0.0326 -0.0427"
        rpy="0 0 0" />
      <mass
        value="0.402" />
      <inertia
        ixx="0.0052"
        ixy="0"
        ixz="0.0002"
        iyy="0.0051"
        iyz="0"
        izz="0.0002" />
    </inertial>
    <visual>
      <origin
        xyz="0 0 0"
        rpy="0 0 0" />
      <geometry>
        <mesh
          filename="package://PONGBOT_Q_V1/meshes/FR_ROTATOR3.STL" />
      </geometry>
      <material
        name="">
        <color
          rgba="0.75294 0.75294 0.75294 1" />
      </material>
    </visual>
    <collision>
      <origin
        xyz="0 0 0"
        rpy="0 0 0" />
      <geometry>
        <mesh
          filename="package://PONGBOT_Q_V1/meshes/FR_ROTATOR3.STL" />
      </geometry>
    </collision>
  </link>
  <joint
    name="FR_ROTATOR3_JOINT"
    type="continuous">
    <origin
      xyz="0 0 -0.304999999997682"
      rpy="9.86076131526265E-32 -1.06745632209058E-30 0" />
    <parent
      link="FR_ROTATOR2" />
    <child
      link="FR_ROTATOR3" />
    <axis
      xyz="0 1 0" />
  </joint>
  <link
    name="RL_HIP">
    <inertial>
      <origin
        xyz="-0.0009 0.0001 0.0002"
        rpy="0 0 0" />
      <mass
        value="1.1163" />
      <inertia
        ixx="0.0011"
        ixy="0"
        ixz="0"
        iyy="0.0012"
        iyz="0"
        izz="0.0012" />
    </inertial>
    <visual>
      <origin
        xyz="0 0 0"
        rpy="0 0 0" />
      <geometry>
        <mesh
          filename="package://PONGBOT_Q_V1/meshes/RL_HIP.STL" />
      </geometry>
      <material
        name="">
        <color
          rgba="0.75294 0.75294 0.75294 1" />
      </material>
    </visual>
    <collision>
      <origin
        xyz="0 0 0"
        rpy="0 0 0" />
      <geometry>
        <mesh
          filename="package://PONGBOT_Q_V1/meshes/RL_HIP.STL" />
      </geometry>
    </collision>
  </link>
  <joint
    name="RL_HIP_JOINT"
    type="continuous">
    <origin
      xyz="0 0.115024090512224 -0.000314647285989393"
      rpy="9.86076131526265E-32 -1.06745632209058E-30 0" />
    <parent
      link="REAR_BODY" />
    <child
      link="RL_HIP" />
    <axis
      xyz="-0.999999999992314 0 0" />
  </joint>
  <link
    name="RL_THIGH">
    <inertial>
      <origin
        xyz="0 -0.0161 -0.0264"
        rpy="0 0 0" />
      <mass
        value="1.8748" />
      <inertia
        ixx="0.0112"
        ixy="0"
        ixz="0"
        iyy="0.0117"
        iyz="-0.0008"
        izz="0.0017" />
    </inertial>
    <visual>
      <origin
        xyz="0 0 0"
        rpy="0 0 0" />
      <geometry>
        <mesh
          filename="package://PONGBOT_Q_V1/meshes/RL_THIGH.STL" />
      </geometry>
      <material
        name="">
        <color
          rgba="0.6 0.6 0.6 1" />
      </material>
    </visual>
    <collision>
      <origin
        xyz="0 0 0"
        rpy="0 0 0" />
      <geometry>
        <mesh
          filename="package://PONGBOT_Q_V1/meshes/RL_THIGH.STL" />
      </geometry>
    </collision>
  </link>
  <joint
    name="RL_THIGH_JOINT"
    type="continuous">
    <origin
      xyz="0 0.10499960714959 0.000287225408803455"
      rpy="9.86076131526265E-32 -1.06745632209058E-30 0" />
    <parent
      link="RL_HIP" />
    <child
      link="RL_THIGH" />
    <axis
      xyz="0 0.999996258567356 0.00273548008383928" />
  </joint>
  <link
    name="RL_ROTATOR1">
    <inertial>
      <origin
        xyz="-0.0021 -0.0028 -0.0058"
        rpy="0 0 0" />
      <mass
        value="0.072" />
      <inertia
        ixx="0.0001"
        ixy="0"
        ixz="0"
        iyy="0.0001"
        iyz="0"
        izz="0" />
    </inertial>
    <visual>
      <origin
        xyz="0 0 0"
        rpy="0 0 0" />
      <geometry>
        <mesh
          filename="package://PONGBOT_Q_V1/meshes/RL_ROTATOR1.STL" />
      </geometry>
      <material
        name="">
        <color
          rgba="0.89804 0.91765 0.92941 1" />
      </material>
    </visual>
    <collision>
      <origin
        xyz="0 0 0"
        rpy="0 0 0" />
      <geometry>
        <mesh
          filename="package://PONGBOT_Q_V1/meshes/RL_ROTATOR1.STL" />
      </geometry>
    </collision>
  </link>
  <joint
    name="RL_ROTATOR1_JOINT"
    type="continuous">
    <origin
      xyz="0 0.0276498965493659 7.56360243180966E-05"
      rpy="9.86076131526265E-32 -1.06745632209058E-30 0" />
    <parent
      link="RL_THIGH" />
    <child
      link="RL_ROTATOR1" />
    <axis
      xyz="0 0.999996258567356 0.00273548008383955" />
  </joint>
  <link
    name="RL_ROTATOR2">
    <inertial>
      <origin
        xyz="0 0.0004 -0.1525"
        rpy="0 0 0" />
      <mass
        value="0.2047" />
      <inertia
        ixx="0.0018"
        ixy="0"
        ixz="0"
        iyy="0.0018"
        iyz="0"
        izz="0" />
    </inertial>
    <visual>
      <origin
        xyz="0 0 0"
        rpy="0 0 0" />
      <geometry>
        <mesh
          filename="package://PONGBOT_Q_V1/meshes/RL_ROTATOR2.STL" />
      </geometry>
      <material
        name="">
        <color
          rgba="0.64706 0.61961 0.58824 1" />
      </material>
    </visual>
    <collision>
      <origin
        xyz="0 0 0"
        rpy="0 0 0" />
      <geometry>
        <mesh
          filename="package://PONGBOT_Q_V1/meshes/RL_ROTATOR2.STL" />
      </geometry>
    </collision>
  </link>
  <joint
    name="RL_ROTATOR2_JOINT"
    type="continuous">
    <origin
      xyz="-0.0171008230281334 0.00697849989361776 -0.0469657842582811"
      rpy="9.86076131526265E-32 -1.06745632209058E-30 0" />
    <parent
      link="RL_ROTATOR1" />
    <child
      link="RL_ROTATOR2" />
    <axis
      xyz="0 0.999996258567356 0.00273548008384041" />
  </joint>
  <link
    name="RL_ROTATOR3">
    <inertial>
      <origin
        xyz="0.0179 -0.0325 -0.0428"
        rpy="0 0 0" />
      <mass
        value="0.402" />
      <inertia
        ixx="0.0052"
        ixy="0"
        ixz="-0.002"
        iyy="0.0051"
        iyz="0"
        izz="0.002" />
    </inertial>
    <visual>
      <origin
        xyz="0 0 0"
        rpy="0 0 0" />
      <geometry>
        <mesh
          filename="package://PONGBOT_Q_V1/meshes/RL_ROTATOR3.STL" />
      </geometry>
      <material
        name="">
        <color
          rgba="0.79216 0.81961 0.93333 1" />
      </material>
    </visual>
    <collision>
      <origin
        xyz="0 0 0"
        rpy="0 0 0" />
      <geometry>
        <mesh
          filename="package://PONGBOT_Q_V1/meshes/RL_ROTATOR3.STL" />
      </geometry>
    </collision>
  </link>
  <joint
    name="RL_ROTATOR3_JOINT"
    type="continuous">
    <origin
      xyz="0 0.000834321425604079 -0.304998858860728"
      rpy="9.86076131526265E-32 -1.06745632209058E-30 0" />
    <parent
      link="RL_ROTATOR2" />
    <child
      link="RL_ROTATOR3" />
    <axis
      xyz="0 0.999996258567356 0.00273548008384001" />
  </joint>
  <link
    name="RR_HIP">
    <inertial>
      <origin
        xyz="-0.0009 -0.0001 -0.0002"
        rpy="0 0 0" />
      <mass
        value="1.1163" />
      <inertia
        ixx="0.0011"
        ixy="0"
        ixz="0"
        iyy="0.0012"
        iyz="0"
        izz="0.0012" />
    </inertial>
    <visual>
      <origin
        xyz="0 0 0"
        rpy="0 0 0" />
      <geometry>
        <mesh
          filename="package://PONGBOT_Q_V1/meshes/RR_HIP.STL" />
      </geometry>
      <material
        name="">
        <color
          rgba="0.75294 0.75294 0.75294 1" />
      </material>
    </visual>
    <collision>
      <origin
        xyz="0 0 0"
        rpy="0 0 0" />
      <geometry>
        <mesh
          filename="package://PONGBOT_Q_V1/meshes/RR_HIP.STL" />
      </geometry>
    </collision>
  </link>
  <joint
    name="RR_HIP_JOINT"
    type="continuous">
    <origin
      xyz="0 -0.11502409051226 -0.00031464728598948"
      rpy="9.86076131526265E-32 -1.06745632209058E-30 0" />
    <parent
      link="REAR_BODY" />
    <child
      link="RR_HIP" />
    <axis
      xyz="-0.999999999992314 0 0" />
  </joint>
  <link
    name="RR_THIGH">
    <inertial>
      <origin
        xyz="0 0.0163 -0.0263"
        rpy="0 0 0" />
      <mass
        value="1.8748" />
      <inertia
        ixx="0.0112"
        ixy="0"
        ixz="0"
        iyy="0.0117"
        iyz="0.0008"
        izz="0.0017" />
    </inertial>
    <visual>
      <origin
        xyz="0 0 0"
        rpy="0 0 0" />
      <geometry>
        <mesh
          filename="package://PONGBOT_Q_V1/meshes/RR_THIGH.STL" />
      </geometry>
      <material
        name="">
        <color
          rgba="0.89804 0.91765 0.92941 1" />
      </material>
    </visual>
    <collision>
      <origin
        xyz="0 0 0"
        rpy="0 0 0" />
      <geometry>
        <mesh
          filename="package://PONGBOT_Q_V1/meshes/RR_THIGH.STL" />
      </geometry>
    </collision>
  </link>
  <joint
    name="RR_THIGH_JOINT"
    type="continuous">
    <origin
      xyz="0 -0.10499960714956 -0.000287225408803039"
      rpy="9.86076131526265E-32 -1.06745632209058E-30 0" />
    <parent
      link="RR_HIP" />
    <child
      link="RR_THIGH" />
    <axis
      xyz="0 0.999996258567356 0.00273548008383845" />
  </joint>
  <link
    name="RR_ROTATOR1">
    <inertial>
      <origin
        xyz="-0.0021 0.0029 -0.0058"
        rpy="0 0 0" />
      <mass
        value="0.072" />
      <inertia
        ixx="0.0001"
        ixy="0"
        ixz="0"
        iyy="0.0001"
        iyz="0"
        izz="0" />
    </inertial>
    <visual>
      <origin
        xyz="0 0 0"
        rpy="0 0 0" />
      <geometry>
        <mesh
          filename="package://PONGBOT_Q_V1/meshes/RR_ROTATOR1.STL" />
      </geometry>
      <material
        name="">
        <color
          rgba="0.89804 0.91765 0.92941 1" />
      </material>
    </visual>
    <collision>
      <origin
        xyz="0 0 0"
        rpy="0 0 0" />
      <geometry>
        <mesh
          filename="package://PONGBOT_Q_V1/meshes/RR_ROTATOR1.STL" />
      </geometry>
    </collision>
  </link>
  <joint
    name="RR_ROTATOR1_JOINT"
    type="continuous">
    <origin
      xyz="0 -0.0276498965493697 -7.56360243180827E-05"
      rpy="9.86076131526265E-32 -1.06745632209058E-30 0" />
    <parent
      link="RR_THIGH" />
    <child
      link="RR_ROTATOR1" />
    <axis
      xyz="0 0.999996258567356 0.00273548008383831" />
  </joint>
  <link
    name="RR_ROTATOR2">
    <inertial>
      <origin
        xyz="0 0.0004 -0.1525"
        rpy="0 0 0" />
      <mass
        value="0.2047" />
      <inertia
        ixx="0.0018"
        ixy="0"
        ixz="0"
        iyy="0.0018"
        iyz="0"
        izz="0" />
    </inertial>
    <visual>
      <origin
        xyz="0 0 0"
        rpy="0 0 0" />
      <geometry>
        <mesh
          filename="package://PONGBOT_Q_V1/meshes/RR_ROTATOR2.STL" />
      </geometry>
      <material
        name="">
        <color
          rgba="0.64706 0.61961 0.58824 1" />
      </material>
    </visual>
    <collision>
      <origin
        xyz="0 0 0"
        rpy="0 0 0" />
      <geometry>
        <mesh
          filename="package://PONGBOT_Q_V1/meshes/RR_ROTATOR2.STL" />
      </geometry>
    </collision>
  </link>
  <joint
    name="RR_ROTATOR2_JOINT"
    type="continuous">
    <origin
      xyz="-0.0171008228811629 -0.00672144884875131 -0.0470032603354323"
      rpy="9.86076131526265E-32 -1.06745632209058E-30 0" />
    <parent
      link="RR_ROTATOR1" />
    <child
      link="RR_ROTATOR2" />
    <axis
      xyz="0 0.999996258567356 0.00273548008384041" />
  </joint>
  <link
    name="RR_ROTATOR3">
    <inertial>
      <origin
        xyz="0.0183 0.0327 -0.0426"
        rpy="0 0 0" />
      <mass
        value="0.402" />
      <inertia
        ixx="0.0052"
        ixy="0"
        ixz="-0.0002"
        iyy="0.0051"
        iyz="-0.0001"
        izz="0.0002" />
    </inertial>
    <visual>
      <origin
        xyz="0 0 0"
        rpy="0 0 0" />
      <geometry>
        <mesh
          filename="package://PONGBOT_Q_V1/meshes/RR_ROTATOR3.STL" />
      </geometry>
      <material
        name="">
        <color
          rgba="0.75294 0.75294 0.75294 1" />
      </material>
    </visual>
    <collision>
      <origin
        xyz="0 0 0"
        rpy="0 0 0" />
      <geometry>
        <mesh
          filename="package://PONGBOT_Q_V1/meshes/RR_ROTATOR3.STL" />
      </geometry>
    </collision>
  </link>
  <joint
    name="RR_ROTATOR3_JOINT"
    type="continuous">
    <origin
      xyz="0 0.000834321425605467 -0.304998858860725"
      rpy="9.86076131526265E-32 -1.06745632209058E-30 0" />
    <parent
      link="RR_ROTATOR2" />
    <child
      link="RR_ROTATOR3" />
    <axis
      xyz="0 0.999996258567356 0.00273548008383997" />
  </joint>
</robot>