<?xml version="1.0"?>
<sdf version='1.6'>
  <model name='Segway_Roboticslab_v2H'>
    <link name='KUDOS_body'>
      <pose frame=''>0 0 0 0 -0 0</pose>
      <inertial>
        <pose frame=''>0 0 0.14 0 -0 0</pose>
        <mass>37.65</mass>
        <inertia>
          <ixx>4.97</ixx>
          <ixy>0.00</ixy>
          <ixz>-0.00</ixz>
          <iyy>4.64</iyy>
          <iyz>-0.00</iyz>
          <izz>0.82</izz>
        </inertia>
      </inertial>
      <!--<collision name='KUDOS_body_collision'>
        <pose frame=''>0 0 0 0 -0 0</pose>
        <geometry>
          <mesh>
            <scale>1 1 1</scale>
            <uri>model://Segway_Roboticslab_v2H/meshes/KUDOS_body.STL</uri>
          </mesh>
        </geometry>
      </collision>-->
      <visual name='KUDOS_body_visual'>
        <pose frame=''>0 0 0 0 -0 0</pose>
        <geometry>
          <mesh>
            <scale>1 1 1</scale>
            <uri>model://Segway_Roboticslab_v2H/meshes/KUDOS_body.STL</uri>
          </mesh>
        </geometry>
      </visual>
      <sensor name='KUDOS_IMU' type='imu'>
	<pose frame=''>0 0 0.14 0 -0 0</pose>
	  <imu>
	    <angular_velocity>
	      <x>
	        <noise type='none'></noise>
	      </x>
	      <y>
	        <noise type='none'></noise>
	      </y>
	      <z>
	        <noise type='none'></noise>
	      </z>
            </angular_velocity>
	    <linear_acceleration>
	      <x>
	        <noise type='none'></noise>
	      </x>
	      <y>
	        <noise type="none"></noise>
	      </y>
	      <z>
	        <noise type='none'></noise>
	      </z>
	    </linear_acceleration>
	  </imu>
	<always_on>1</always_on>
	<update_rate>1000</update_rate>
	<visualize>true</visualize>
      </sensor>	
    </link>
    <link name='KUDOS_wheel1'>
      <pose frame=''>0 0.274 0 -3.14159 1.4851 -3.14159</pose>
      <inertial>
        <pose frame=''>0 0.011823 0 0 -0 0</pose>
        <mass>0.84888</mass>
        <inertia>
          <ixx>0.010817</ixx>
          <ixy>0</ixy>
          <ixz>0</ixz>
          <iyy>0.021479</iyy>
          <iyz>0</iyz>
          <izz>0.010817</izz>
        </inertia>
      </inertial>
      <collision name='KUDOS_wheel1_collision'>
        <pose frame=''>0 0.011823 0 -1.57079632679 -0 0</pose>
        <geometry>
          <cylinder>
            <radius>0.1925</radius>
            <length>0.034</length>
          </cylinder>
        </geometry>
      </collision>
      <visual name='KUDOS_wheel1_visual'>
        <pose frame=''>0 0 0 0 -0 0</pose>
        <geometry>
          <mesh>
            <scale>1 1 1</scale>
            <uri>model://Segway_Roboticslab_v2H/meshes/KUDOS_wheel1.STL</uri>
          </mesh>
        </geometry>
      </visual>
    </link>
    <joint name='KUDOS_wheel1shaft' type='revolute'>
      <child>KUDOS_wheel1</child>
      <parent>KUDOS_body</parent>
      <axis>
        <xyz>0 -1 1e-06</xyz>
        <limit>
          <lower>-1e+16</lower>
          <upper>1e+16</upper>
          <effort>1000</effort>
          <velocity>0</velocity>
        </limit>
        <dynamics>
          <spring_reference>0</spring_reference>
          <spring_stiffness>0</spring_stiffness>
        </dynamics>
        <use_parent_model_frame>1</use_parent_model_frame>
      </axis>
    </joint>
    <link name='KUDOS_wheel2'>
      <pose frame=''>0 -0.274 0 -0 1.4851 3.14159</pose>
      <inertial>
        <pose frame=''>0 0.011823 0 0 -0 0</pose>
        <mass>0.84888</mass>
        <inertia>
          <ixx>0.010817</ixx>
          <ixy>0</ixy>
          <ixz>0</ixz>
          <iyy>0.021479</iyy>
          <iyz>0</iyz>
          <izz>0.010817</izz>
        </inertia>
      </inertial>1.2
      <collision name='KUDOS_wheel2_collision'>
        <pose frame=''>0 0.011823 0 -1.57079632679 -0 0</pose>
        <geometry>
          <cylinder>
            <radius>0.1925</radius>
            <length>0.034</length>
          </cylinder>
        </geometry>
      </collision>
      <visual name='KUDOS_wheel2_visual'>
        <pose frame=''>0 0 0 0 -0 0</pose>
        <geometry>
          <mesh>
            <scale>1 1 1</scale>
            <uri>model://Segway_Roboticslab_v2H/meshes/KUDOS_wheel2.STL</uri>
          </mesh>
        </geometry>
      </visual>
    </link>
    <joint name='KUDOS_wheel2shaft' type='revolute'>
      <child>KUDOS_wheel2</child>
      <parent>KUDOS_body</parent>
      <axis>
        <xyz>7e-06 1 0</xyz>
        <limit>
          <lower>-1e+16</lower>
          <upper>1e+16</upper>
	  <effort>1000</effort>
          <velocity>0</velocity>
        </limit>
        <dynamics>
          <spring_reference>0</spring_reference>
          <spring_stiffness>0</spring_stiffness>
        </dynamics>
        <use_parent_model_frame>1</use_parent_model_frame>
      </axis>
    </joint>
  </model>
</sdf>
