<sdf version='1.6'>
  <model name='SLAVE_ARM2'>

    <joint name="fixed to ground" type="fixed">
      <parent>world</parent>
      <child>BASE</child>
    </joint>

    <link name='BASE'>
      <pose frame=''>0 0 0 0 -0 0</pose>
      <inertial>
        <pose frame=''>0.29533 -0.048851 0.1022 0 -0 0</pose>
        <mass>18.677</mass>
        <inertia>
          <ixx>0.46316</ixx>
          <ixy>-0.017348</ixy>
          <ixz>0</ixz>
          <iyy>0.78313</iyy>
          <iyz>0</iyz>
          <izz>0.97746</izz>
        </inertia>
      </inertial>
      <collision name='BASE_collision'>
        <pose frame=''>0 0 0 0 -0 0</pose>
        <geometry>
          <mesh>
            <scale>1 1 1</scale>
            <uri>model://SLAVE_ARM2/meshes/BASE.STL</uri>
          </mesh>
        </geometry>
      </collision>
      <visual name='BASE_visual'>
        <pose frame=''>0 0 0 0 -0 0</pose>
        <geometry>
          <mesh>
            <scale>1 1 1</scale>
            <uri>model://SLAVE_ARM2/meshes/BASE.STL</uri>
          </mesh>
        </geometry>
      </visual>
    </link>
    <link name='LINK1'>
      <pose frame=''>0.608 -0.052 0.111 0 -0 0</pose>
      <inertial>
        <pose frame=''>0.11039 -0.013719 0.018917 0 -0 0</pose>
        <mass>10.337</mass>
        <inertia>
          <ixx>0.16943</ixx>
          <ixy>-0.014979</ixy>
          <ixz>0.0092941</ixz>
          <iyy>0.10174</iyy>
          <iyz>0</iyz>
          <izz>0.20482</izz>
        </inertia>
      </inertial>
      <collision name='LINK1_collision'>
        <pose frame=''>0 0 0 0 -0 0</pose>
        <geometry>
          <mesh>
            <scale>1 1 1</scale>
            <uri>model://SLAVE_ARM2/meshes/LINK1.STL</uri>
          </mesh>
        </geometry>
      </collision>
      <visual name='LINK1_visual'>
        <pose frame=''>0 0 0 0 -0 0</pose>
        <geometry>
          <mesh>
            <scale>1 1 1</scale>
            <uri>model://SLAVE_ARM2/meshes/LINK1.STL</uri>
          </mesh>
        </geometry>
      </visual>
    </link>
    <joint name='LINK1_JOINT' type='revolute'>
      <child>LINK1</child>
      <parent>BASE</parent>
      <axis>
        <xyz>0 0 1</xyz>
        <limit>
          <lower>-1e+16</lower>
          <upper>1e+16</upper>
        </limit>
        <dynamics>
          <spring_reference>0</spring_reference>
          <spring_stiffness>0</spring_stiffness>
        </dynamics>
        <use_parent_model_frame>1</use_parent_model_frame>
      </axis>
    </joint>
    <link name='LINK2'>
      <pose frame=''>0.808 -0.052 0.201 0 -0 0</pose>
      <inertial>
        <pose frame=''>0.38704 0.001282 0.021917 0 -0 0</pose>
        <mass>9.5851</mass>
        <inertia>
          <ixx>0.1866</ixx>
          <ixy>-0.016571</ixy>
          <ixz>0.023672</ixz>
          <iyy>0.52143</iyy>
          <iyz>0</iyz>
          <izz>0.64609</izz>
        </inertia>
      </inertial>
      <collision name='LINK2_collision'>
        <pose frame=''>0 0 0 0 -0 0</pose>
        <geometry>
          <mesh>
            <scale>1 1 1</scale>
            <uri>model://SLAVE_ARM2/meshes/LINK2.STL</uri>
          </mesh>
        </geometry>
      </collision>
      <visual name='LINK2_visual'>
        <pose frame=''>0 0 0 0 -0 0</pose>
        <geometry>
          <mesh>
            <scale>1 1 1</scale>
            <uri>model://SLAVE_ARM2/meshes/LINK2.STL</uri>
          </mesh>
        </geometry>
      </visual>
    </link>
    <joint name='LINK2_JOINT' type='revolute'>
      <child>LINK2</child>
      <parent>LINK1</parent>
      <axis>
        <xyz>0 1 0</xyz>
        <limit>
          <lower>-1e+16</lower>
          <upper>1e+16</upper>
        </limit>
        <dynamics>
          <spring_reference>0</spring_reference>
          <spring_stiffness>0</spring_stiffness>
        </dynamics>
        <use_parent_model_frame>1</use_parent_model_frame>
      </axis>
    </joint>
    <link name='LINK3'>
      <pose frame=''>1.573 -0.052 0.201 0 -0 0</pose>
      <inertial>
        <pose frame=''>0.25126 0.006018 0.030861 0 -0 0</pose>
        <mass>4.6467</mass>
        <inertia>
          <ixx>0.064981</ixx>
          <ixy>0</ixy>
          <ixz>0</ixz>
          <iyy>0.1378</iyy>
          <iyz>0</iyz>
          <izz>0.18077</izz>
        </inertia>
      </inertial>
      <collision name='LINK3_collision'>
        <pose frame=''>0 0 0 0 -0 0</pose>
        <geometry>
          <mesh>
            <scale>1 1 1</scale>
            <uri>model://SLAVE_ARM2/meshes/LINK3.STL</uri>
          </mesh>
        </geometry>
      </collision>
      <visual name='LINK3_visual'>
        <pose frame=''>0 0 0 0 -0 0</pose>
        <geometry>
          <mesh>
            <scale>1 1 1</scale>
            <uri>model://SLAVE_ARM2/meshes/LINK3.STL</uri>
          </mesh>
        </geometry>
      </visual>
    </link>
    <joint name='LINK3_JOINT' type='revolute'>
      <child>LINK3</child>
      <parent>LINK2</parent>
      <axis>
        <xyz>0 1 0</xyz>
        <limit>
          <lower>-1e+16</lower>
          <upper>1e+16</upper>
        </limit>
        <dynamics>
          <spring_reference>0</spring_reference>
          <spring_stiffness>0</spring_stiffness>
        </dynamics>
        <use_parent_model_frame>1</use_parent_model_frame>
      </axis>
    </joint>
    <link name='LINK4'>
      <pose frame=''>2.155 -0.052 0.201 0 -0 0</pose>
      <inertial>
        <pose frame=''>0.096298 0.005971 -0.013363 0 -0 0</pose>
        <mass>6.0823</mass>
        <inertia>
          <ixx>0.032953</ixx>
          <ixy>-0.01246</ixy>
          <ixz>0</ixz>
          <iyy>0.1069</iyy>
          <iyz>0</iyz>
          <izz>0.11961</izz>
        </inertia>
      </inertial>
      <collision name='LINK4_collision'>
        <pose frame=''>0 0 0 0 -0 0</pose>
        <geometry>
          <mesh>
            <scale>1 1 1</scale>
            <uri>model://SLAVE_ARM2/meshes/LINK4.STL</uri>
          </mesh>
        </geometry>
      </collision>
      <visual name='LINK4_visual'>
        <pose frame=''>0 0 0 0 -0 0</pose>
        <geometry>
          <mesh>
            <scale>1 1 1</scale>
            <uri>model://SLAVE_ARM2/meshes/LINK4.STL</uri>
          </mesh>
        </geometry>
      </visual>
    </link>
    <joint name='LINK4_JOINT' type='revolute'>
      <child>LINK4</child>
      <parent>LINK3</parent>
      <axis>
        <xyz>0 1 0</xyz>
        <limit>
          <lower>-1e+16</lower>
          <upper>1e+16</upper>
        </limit>
        <dynamics>
          <spring_reference>0</spring_reference>
          <spring_stiffness>0</spring_stiffness>
        </dynamics>
        <use_parent_model_frame>1</use_parent_model_frame>
      </axis>
    </joint>
    <link name='LINK5'>
      <pose frame=''>2.495 -0.052 0.191 0 -0 0</pose>
      <inertial>
        <pose frame=''>0.15128 -0.000396 0.001188 0 -0 0</pose>
        <mass>7.0927</mass>
        <inertia>
          <ixx>0.044594</ixx>
          <ixy>0.00072634</ixy>
          <ixz>0.0010377</ixz>
          <iyy>0.059768</iyy>
          <iyz>-0.00044615</iyz>
          <izz>0.05698</izz>
        </inertia>
      </inertial>
      <collision name='LINK5_collision'>
        <pose frame=''>0 0 0 0 -0 0</pose>
        <geometry>
          <mesh>
            <scale>1 1 1</scale>
            <uri>model://SLAVE_ARM2/meshes/LINK5.STL</uri>
          </mesh>
        </geometry>
      </collision>
      <visual name='LINK5_visual'>
        <pose frame=''>0 0 0 0 -0 0</pose>
        <geometry>
          <mesh>
            <scale>1 1 1</scale>
            <uri>model://SLAVE_ARM2/meshes/LINK5.STL</uri>
          </mesh>
        </geometry>
      </visual>
    </link>
    <joint name='LINK5_JOINT' type='revolute'>
      <child>LINK5</child>
      <parent>LINK4</parent>
      <axis>
        <xyz>0 0 1</xyz>
        <limit>
          <lower>-1e+16</lower>
          <upper>1e+16</upper>
        </limit>
        <dynamics>
          <spring_reference>0</spring_reference>
          <spring_stiffness>0</spring_stiffness>
        </dynamics>
        <use_parent_model_frame>1</use_parent_model_frame>
      </axis>
    </joint>
    <link name='LINK6'>
      <pose frame=''>2.78662 -0.052 0.191 0 -0 0</pose>
      <inertial>
        <pose frame=''>0.11622 0 0 0 -0 0</pose>
        <mass>9.3631</mass>
        <inertia>
          <ixx>0.084239</ixx>
          <ixy>0</ixy>
          <ixz>0</ixz>
          <iyy>0.10785</iyy>
          <iyz>0</iyz>
          <izz>0.082741</izz>
        </inertia>
      </inertial>
      <collision name='LINK6_collision'>
        <pose frame=''>0 0 0 0 -0 0</pose>
        <geometry>
          <mesh>
            <scale>1 1 1</scale>
            <uri>model://SLAVE_ARM2/meshes/LINK6.STL</uri>
          </mesh>
        </geometry>
      </collision>
      <visual name='LINK6_visual'>
        <pose frame=''>0 0 0 0 -0 0</pose>
        <geometry>
          <mesh>
            <scale>1 1 1</scale>
            <uri>model://SLAVE_ARM2/meshes/LINK6.STL</uri>
          </mesh>
        </geometry>
      </visual>
    </link>
    <joint name='LINK6_JOINT' type='revolute'>
      <child>LINK6</child>
      <parent>LINK5</parent>
      <axis>
        <xyz>1 0 0</xyz>
        <limit>
          <lower>-1e+16</lower>
          <upper>1e+16</upper>
        </limit>
        <dynamics>
          <spring_reference>0</spring_reference>
          <spring_stiffness>0</spring_stiffness>
        </dynamics>
        <use_parent_model_frame>1</use_parent_model_frame>
      </axis>
    </joint>
  </model>
</sdf>
