<sdf version='1.6'>
  <model name='PONGBOT_Q_V1'>

    <joint name="fixed to ground" type="fixed">
      <parent>world</parent>
      <child>REAR_BODY</child>
    </joint>

    <link name='REAR_BODY'>
      <pose frame=''>0 0 0 0 -0 0</pose>
      <inertial>
        <pose frame=''>0.1148 0.002 0.0148 0 -0 0</pose>
        <mass>11.1272</mass>
        <inertia>
          <ixx>0.1226</ixx>
          <ixy>0.0038</ixy>
          <ixz>-0.0088</ixz>
          <iyy>0.1436</iyy>
          <iyz>-0.0012</iyz>
          <izz>0.2321</izz>
        </inertia>
      </inertial>
      <collision name='REAR_BODY_collision'>
        <pose frame=''>0 0 0 0 -0 0</pose>
        <geometry>
          <mesh>
            <scale>1 1 1</scale>
            <uri>model://PONGBOT_Q_V1/meshes/REAR_BODY.STL</uri>
          </mesh>
        </geometry>
      </collision>
      <visual name='REAR_BODY_visual'>
        <pose frame=''>0 0 0 0 -0 0</pose>
        <geometry>
          <mesh>
            <scale>1 1 1</scale>
            <uri>model://PONGBOT_Q_V1/meshes/REAR_BODY.STL</uri>
          </mesh>
        </geometry>
        <material>
       <ambient>97 97 97 1</ambient>
       <diffuse>1 1 1 1</diffuse>
       <emissive>0 0 0 0</emissive>
       <specular>0 0 0 0</specular>
       </material>
      </visual>
      <sensor name='IMU' type='imu'>
  <pose frame=''>0.354 0 -0.018 0 -0 0</pose>
    <imu>
      <angular_velocity>
        <x>
          <noise type='none'></noise>
        </x>
        <y>
          <noise type='none'></noise>
        </y>
        <z>
          <noise type='none'></noise>
        </z>
      </angular_velocity>
      <linear_acceleration>
        <x>
          <noise type='none'></noise>
        </x>
        <y>
          <noise type="none"></noise>
        </y>
        <z>
          <noise type='none'></noise>
        </z>
      </linear_acceleration>
    </imu>
    <always_on>1</always_on>
    <update_rate>1000</update_rate>
    <visualize>true</visualize>
     </sensor>
    </link>
    <link name='RL_HIP'>
      <pose frame=''>0 0.115024 -0.000315 0 -0 0</pose>
      <inertial>
        <pose frame=''>-0.0009 0.0001 0.0002 0 -0 0</pose>
        <mass>1.1163</mass>
        <inertia>
          <ixx>0.0011</ixx>
          <ixy>0</ixy>
          <ixz>0</ixz>
          <iyy>0.0012</iyy>
          <iyz>0</iyz>
          <izz>0.0012</izz>
        </inertia>
      </inertial>
      <collision name='RL_HIP_collision'>
        <pose frame=''>0 0 0 0 -0 0</pose>
        <geometry>
          <mesh>
            <scale>1 1 1</scale>
            <uri>model://PONGBOT_Q_V1/meshes/RL_HIP.STL</uri>
          </mesh>
        </geometry>
      </collision>
      <visual name='RL_HIP_visual'>
        <pose frame=''>0 0 0 0 -0 0</pose>
        <geometry>
          <mesh>
            <scale>1 1 1</scale>
            <uri>model://PONGBOT_Q_V1/meshes/RL_HIP.STL</uri>
          </mesh>
        </geometry>
        <material>
       <ambient>213 0 0 1</ambient>
       <diffuse>1 1 1 1</diffuse>
       <emissive>0 0 0 1</emissive>
       <specular>0 0 0 0</specular>
       </material>
      </visual>
    </link>
    <joint name='RL_HIP_JOINT' type='revolute'>
      <child>RL_HIP</child>
      <parent>REAR_BODY</parent>
      <axis>
        <xyz>-1 0 -0</xyz>
        <limit>
          <lower>-3.141592</lower>
          <upper>3.141592</upper>
        </limit>
        <dynamics>
          <spring_reference>0</spring_reference>
          <spring_stiffness>0</spring_stiffness>
        </dynamics>
        <use_parent_model_frame>1</use_parent_model_frame>
      </axis>
    </joint>
    <link name='RL_THIGH'>
      <pose frame=''>-0 0.220024 -2.7e-05 0 -0 -0</pose>
      <inertial>
        <pose frame=''>0 -0.0161 -0.0264 0 -0 0</pose>
        <mass>1.8748</mass>
        <inertia>
          <ixx>0.0112</ixx>
          <ixy>0</ixy>
          <ixz>0</ixz>
          <iyy>0.0117</iyy>
          <iyz>-0.0008</iyz>
          <izz>0.0017</izz>
        </inertia>
      </inertial>
      <collision name='RL_THIGH_collision'>
        <pose frame=''>0 0 0 0 -0 0</pose>
        <geometry>
          <mesh>
            <scale>1 1 1</scale>
            <uri>model://PONGBOT_Q_V1/meshes/RL_THIGH.STL</uri>
          </mesh>
        </geometry>
      </collision>
      <visual name='RL_THIGH_visual'>
        <pose frame=''>0 0 0 0 -0 0</pose>
        <geometry>
          <mesh>
            <scale>1 1 1</scale>
            <uri>model://PONGBOT_Q_V1/meshes/RL_THIGH.STL</uri>
          </mesh>
        </geometry>
        <material>
       <ambient>213 0 0 1</ambient>
       <diffuse>1 1 1 1</diffuse>
       <emissive>0 0 0 1</emissive>
       <specular>0 0 0 0</specular>
       </material>
      </visual>
    </link>
    <joint name='RL_THIGH_JOINT' type='revolute'>
      <child>RL_THIGH</child>
      <parent>RL_HIP</parent>
      <axis>
        <xyz>-0 0.999996 0.002735</xyz>
        <limit>
          <lower>-3.141592</lower>
          <upper>3.141592</upper>
        </limit>
        <dynamics>
          <spring_reference>0</spring_reference>
          <spring_stiffness>0</spring_stiffness>
        </dynamics>
        <use_parent_model_frame>1</use_parent_model_frame>
      </axis>
    </joint>
    <link name='RL_ROTATOR1'>
      <pose frame=''>-0 0.247674 4.8e-05 0 -0 -0</pose>
      <inertial>
        <pose frame=''>-0.0021 -0.0028 -0.0058 0 -0 0</pose>
        <mass>0.072</mass>
        <inertia>
          <ixx>0.0001</ixx>
          <ixy>0</ixy>
          <ixz>0</ixz>
          <iyy>0.0001</iyy>
          <iyz>0</iyz>
          <izz>0</izz>
        </inertia>
      </inertial>
      <collision name='RL_ROTATOR1_collision'>
        <pose frame=''>0 0 0 0 -0 0</pose>
        <geometry>
          <mesh>
            <scale>1 1 1</scale>
            <uri>model://PONGBOT_Q_V1/meshes/RL_ROTATOR1.STL</uri>
          </mesh>
        </geometry>
      </collision>
      <visual name='RL_ROTATOR1_visual'>
        <pose frame=''>0 0 0 0 -0 0</pose>
        <geometry>
          <mesh>
            <scale>1 1 1</scale>
            <uri>model://PONGBOT_Q_V1/meshes/RL_ROTATOR1.STL</uri>
          </mesh>
        </geometry>
        <material>
       <ambient>26 35 126 1</ambient>
       <diffuse>1 1 1 1</diffuse>
       <emissive>0 0 0 1</emissive>
       <specular>0 0 0 0</specular>
       </material>
      </visual>
    </link>
    <joint name='RL_ROTATOR1_JOINT' type='revolute'>
      <child>RL_ROTATOR1</child>
      <parent>RL_THIGH</parent>
      <axis>
        <xyz>-0 0.999996 0.002735</xyz>
        <limit>
          <lower>-3.141592</lower>
          <upper>3.141592</upper>
        </limit>
        <dynamics>
          <spring_reference>0</spring_reference>
          <spring_stiffness>0</spring_stiffness>
        </dynamics>
        <use_parent_model_frame>1</use_parent_model_frame>
      </axis>
    </joint>
    <link name='RL_ROTATOR2'>
      <pose frame=''>-0.017101 0.254652 -0.046918 0 -0 -0</pose>
      <inertial>
        <pose frame=''>0 0.0004 -0.1525 0 -0 0</pose>
        <mass>0.2047</mass>
        <inertia>
          <ixx>0.0018</ixx>
          <ixy>0</ixy>
          <ixz>0</ixz>
          <iyy>0.0018</iyy>
          <iyz>0</iyz>
          <izz>0</izz>
        </inertia>
      </inertial>
      <collision name='RL_ROTATOR2_collision'>
        <pose frame=''>0 0 0 0 -0 0</pose>
        <geometry>
          <mesh>
            <scale>1 1 1</scale>
            <uri>model://PONGBOT_Q_V1/meshes/RL_ROTATOR2.STL</uri>
          </mesh>
        </geometry>
      </collision>
      <visual name='RL_ROTATOR2_visual'>
        <pose frame=''>0 0 0 0 -0 0</pose>
        <geometry>
          <mesh>
            <scale>1 1 1</scale>
            <uri>model://PONGBOT_Q_V1/meshes/RL_ROTATOR2.STL</uri>
          </mesh>
        </geometry>
        <material>
       <ambient>158 158 158 1</ambient>
       <diffuse>1 1 1 1</diffuse>
       <emissive>0 0 0 1</emissive>
       <specular>0 0 0 0</specular>
       </material>
      </visual>
    </link>

    <joint name='RL_ROTATOR2_JOINT' type='revolute'>
      <child>RL_ROTATOR2</child>
      <parent>RL_ROTATOR1</parent>
      <axis>
        <xyz>-0 0.999996 0.002735</xyz>
        <limit>
          <lower>-3.141592</lower>
          <upper>3.141592</upper>
        </limit>
        <dynamics>
          <spring_reference>0</spring_reference>
          <spring_stiffness>0</spring_stiffness>
        </dynamics>
        <use_parent_model_frame>1</use_parent_model_frame>
      </axis>
    </joint>
    <link name='RL_ROTATOR3'>
      <pose frame=''>-0.017101 0.255486 -0.351916 0 -0 -0</pose>
      <inertial>
        <pose frame=''>0.0179 -0.0325 -0.0428 0 -0 0</pose>
        <mass>0.402</mass>
        <inertia>
          <ixx>0.0052</ixx>
          <ixy>0</ixy>
          <ixz>-0.002</ixz>
          <iyy>0.0051</iyy>
          <iyz>0</iyz>
          <izz>0.002</izz>
        </inertia>
      </inertial>
      <collision name='RL_ROTATOR3_collision'>
        <pose frame=''>0 0 0 0 -0 0</pose>
        <geometry>
          <mesh>
            <scale>1 1 1</scale>
            <uri>model://PONGBOT_Q_V1/meshes/RL_ROTATOR3.STL</uri>
          </mesh>
        </geometry>
      </collision>
      <visual name='RL_ROTATOR3_visual'>
        <pose frame=''>0 0 0 0 -0 0</pose>
        <geometry>
          <mesh>
            <scale>1 1 1</scale>
            <uri>model://PONGBOT_Q_V1/meshes/RL_ROTATOR3.STL</uri>
          </mesh>
        </geometry>
        <material>
       <ambient>33 33 33 1</ambient>
       <diffuse>1 1 1 1</diffuse>
       <emissive>0 0 0 1</emissive>
       <specular>0 0 0 0</specular>
       </material>
      </visual>
    </link>
    <joint name='RL_ROTATOR3_JOINT' type='revolute'>
      <child>RL_ROTATOR3</child>
      <parent>RL_ROTATOR2</parent>
      <axis>
        <xyz>-0 0.999996 0.002735</xyz>
        <limit>
          <lower>-3.141592</lower>
          <upper>3.141592</upper>
        </limit>
        <dynamics>
          <spring_reference>0</spring_reference>
          <spring_stiffness>0</spring_stiffness>
        </dynamics>
        <use_parent_model_frame>1</use_parent_model_frame>
      </axis>
    </joint>
    <link name='RR_HIP'>
      <pose frame=''>0 -0.115024 -0.000315 0 -0 0</pose>
      <inertial>
        <pose frame=''>-0.0009 -0.0001 -0.0002 0 -0 0</pose>
        <mass>1.1163</mass>
        <inertia>
          <ixx>0.0011</ixx>
          <ixy>0</ixy>
          <ixz>0</ixz>
          <iyy>0.0012</iyy>
          <iyz>0</iyz>
          <izz>0.0012</izz>
        </inertia>
      </inertial>
      <collision name='RR_HIP_collision'>
        <pose frame=''>0 0 0 0 -0 0</pose>
        <geometry>
          <mesh>
            <scale>1 1 1</scale>
            <uri>model://PONGBOT_Q_V1/meshes/RR_HIP.STL</uri>
          </mesh>
        </geometry>
      </collision>
      <visual name='RR_HIP_visual'>
        <pose frame=''>0 0 0 0 -0 0</pose>
        <geometry>
          <mesh>
            <scale>1 1 1</scale>
            <uri>model://PONGBOT_Q_V1/meshes/RR_HIP.STL</uri>
          </mesh>
        </geometry>
        <material>
       <ambient>213 0 0 1</ambient>
       <diffuse>1 1 1 1</diffuse>
       <emissive>0 0 0 1</emissive>
       <specular>0 0 0 0</specular>
       </material>
      </visual>
    </link>
    <joint name='RR_HIP_JOINT' type='revolute'>
      <child>RR_HIP</child>
      <parent>REAR_BODY</parent>
      <axis>
        <xyz>-1 0 -0</xyz>
        <limit>
          <lower>-3.141592</lower>
          <upper>3.141592</upper>
        </limit>
        <dynamics>
          <spring_reference>0</spring_reference>
          <spring_stiffness>0</spring_stiffness>
        </dynamics>
        <use_parent_model_frame>1</use_parent_model_frame>
      </axis>
    </joint>
    <link name='RR_THIGH'>
      <pose frame=''>0 -0.220024 -0.000602 0 -0 -0</pose>
      <inertial>
        <pose frame=''>0 0.0163 -0.0263 0 -0 0</pose>
        <mass>1.8748</mass>
        <inertia>
          <ixx>0.0112</ixx>
          <ixy>0</ixy>
          <ixz>0</ixz>
          <iyy>0.0117</iyy>
          <iyz>0.0008</iyz>
          <izz>0.0017</izz>
        </inertia>
      </inertial>
      <collision name='RR_THIGH_collision'>
        <pose frame=''>0 0 0 0 -0 0</pose>
        <geometry>
          <mesh>
            <scale>1 1 1</scale>
            <uri>model://PONGBOT_Q_V1/meshes/RR_THIGH.STL</uri>
          </mesh>
        </geometry>
      </collision>
      <visual name='RR_THIGH_visual'>
        <pose frame=''>0 0 0 0 -0 0</pose>
        <geometry>
          <mesh>
            <scale>1 1 1</scale>
            <uri>model://PONGBOT_Q_V1/meshes/RR_THIGH.STL</uri>
          </mesh>
        </geometry>
        <material>
       <ambient>213 0 0 1</ambient>
       <diffuse>1 1 1 1</diffuse>
       <emissive>0 0 0 1</emissive>
       <specular>0 0 0 0</specular>
       </material>
      </visual>
    </link>
    <joint name='RR_THIGH_JOINT' type='revolute'>
      <child>RR_THIGH</child>
      <parent>RR_HIP</parent>
      <axis>
        <xyz>-0 0.999996 0.002735</xyz>
        <limit>
          <lower>-3.141592</lower>
          <upper>3.141592</upper>
        </limit>
        <dynamics>
          <spring_reference>0</spring_reference>
          <spring_stiffness>0</spring_stiffness>
        </dynamics>
        <use_parent_model_frame>1</use_parent_model_frame>
      </axis>
    </joint>
    <link name='RR_ROTATOR1'>
      <pose frame=''>0 -0.247674 -0.000678 0 -0 -0</pose>
      <inertial>
        <pose frame=''>-0.0021 0.0029 -0.0058 0 -0 0</pose>
        <mass>0.072</mass>
        <inertia>
          <ixx>0.0001</ixx>
          <ixy>0</ixy>
          <ixz>0</ixz>
          <iyy>0.0001</iyy>
          <iyz>0</iyz>
          <izz>0</izz>
        </inertia>
      </inertial>
      <collision name='RR_ROTATOR1_collision'>
        <pose frame=''>0 0 0 0 -0 0</pose>
        <geometry>
          <mesh>
            <scale>1 1 1</scale>
            <uri>model://PONGBOT_Q_V1/meshes/RR_ROTATOR1.STL</uri>
          </mesh>
        </geometry>
      </collision>
      <visual name='RR_ROTATOR1_visual'>
        <pose frame=''>0 0 0 0 -0 0</pose>
        <geometry>
          <mesh>
            <scale>1 1 1</scale>
            <uri>model://PONGBOT_Q_V1/meshes/RR_ROTATOR1.STL</uri>
          </mesh>
        </geometry>
        <material>
       <ambient>26 35 126 1</ambient>
       <diffuse>1 1 1 1</diffuse>
       <emissive>0 0 0 1</emissive>
       <specular>0 0 0 0</specular>
       </material>
      </visual>
    </link>
    <joint name='RR_ROTATOR1_JOINT' type='revolute'>
      <child>RR_ROTATOR1</child>
      <parent>RR_THIGH</parent>
      <axis>
        <xyz>-0 0.999996 0.002735</xyz>
        <limit>
          <lower>-3.141592</lower>
          <upper>3.141592</upper>
        </limit>
        <dynamics>
          <spring_reference>0</spring_reference>
          <spring_stiffness>0</spring_stiffness>
        </dynamics>
        <use_parent_model_frame>1</use_parent_model_frame>
      </axis>
    </joint>
    <link name='RR_ROTATOR2'>
      <pose frame=''>-0.017101 -0.254395 -0.047681 0 -0 -0</pose>
      <inertial>
        <pose frame=''>0 0.0004 -0.1525 0 -0 0</pose>
        <mass>0.2047</mass>
        <inertia>
          <ixx>0.0018</ixx>
          <ixy>0</ixy>
          <ixz>0</ixz>
          <iyy>0.0018</iyy>
          <iyz>0</iyz>
          <izz>0</izz>
        </inertia>
      </inertial>
      <collision name='RR_ROTATOR2_collision'>
        <pose frame=''>0 0 0 0 -0 0</pose>
        <geometry>
          <mesh>
            <scale>1 1 1</scale>
            <uri>model://PONGBOT_Q_V1/meshes/RR_ROTATOR2.STL</uri>
          </mesh>
        </geometry>
      </collision>
      <visual name='RR_ROTATOR2_visual'>
        <pose frame=''>0 0 0 0 -0 0</pose>
        <geometry>
          <mesh>
            <scale>1 1 1</scale>
            <uri>model://PONGBOT_Q_V1/meshes/RR_ROTATOR2.STL</uri>
          </mesh>
        </geometry>
        <material>
       <ambient>158 158 158 1</ambient>
       <diffuse>1 1 1 1</diffuse>
       <emissive>0 0 0 1</emissive>
       <specular>0 0 0 0</specular>
       </material>
      </visual>
    </link>
    <joint name='RR_ROTATOR2_JOINT' type='revolute'>
      <child>RR_ROTATOR2</child>
      <parent>RR_ROTATOR1</parent>
      <axis>
        <xyz>-0 0.999996 0.002735</xyz>
        <limit>
          <lower>-3.141592</lower>
          <upper>3.141592</upper>
        </limit>
        <dynamics>
          <spring_reference>0</spring_reference>
          <spring_stiffness>0</spring_stiffness>
        </dynamics>
        <use_parent_model_frame>1</use_parent_model_frame>
      </axis>
    </joint>
    <link name='RR_ROTATOR3'>
      <pose frame=''>-0.017101 -0.253561 -0.35268 0 -0 -0</pose>
      <inertial>
        <pose frame=''>0.0183 0.0327 -0.0426 0 -0 0</pose>
        <mass>0.402</mass>
        <inertia>
          <ixx>0.0052</ixx>
          <ixy>0</ixy>
          <ixz>-0.0002</ixz>
          <iyy>0.0051</iyy>
          <iyz>-0.0001</iyz>
          <izz>0.0002</izz>
        </inertia>
      </inertial>
      <collision name='RR_ROTATOR3_collision'>
        <pose frame=''>0 0 0 0 -0 0</pose>
        <geometry>
          <mesh>
            <scale>1 1 1</scale>
            <uri>model://PONGBOT_Q_V1/meshes/RR_ROTATOR3.STL</uri>
          </mesh>
        </geometry>
      </collision>
      <visual name='RR_ROTATOR3_visual'>
        <pose frame=''>0 0 0 0 -0 0</pose>
        <geometry>
          <mesh>
            <scale>1 1 1</scale>
            <uri>model://PONGBOT_Q_V1/meshes/RR_ROTATOR3.STL</uri>
          </mesh>
        </geometry>
        <material>
       <ambient>33 33 33 1</ambient>
       <diffuse>1 1 1 1</diffuse>
       <emissive>0 0 0 1</emissive>
       <specular>0 0 0 0</specular>
       </material>
      </visual>
    </link>
    <joint name='RR_ROTATOR3_JOINT' type='revolute'>
      <child>RR_ROTATOR3</child>
      <parent>RR_ROTATOR2</parent>
      <axis>
        <xyz>-0 0.999996 0.002735</xyz>
        <limit>
          <lower>-3.141592</lower>
          <upper>3.141592</upper>
        </limit>
        <dynamics>
          <spring_reference>0</spring_reference>
          <spring_stiffness>0</spring_stiffness>
        </dynamics>
        <use_parent_model_frame>1</use_parent_model_frame>
      </axis>
    </joint>
    <link name='FRONT_BODY'>
      <pose frame=''>0.35 0 0.035238 0 -0 0</pose>
      <inertial>
        <pose frame=''>0.2333 -0.0003 -0.0078 0 -0 0</pose>
        <mass>12.2749</mass>
        <inertia>
          <ixx>0.1398</ixx>
          <ixy>0.0001</ixy>
          <ixz>-0.0097</ixz>
          <iyy>0.1334</iyy>
          <iyz>0</iyz>
          <izz>0.2186</izz>
        </inertia>
      </inertial>
      <collision name='FRONT_BODY_collision'>
        <pose frame=''>0 0 0 0 -0 0</pose>
        <geometry>
          <mesh>
            <scale>1 1 1</scale>
            <uri>model://PONGBOT_Q_V1/meshes/FRONT_BODY.STL</uri>
          </mesh>
        </geometry>
      </collision>
      <visual name='FRONT_BODY_visual'>
        <pose frame=''>0 0 0 0 -0 0</pose>
        <geometry>
          <mesh>
            <scale>1 1 1</scale>
            <uri>model://PONGBOT_Q_V1/meshes/FRONT_BODY.STL</uri>
          </mesh>
        </geometry>
        <material>
       <ambient>97 97 97 1</ambient>
       <diffuse>1 1 1 1</diffuse>
       <emissive>0 0 0 1</emissive>
       <specular>0 0 0 0</specular>
       </material>
      </visual>
    </link>
    <joint name='WAIST_JOINT' type='revolute'>
      <child>FRONT_BODY</child>
      <parent>REAR_BODY</parent>
      <axis>
        <xyz>-0 -0 1</xyz>
        <limit>
          <lower>-3.141592</lower>
          <upper>3.141592</upper>
        </limit>
        <dynamics>
          <spring_reference>0</spring_reference>
          <spring_stiffness>0</spring_stiffness>
        </dynamics>
        <use_parent_model_frame>1</use_parent_model_frame>
      </axis>
    </joint>
    <link name='FL_HIP'>
      <pose frame=''>0.7 0.115024 -0.000312 0 0 0</pose>
      <inertial>
        <pose frame=''>0.0009 0.0001 -0.0002 0 -0 0</pose>
        <mass>1.1163</mass>
        <inertia>
          <ixx>0.0011</ixx>
          <ixy>0</ixy>
          <ixz>0</ixz>
          <iyy>0.0012</iyy>
          <iyz>0</iyz>
          <izz>0.0012</izz>
        </inertia>
      </inertial>
      <collision name='FL_HIP_collision'>
        <pose frame=''>0 0 0 0 -0 0</pose>
        <geometry>
          <mesh>
            <scale>1 1 1</scale>
            <uri>model://PONGBOT_Q_V1/meshes/FL_HIP.STL</uri>
          </mesh>
        </geometry>
      </collision>
      <visual name='FL_HIP_visual'>
        <pose frame=''>0 0 0 0 -0 0</pose>
        <geometry>
          <mesh>
            <scale>1 1 1</scale>
            <uri>model://PONGBOT_Q_V1/meshes/FL_HIP.STL</uri>
          </mesh>
        </geometry>
        <material>
       <ambient>213 0 0 1</ambient>
       <diffuse>1 1 1 1</diffuse>
       <emissive>0 0 0 1</emissive>
       <specular>0 0 0 0</specular>
       </material>
      </visual>
    </link>
    <joint name='FL_HIP_JOINT' type='revolute'>
      <child>FL_HIP</child>
      <parent>FRONT_BODY</parent>
      <axis>
        <xyz>-1 -0 0</xyz>
        <limit>
          <lower>-3.141592</lower>
          <upper>3.141592</upper>
        </limit>
        <dynamics>
          <spring_reference>0</spring_reference>
          <spring_stiffness>0</spring_stiffness>
        </dynamics>
        <use_parent_model_frame>1</use_parent_model_frame>
      </axis>
    </joint>
    <link name='FL_THIGH'>
      <pose frame=''>0.7 0.220024 -0.000312 0 -0 0</pose>
      <inertial>
        <pose frame=''>0 -0.0162 -0.0264 0 -0 0</pose>
        <mass>1.8748</mass>
        <inertia>
          <ixx>0.0112</ixx>
          <ixy>0</ixy>
          <ixz>0</ixz>
          <iyy>0.0117</iyy>
          <iyz>-0.0008</iyz>
          <izz>0.0017</izz>
        </inertia>
      </inertial>
      <collision name='FL_THIGH_collision'>
        <pose frame=''>0 0 0 0 -0 0</pose>
        <geometry>
          <mesh>
            <scale>1 1 1</scale>
            <uri>model://PONGBOT_Q_V1/meshes/FL_THIGH.STL</uri>
          </mesh>
        </geometry>
      </collision>
      <visual name='FL_THIGH_visual'>
        <pose frame=''>0 0 0 0 -0 0</pose>
        <geometry>
          <mesh>
            <scale>1 1 1</scale>
            <uri>model://PONGBOT_Q_V1/meshes/FL_THIGH.STL</uri>
          </mesh>
        </geometry>
        <material>
       <ambient>213 0 0 1</ambient>
       <diffuse>1 1 1 1</diffuse>
       <emissive>0 0 0 1</emissive>
       <specular>0 0 0 0</specular>
       </material>
      </visual>
    </link>
    <joint name='FL_THIGH_JOINT' type='revolute'>
      <child>FL_THIGH</child>
      <parent>FL_HIP</parent>
      <axis>
        <xyz>-0 1 0</xyz>
        <limit>
          <lower>-3.141592</lower>
          <upper>3.141592</upper>
        </limit>
        <dynamics>
          <spring_reference>0</spring_reference>
          <spring_stiffness>0</spring_stiffness>
        </dynamics>
        <use_parent_model_frame>1</use_parent_model_frame>
      </axis>
    </joint>
    <link name='FL_ROTATOR1'>
      <pose frame=''>0.7 0.247674 -0.000312 0 -0 0</pose>
      <inertial>
        <pose frame=''>0.0021 -0.0028 -0.0058 0 -0 0</pose>
        <mass>0.072</mass>
        <inertia>
          <ixx>0.0001</ixx>
          <ixy>0</ixy>
          <ixz>0</ixz>
          <iyy>0.0001</iyy>
          <iyz>0</iyz>
          <izz>0</izz>
        </inertia>
      </inertial>
      <collision name='FL_ROTATOR1_collision'>
        <pose frame=''>0 0 0 0 -0 0</pose>
        <geometry>
          <mesh>
            <scale>1 1 1</scale>
            <uri>model://PONGBOT_Q_V1/meshes/FL_ROTATOR1.STL</uri>
          </mesh>
        </geometry>
      </collision>
      <visual name='FL_ROTATOR1_visual'>
        <pose frame=''>0 0 0 0 -0 0</pose>
        <geometry>
          <mesh>
            <scale>1 1 1</scale>
            <uri>model://PONGBOT_Q_V1/meshes/FL_ROTATOR1.STL</uri>
          </mesh>
        </geometry>
        <material>
       <ambient>26 35 126 1</ambient>
       <diffuse>1 1 1 1</diffuse>
       <emissive>0 0 0 1</emissive>
       <specular>0 0 0 0</specular>
       </material>
      </visual>
    </link>
    <joint name='FL_ROTATOR1_JOINT' type='revolute'>
      <child>FL_ROTATOR1</child>
      <parent>FL_THIGH</parent>
      <axis>
        <xyz>-0 1 0</xyz>
        <limit>
          <lower>-3.141592</lower>
          <upper>3.141592</upper>
        </limit>
        <dynamics>
          <spring_reference>0</spring_reference>
          <spring_stiffness>0</spring_stiffness>
        </dynamics>
        <use_parent_model_frame>1</use_parent_model_frame>
      </axis>
    </joint>
    <link name='FL_ROTATOR2'>
      <pose frame=''>0.717101 0.254524 -0.047297 0 -0 0</pose>
      <inertial>
        <pose frame=''>0 0 -0.1525 0 -0 0</pose>
        <mass>0.2047</mass>
        <inertia>
          <ixx>0.0018</ixx>
          <ixy>0</ixy>
          <ixz>0</ixz>
          <iyy>0.0018</iyy>
          <iyz>0</iyz>
          <izz>0</izz>
        </inertia>
      </inertial>
      <collision name='FL_ROTATOR2_collision'>
        <pose frame=''>0 0 0 0 -0 0</pose>
        <geometry>
          <mesh>
            <scale>1 1 1</scale>
            <uri>model://PONGBOT_Q_V1/meshes/FL_ROTATOR2.STL</uri>
          </mesh>
        </geometry>
      </collision>
      <visual name='FL_ROTATOR2_visual'>
        <pose frame=''>0 0 0 0 -0 0</pose>
        <geometry>
          <mesh>
            <scale>1 1 1</scale>
            <uri>model://PONGBOT_Q_V1/meshes/FL_ROTATOR2.STL</uri>
          </mesh>
        </geometry>
        <material>
       <ambient>158 158 158 1</ambient>
       <diffuse>1 1 1 1</diffuse>
       <emissive>0 0 0 1</emissive>
       <specular>0 0 0 0</specular>
       </material>
      </visual>
    </link>
    <joint name='FL_ROTATOR2_JOINT' type='revolute'>
      <child>FL_ROTATOR2</child>
      <parent>FL_ROTATOR1</parent>
      <axis>
        <xyz>-0 1 0</xyz>
        <limit>
          <lower>-3.141592</lower>
          <upper>3.141592</upper>
        </limit>
        <dynamics>
          <spring_reference>0</spring_reference>
          <spring_stiffness>0</spring_stiffness>
        </dynamics>
        <use_parent_model_frame>1</use_parent_model_frame>
      </axis>
    </joint>
    <link name='FL_ROTATOR3'>
      <pose frame=''>0.717101 0.254524 -0.352296 0 -0 0</pose>
      <inertial>
        <pose frame=''>-0.0183 -0.0326 -0.0427 0 -0 0</pose>
        <mass>0.402</mass>
        <inertia>
          <ixx>0.0052</ixx>
          <ixy>0</ixy>
          <ixz>0.0002</ixz>
          <iyy>0.0051</iyy>
          <iyz>0</iyz>
          <izz>0.0002</izz>
        </inertia>
      </inertial>
      <collision name='FL_ROTATOR3_collision'>
        <pose frame=''>0 0 0 0 -0 0</pose>
        <geometry>
          <mesh>
            <scale>1 1 1</scale>
            <uri>model://PONGBOT_Q_V1/meshes/FL_ROTATOR3.STL</uri>
          </mesh>
        </geometry>
      </collision>
      <visual name='FL_ROTATOR3_visual'>
        <pose frame=''>0 0 0 0 -0 0</pose>
        <geometry>
          <mesh>
            <scale>1 1 1</scale>
            <uri>model://PONGBOT_Q_V1/meshes/FL_ROTATOR3.STL</uri>
          </mesh>
        </geometry>
        <material>
       <ambient>33 33 33 1</ambient>
       <diffuse>1 1 1 1</diffuse>
       <emissive>0 0 0 1</emissive>
       <specular>0 0 0 0</specular>
       </material>
      </visual>
    </link>
    <joint name='FL_ROTATOR3_JOINT' type='revolute'>
      <child>FL_ROTATOR3</child>
      <parent>FL_ROTATOR2</parent>
      <axis>
        <xyz>-0 1 0</xyz>
        <limit>
          <lower>-3.141592</lower>
          <upper>3.141592</upper>
        </limit>
        <dynamics>
          <spring_reference>0</spring_reference>
          <spring_stiffness>0</spring_stiffness>
        </dynamics>
        <use_parent_model_frame>1</use_parent_model_frame>
      </axis>
    </joint>
    <link name='FR_HIP'>
      <pose frame=''>0.7 -0.115024 -0.000312 0 -0 -0</pose>
      <inertial>
        <pose frame=''>0.0009 -0.0001 0.0002 0 -0 0</pose>
        <mass>1.1163</mass>
        <inertia>
          <ixx>0.0011</ixx>
          <ixy>0</ixy>
          <ixz>0</ixz>
          <iyy>0.0012</iyy>
          <iyz>0</iyz>
          <izz>0.0012</izz>
        </inertia>
      </inertial>
      <collision name='FR_HIP_collision'>
        <pose frame=''>0 0 0 0 -0 0</pose>
        <geometry>
          <mesh>
            <scale>1 1 1</scale>
            <uri>model://PONGBOT_Q_V1/meshes/FR_HIP.STL</uri>
          </mesh>
        </geometry>
      </collision>
      <visual name='FR_HIP_visual'>
        <pose frame=''>0 0 0 0 -0 0</pose>
        <geometry>
          <mesh>
            <scale>1 1 1</scale>
            <uri>model://PONGBOT_Q_V1/meshes/FR_HIP.STL</uri>
          </mesh>
        </geometry>
        <material>
       <ambient>213 0 0 1</ambient>
       <diffuse>1 1 1 1</diffuse>
       <emissive>0 0 0 1</emissive>
       <specular>0 0 0 0</specular>
       </material>
      </visual>
    </link>
    <joint name='FR_HIP_JOINT' type='revolute'>
      <child>FR_HIP</child>
      <parent>FRONT_BODY</parent>
      <axis>
        <xyz>-1 0 -0</xyz>
        <limit>
          <lower>-3.141592</lower>
          <upper>3.141592</upper>
        </limit>
        <dynamics>
          <spring_reference>0</spring_reference>
          <spring_stiffness>0</spring_stiffness>
        </dynamics>
        <use_parent_model_frame>1</use_parent_model_frame>
      </axis>
    </joint>
    <link name='FR_THIGH'>
      <pose frame=''>0.7 -0.220024 -0.000312 0 -0 -0</pose>
      <inertial>
        <pose frame=''>0 0.0162 -0.0264 0 -0 0</pose>
        <mass>1.8748</mass>
        <inertia>
          <ixx>0.0112</ixx>
          <ixy>0</ixy>
          <ixz>0</ixz>
          <iyy>0.0117</iyy>
          <iyz>0.0008</iyz>
          <izz>0.0017</izz>
        </inertia>
      </inertial>
      <collision name='FR_THIGH_collision'>
        <pose frame=''>0 0 0 0 -0 0</pose>
        <geometry>
          <mesh>
            <scale>1 1 1</scale>
            <uri>model://PONGBOT_Q_V1/meshes/FR_THIGH.STL</uri>
          </mesh>
        </geometry>
      </collision>
      <visual name='FR_THIGH_visual'>
        <pose frame=''>0 0 0 0 -0 0</pose>
        <geometry>
          <mesh>
            <scale>1 1 1</scale>
            <uri>model://PONGBOT_Q_V1/meshes/FR_THIGH.STL</uri>
          </mesh>
        </geometry>
        <material>
       <ambient>213 0 0 1</ambient>
       <diffuse>1 1 1 1</diffuse>
       <emissive>0 0 0 1</emissive>
       <specular>0 0 0 0</specular>
       </material>
      </visual>
    </link>
    <joint name='FR_THIGH_JOINT' type='revolute'>
      <child>FR_THIGH</child>
      <parent>FR_HIP</parent>
      <axis>
        <xyz>-0 1 0</xyz>
        <limit>
          <lower>-3.141592</lower>
          <upper>3.141592</upper>
        </limit>
        <dynamics>
          <spring_reference>0</spring_reference>
          <spring_stiffness>0</spring_stiffness>
        </dynamics>
        <use_parent_model_frame>1</use_parent_model_frame>
      </axis>
    </joint>
    <link name='FR_ROTATOR1'>
      <pose frame=''>0.7 -0.247674 -0.000312 0 -0 0</pose>
      <inertial>
        <pose frame=''>0.0021 0.0028 -0.0058 0 -0 0</pose>
        <mass>0.072</mass>
        <inertia>
          <ixx>0.0001</ixx>
          <ixy>0</ixy>
          <ixz>0</ixz>
          <iyy>0.0001</iyy>
          <iyz>0</iyz>
          <izz>0</izz>
        </inertia>
      </inertial>
      <collision name='FR_ROTATOR1_collision'>
        <pose frame=''>0 0 0 0 -0 0</pose>
        <geometry>
          <mesh>
            <scale>1 1 1</scale>
            <uri>model://PONGBOT_Q_V1/meshes/FR_ROTATOR1.STL</uri>
          </mesh>
        </geometry>
      </collision>
      <visual name='FR_ROTATOR1_visual'>
        <pose frame=''>0 0 0 0 -0 0</pose>
        <geometry>
          <mesh>
            <scale>1 1 1</scale>
            <uri>model://PONGBOT_Q_V1/meshes/FR_ROTATOR1.STL</uri>
          </mesh>
        </geometry>
        <material>
       <ambient>26 35 126 1</ambient>
       <diffuse>1 1 1 1</diffuse>
       <emissive>0 0 0 1</emissive>
       <specular>0 0 0 0</specular>
       </material>
      </visual>
    </link>
    <joint name='FR_ROTATOR1_JOINT' type='revolute'>
      <child>FR_ROTATOR1</child>
      <parent>FR_THIGH</parent>
      <axis>
        <xyz>-0 1 0</xyz>
        <limit>
          <lower>-3.141592</lower>
          <upper>3.141592</upper>
        </limit>
        <dynamics>
          <spring_reference>0</spring_reference>
          <spring_stiffness>0</spring_stiffness>
        </dynamics>
        <use_parent_model_frame>1</use_parent_model_frame>
      </axis>
    </joint>
    <link name='FR_ROTATOR2'>
      <pose frame=''>0.717101 -0.254524 -0.047297 0 -0 -0</pose>
      <inertial>
        <pose frame=''>0 0 -0.1525 0 -0 0</pose>
        <mass>0.2047</mass>
        <inertia>
          <ixx>0.0018</ixx>
          <ixy>0</ixy>
          <ixz>0</ixz>
          <iyy>0.0018</iyy>
          <iyz>0</iyz>
          <izz>0</izz>
        </inertia>
      </inertial>
      <collision name='FR_ROTATOR2_collision'>
        <pose frame=''>0 0 0 0 -0 0</pose>
        <geometry>
          <mesh>
            <scale>1 1 1</scale>
            <uri>model://PONGBOT_Q_V1/meshes/FR_ROTATOR2.STL</uri>
          </mesh>
        </geometry>
      </collision>
      <visual name='FR_ROTATOR2_visual'>
        <pose frame=''>0 0 0 0 -0 0</pose>
        <geometry>
          <mesh>
            <scale>1 1 1</scale>
            <uri>model://PONGBOT_Q_V1/meshes/FR_ROTATOR2.STL</uri>
          </mesh>
        </geometry>
        <material>
       <ambient>158 158 158 1</ambient>
       <diffuse>1 1 1 1</diffuse>
       <emissive>0 0 0 1</emissive>
       <specular>0 0 0 0</specular>
       </material>
      </visual>
    </link>
    <joint name='FR_ROTATOR2_JOINT' type='revolute'>
      <child>FR_ROTATOR2</child>
      <parent>FR_ROTATOR1</parent>
      <axis>
        <xyz>-0 1 0</xyz>
        <limit>
          <lower>-3.141592</lower>
          <upper>3.141592</upper>
        </limit>
        <dynamics>
          <spring_reference>0</spring_reference>
          <spring_stiffness>0</spring_stiffness>
        </dynamics>
        <use_parent_model_frame>1</use_parent_model_frame>
      </axis>
    </joint>
    <link name='FR_ROTATOR3'>
      <pose frame=''>0.717101 -0.254524 -0.352296 0 -0 -0</pose>
      <inertial>
        <pose frame=''>-0.0179 0.0326 -0.0427 0 -0 0</pose>
        <mass>0.402</mass>
        <inertia>
          <ixx>0.0052</ixx>
          <ixy>0</ixy>
          <ixz>0.0002</ixz>
          <iyy>0.0051</iyy>
          <iyz>0</iyz>
          <izz>0.0002</izz>
        </inertia>
      </inertial>
      <collision name='FR_ROTATOR3_collision'>
        <pose frame=''>0 0 0 0 -0 0</pose>
        <geometry>
          <mesh>
            <scale>1 1 1</scale>
            <uri>model://PONGBOT_Q_V1/meshes/FR_ROTATOR3.STL</uri>
          </mesh>
        </geometry>
      </collision>
      <visual name='FR_ROTATOR3_visual'>
        <pose frame=''>0 0 0 0 -0 0</pose>
        <geometry>
          <mesh>
            <scale>1 1 1</scale>
            <uri>model://PONGBOT_Q_V1/meshes/FR_ROTATOR3.STL</uri>
          </mesh>
        </geometry>
        <material>
       <ambient>33 33 33 1</ambient>
       <diffuse>1 1 1 1</diffuse>
       <emissive>0 0 0 1</emissive>
       <specular>0 0 0 0</specular>
       </material>
      </visual>
    </link>
    <joint name='FR_ROTATOR3_JOINT' type='revolute'>
      <child>FR_ROTATOR3</child>
      <parent>FR_ROTATOR2</parent>
      <axis>
        <xyz>-0 1 0</xyz>
        <limit>
          <lower>-3.141592</lower>
          <upper>3.141592</upper>
        </limit>
        <dynamics>
          <spring_reference>0</spring_reference>
          <spring_stiffness>0</spring_stiffness>
        </dynamics>
        <use_parent_model_frame>1</use_parent_model_frame>
      </axis>
    </joint>

    <joint name='FL_THIGH_CALF_JOINT' type='revolute'>
      <child>FL_ROTATOR3</child>
      <parent>FL_THIGH</parent>
      <axis>
        <xyz>-0 1 0</xyz>
        <limit>
          <lower>-3.141592</lower>
          <upper>3.141592</upper>
        </limit>
        <dynamics>
          <spring_reference>0</spring_reference>
          <spring_stiffness>0</spring_stiffness>
        </dynamics>
        <use_parent_model_frame>1</use_parent_model_frame>
      </axis>
      <pose frame=''>-0.0171 -0.0345 0.046984 0 -0 0</pose>
    </joint>

    <joint name='FR_THIGH_CALF_JOINT' type='revolute'>
      <child>FR_ROTATOR3</child>
      <parent>FR_THIGH</parent>
      <axis>
        <xyz>-0 1 0</xyz>
        <limit>
          <lower>-3.141592</lower>
          <upper>3.141592</upper>
        </limit>
        <dynamics>
          <spring_reference>0</spring_reference>
          <spring_stiffness>0</spring_stiffness>
        </dynamics>
        <use_parent_model_frame>1</use_parent_model_frame>
      </axis>
      <pose frame=''>-0.0171 0.0345 0.04698 0 -0 0</pose>
    </joint>

    <joint name='RL_THIGH_CALF_JOINT' type='revolute'>
      <child>RL_ROTATOR3</child>
      <parent>RL_THIGH</parent>
      <axis>
        <xyz>-0 1 0</xyz>
        <limit>
          <lower>-3.141592</lower>
          <upper>3.141592</upper>
        </limit>
        <dynamics>
          <spring_reference>0</spring_reference>
          <spring_stiffness>0</spring_stiffness>
        </dynamics>
        <use_parent_model_frame>1</use_parent_model_frame>
      </axis>
      <pose frame=''>0.0171 -0.0345 0.04698 0 -0 0</pose>
    </joint>

    <joint name='RR_THIGH_CALF_JOINT' type='revolute'>
      <child>RR_ROTATOR3</child>
      <parent>RR_THIGH</parent>
      <axis>
        <xyz>-0 1 0</xyz>
        <limit>
          <lower>-3.141592</lower>
          <upper>3.141592</upper>
        </limit>
        <dynamics>
          <spring_reference>0</spring_reference>
          <spring_stiffness>0</spring_stiffness>
        </dynamics>
        <use_parent_model_frame>1</use_parent_model_frame>
      </axis>
      <pose frame=''>0.0171 0.0345 0.04698 0 -0 0</pose>
    </joint>
  </model>
</sdf>
