<?xml version="1.0" ?>
<sdf version='1.6'>
  <model name='PONGBOT_Q_V2'>

  <!--<joint name="fixed to ground" type="fixed">
    <parent>world</parent>
    <child>REAR_BODY</child>
  </joint> -->

  <link name='REAR_BODY'>
    <pose frame=''>0 0 0 0 -0 0</pose>
    <inertial>
      <pose frame=''>0.1216 0.0026 0.0201 0 -0 0</pose>
      <mass>7.7996</mass>
      <inertia>
        <ixx>0.0745</ixx>
        <ixy>0.0038</ixy>
        <ixz>-0.0097</ixz>
        <iyy>0.1354</iyy>
        <iyz>-0.0014</iyz>
        <izz>0.1812</izz>
      </inertia>
    </inertial>
<!--    <collision name='REAR_BODY_collision'>
      <pose frame=''>0 0 0 0 -0 0</pose>
      <geometry>
        <mesh>
          <scale>1 1 1</scale>
          <uri>model://PONGBOT_Q_V2/meshes/REAR_BODY.STL</uri>
        </mesh>
      </geometry>
    </collision>-->
    <visual name='REAR_BODY_visual'>
      <pose frame=''>0 0 0 0 -0 0</pose>
      <geometry>
        <mesh>
          <scale>1 1 1</scale>
          <uri>model://PONGBOT_Q_V2/meshes/REAR_BODY.STL</uri>
        </mesh>
      </geometry>
      <material>
        <ambient>97 97 97 1</ambient>
        <diffuse>1 1 1 1</diffuse>
        <emissive>0 0 0 0</emissive>
        <specular>0 0 0 0</specular>
      </material>
    </visual>
    <sensor name='IMU' type='imu'>
      <pose frame=''>0.354 0 -0.018 0 -0 0</pose>
      <imu>
        <angular_velocity>
          <x>
            <noise type='none'></noise>
          </x>
          <y>
            <noise type='none'></noise>
          </y>
          <z>
            <noise type='none'></noise>
          </z>
        </angular_velocity>
        <linear_acceleration>
          <x>
            <noise type='none'></noise>
          </x>
          <y>
            <noise type="none"></noise>
          </y>
          <z>
            <noise type='none'></noise>
          </z>
        </linear_acceleration>
      </imu>
      <always_on>1</always_on>
      <update_rate>1000</update_rate>
      <visualize>true</visualize>
    </sensor>
  </link>
  <link name='RL_HIP'>
    <pose frame=''>0 0.11502 -0.000315 0 -0 0</pose>
    <inertial>
      <pose frame=''>-0.0009 0.0001 0.0002 0 -0 0</pose>
      <mass>1.1163</mass>
      <inertia>
        <ixx>0.0011</ixx>
        <ixy>0</ixy>
        <ixz>0</ixz>
        <iyy>0.0012</iyy>
        <iyz>0</iyz>
        <izz>0.0012</izz>
      </inertia>
    </inertial>
    <!--<collision name='RL_HIP_collision'>
      <pose frame=''>0 0 0 0 -0 0</pose>
      <geometry>
        <mesh>
          <scale>1 1 1</scale>
          <uri>model://PONGBOT_Q_V2/meshes/RL_HIP.STL</uri>
        </mesh>
      </geometry>
    </collision>-->
    <visual name='RL_HIP_visual'>
      <pose frame=''>0 0 0 0 -0 0</pose>
      <geometry>
        <mesh>
          <scale>1 1 1</scale>
          <uri>model://PONGBOT_Q_V2/meshes/RL_HIP.STL</uri>
        </mesh>
      </geometry>
      <material>
        <ambient>213 0 0 1</ambient>
        <diffuse>1 1 1 1</diffuse>
        <emissive>0 0 0 1</emissive>
        <specular>0 0 0 0</specular>
      </material>
    </visual>
  </link>
  <joint name='RL_HIP_JOINT' type='revolute'>
    <child>RL_HIP</child>
    <parent>REAR_BODY</parent>
    <axis>
      <xyz>1 0 -0</xyz>
      <limit>
        <lower>-3.141592</lower>
        <upper>3.141592</upper>
      </limit>
      <dynamics>
        <spring_reference>0</spring_reference>
        <spring_stiffness>0</spring_stiffness>
      </dynamics>
      <use_parent_model_frame>1</use_parent_model_frame>
    </axis>
  </joint>
  <link name='RL_THIGH'>
    <pose frame=''>-0 0.22002 -2.7e-05 0 -0 -0</pose>
    <inertial>
      <pose frame=''>-0.0017 -0.0099 -0.0422 0 -0 0</pose>
      <mass>2.1516</mass>
      <inertia>
        <ixx>0.0193</ixx>
        <ixy>0.0002</ixy>
        <ixz>0.0005</ixz>
        <iyy>0.0193</iyy>
        <iyz>-0.0024</iyz>
        <izz>0.0024</izz>
      </inertia>
    </inertial>
<!--    <collision name='RL_THIGH_collision'>
      <pose frame=''>0 0 0 0 -0 0</pose>
      <geometry>
        <mesh>
          <scale>1 1 1</scale>
          <uri>model://PONGBOT_Q_V2/meshes/RL_THIGH.STL</uri>
        </mesh>
      </geometry>
    </collision>-->
    <visual name='RL_THIGH_visual'>
      <pose frame=''>0 0 0 0 -0 0</pose>
      <geometry>
        <mesh>
          <scale>1 1 1</scale>
          <uri>model://PONGBOT_Q_V2/meshes/RL_THIGH.STL</uri>
        </mesh>
      </geometry>
      <material>
        <ambient>213 0 0 1</ambient>
        <diffuse>1 1 1 1</diffuse>
        <emissive>0 0 0 1</emissive>
        <specular>0 0 0 0</specular>
      </material>
    </visual>
  </link>
  <joint name='RL_THIGH_JOINT' type='revolute'>
    <child>RL_THIGH</child>
    <parent>RL_HIP</parent>
    <axis>
      <xyz>-0 1 0</xyz>
      <limit>
        <lower>-3.141592</lower>
        <upper>3.141592</upper>
      </limit>
      <dynamics>
        <spring_reference>0</spring_reference>
        <spring_stiffness>0</spring_stiffness>
      </dynamics>
      <use_parent_model_frame>1</use_parent_model_frame>
    </axis>
  </joint>
  <link name='RL_CALF'>
    <pose frame=''>0 0.220854 -0.305027 0 -0 -0</pose>
    <inertial>
      <pose frame=''>0.0008 0.0021 -0.0897 0 -0 0</pose>
      <mass>0.402</mass>
      <inertia>
        <ixx>0.0052</ixx>
        <ixy>0</ixy>
        <ixz>-0.0002</ixz>
        <iyy>0.0051</iyy>
        <iyz>0</iyz>
        <izz>0.0002</izz>
      </inertia>
    </inertial>
<!--    <collision name='RL_CALF_collision'>
      <pose frame=''>0 0 0 0 -0 0</pose>
      <geometry>
        <mesh>
          <scale>1 1 1</scale>
          <uri>model://PONGBOT_Q_V2/meshes/RL_CALF.STL</uri>
        </mesh>
      </geometry>
    </collision>-->
    <visual name='RL_CALF_visual'>
      <pose frame=''>0 0 0 0 -0 0</pose>
      <geometry>
        <mesh>
          <scale>1 1 1</scale>
          <uri>model://PONGBOT_Q_V2/meshes/RL_CALF.STL</uri>
        </mesh>
      </geometry>
      <material>
        <ambient>33 33 33 1</ambient>
        <diffuse>1 1 1 1</diffuse>
        <emissive>0 0 0 1</emissive>
        <specular>0 0 0 0</specular>
      </material>
    </visual>
  </link>
  <joint name='RL_CALF_JOINT' type='revolute'>
    <child>RL_CALF</child>
    <parent>RL_THIGH</parent>
    <axis>
      <xyz>-0 1 0</xyz>
      <limit>
        <lower>-3.141592</lower>
        <upper>3.141592</upper>
      </limit>
      <dynamics>
        <spring_reference>0</spring_reference>
        <spring_stiffness>0</spring_stiffness>
      </dynamics>
      <use_parent_model_frame>1</use_parent_model_frame>
    </axis>
  </joint>

  <link name='RL_TIP'>
    <pose frame=''>0.0165 0.2215 -0.5945 0 -0.7854 0</pose>
    <inertial>
      <pose frame=''>0 0 0 0 0 0</pose>
      <mass>0.01</mass>
      <inertia>
        <ixx>1.78278728118618E-06</ixx>
        <ixy>1.78278728118618E-06</ixy>
        <ixz>1.78278728118618E-06</ixz>
        <iyy>1.78278728118618E-06</iyy>
        <iyz>1.78278728118618E-06</iyz>
        <izz>1.78278728118618E-06</izz>
      </inertia>
    </inertial>
    <collision name='RL_TIP_collision'>
      <pose frame=''>0 0 0 0 0 0</pose>
      <geometry>
        <sphere>
          <radius> .026 </radius>
        </sphere>
      </geometry>
      <surface>
        <bounce>
          <restitution_coefficient> 0 </restitution_coefficient>
        </bounce>
        <friction>
          <ode>
            <mu>  1  </mu>
            <mu2> 1  </mu2>
          </ode>
        </friction>
        <contact>
          <ode>
            <kp>5000000</kp>
            <kd>5000</kd>
            <max_vel>0.1</max_vel>
            <min_depth>0.0001</min_depth>
          </ode>
        </contact>
      </surface>
    </collision>
    <visual name='RL_TIP_visual'>
      <pose frame=''>0 0 0 0 0 0</pose>
      <geometry>
        <mesh>
          <uri>model://PONGBOT_Q_V2/meshes/RL_TIP.STL</uri>
          <scale>1 1 1</scale>
        </mesh>
      </geometry>
    </visual>
  </link>

  <joint name="RL_TIP_JOINT" type="fixed">
    <child>RL_TIP</child>
    <parent>RL_CALF</parent>
    <sensor name="RL_FT_SENSOR" type="force_torque">
      <force_torque>
        <frame>child</frame>
        <measure_direction>child_to_parent</measure_direction>
      </force_torque>
	<visualize>true</visualize>
    </sensor>
  </joint>

  <link name='RR_HIP'>
    <pose frame=''>0 -0.11502 -0.000315 0 -0 0</pose>
    <inertial>
      <pose frame=''>-0.0009 -0.0001 -0.0002 0 -0 0</pose>
      <mass>1.1163</mass>
      <inertia>
        <ixx>0.0011</ixx>
        <ixy>0</ixy>
        <ixz>0</ixz>
        <iyy>0.0012</iyy>
        <iyz>0</iyz>
        <izz>0.0012</izz>
      </inertia>
    </inertial>
   <!-- <collision name='RR_HIP_collision'>
      <pose frame=''>0 0 0 0 -0 0</pose>
      <geometry>
        <mesh>
          <scale>1 1 1</scale>
          <uri>model://PONGBOT_Q_V2/meshes/RR_HIP.STL</uri>
        </mesh>
      </geometry>
    </collision>-->
    <visual name='RR_HIP_visual'>
      <pose frame=''>0 0 0 0 -0 0</pose>
      <geometry>
        <mesh>
          <scale>1 1 1</scale>
          <uri>model://PONGBOT_Q_V2/meshes/RR_HIP.STL</uri>
        </mesh>
      </geometry>
      <material>
        <ambient>213 0 0 1</ambient>
        <diffuse>1 1 1 1</diffuse>
        <emissive>0 0 0 1</emissive>
        <specular>0 0 0 0</specular>
      </material>
    </visual>
  </link>
  <joint name='RR_HIP_JOINT' type='revolute'>
    <child>RR_HIP</child>
    <parent>REAR_BODY</parent>
    <axis>
      <xyz>1 0 -0</xyz>
      <limit>
        <lower>-3.141592</lower>
        <upper>3.141592</upper>
      </limit>
      <dynamics>
        <spring_reference>0</spring_reference>
        <spring_stiffness>0</spring_stiffness>
      </dynamics>
      <use_parent_model_frame>1</use_parent_model_frame>
    </axis>
  </joint>
  <link name='RR_THIGH'>
    <pose frame=''>0 -0.22002 -0.000602 0 -0 -0</pose>
    <inertial>
      <pose frame=''>-0.0017 0.0101 -0.0421 0 -0 0</pose>
      <mass>2.1516</mass>
      <inertia>
        <ixx>0.0193</ixx>
        <ixy>0.0002</ixy>
        <ixz>0.0006</ixz>
        <iyy>0.0193</iyy>
        <iyz>0.0023</iyz>
        <izz>0.0024</izz>
      </inertia>
    </inertial>
 <!--   <collision name='RR_THIGH_collision'>
      <pose frame=''>0 0 0 0 -0 0</pose>
      <geometry>
        <mesh>
          <scale>1 1 1</scale>
          <uri>model://PONGBOT_Q_V2/meshes/RR_THIGH.STL</uri>
        </mesh>
      </geometry>
    </collision>-->
    <visual name='RR_THIGH_visual'>
      <pose frame=''>0 0 0 0 -0 0</pose>
      <geometry>
        <mesh>
          <scale>1 1 1</scale>
          <uri>model://PONGBOT_Q_V2/meshes/RR_THIGH.STL</uri>
        </mesh>
      </geometry>
      <material>
        <ambient>213 0 0 1</ambient>
        <diffuse>1 1 1 1</diffuse>
        <emissive>0 0 0 1</emissive>
        <specular>0 0 0 0</specular>
      </material>
    </visual>
  </link>
  <joint name='RR_THIGH_JOINT' type='revolute'>
    <child>RR_THIGH</child>
    <parent>RR_HIP</parent>
    <axis>
      <xyz>-0 1 0</xyz>
      <limit>
        <lower>-3.141592</lower>
        <upper>3.141592</upper>
      </limit>
      <dynamics>
        <spring_reference>0</spring_reference>
        <spring_stiffness>0</spring_stiffness>
      </dynamics>
      <use_parent_model_frame>1</use_parent_model_frame>
    </axis>
  </joint>
  <link name='RR_CALF'>
    <pose frame=''>0 -0.219186 -0.305602 0 -0 -0</pose>
    <inertial>
      <pose frame=''>0.0012 -0.0017 -0.0897 0 -0 0</pose>
      <mass>0.402</mass>
      <inertia>
        <ixx>0.0052</ixx>
        <ixy>0</ixy>
        <ixz>-0.0002</ixz>
        <iyy>0.0051</iyy>
        <iyz>-0.0001</iyz>
        <izz>0.0002</izz>
      </inertia>
    </inertial>
<!--    <collision name='RR_CALF_collision'>
      <pose frame=''>0 0 0 0 -0 0</pose>
      <geometry>
        <mesh>
          <scale>1 1 1</scale>
          <uri>model://PONGBOT_Q_V2/meshes/RR_CALF.STL</uri>
        </mesh>
      </geometry>
    </collision>-->
    <visual name='RR_CALF_visual'>
      <pose frame=''>0 0 0 0 -0 0</pose>
      <geometry>
        <mesh>
          <scale>1 1 1</scale>
          <uri>model://PONGBOT_Q_V2/meshes/RR_CALF.STL</uri>
        </mesh>
      </geometry>
      <material>
        <ambient>33 33 33 1</ambient>
        <diffuse>1 1 1 1</diffuse>
        <emissive>0 0 0 1</emissive>
        <specular>0 0 0 0</specular>
      </material>
    </visual>
  </link>
  <joint name='RR_CALF_JOINT' type='revolute'>
    <child>RR_CALF</child>
    <parent>RR_THIGH</parent>
    <axis>
      <xyz>-0 1 0</xyz>
      <limit>
        <lower>-3.141592</lower>
        <upper>3.141592</upper>
      </limit>
      <dynamics>
        <spring_reference>0</spring_reference>
        <spring_stiffness>0</spring_stiffness>
      </dynamics>
      <use_parent_model_frame>1</use_parent_model_frame>
    </axis>
  </joint>

  <link name='RR_TIP'>
    <pose frame=''>0.0155 -0.2185 -0.5945 0 -0.784 0</pose>
    <inertial>
      <pose frame=''>0 0 0 0 0 0</pose>
      <mass>0.01</mass>
      <inertia>
        <ixx>1.78278728118618E-06</ixx>
        <ixy>1.78278728118618E-06</ixy>
        <ixz>1.78278728118618E-06</ixz>
        <iyy>1.78278728118618E-06</iyy>
        <iyz>1.78278728118618E-06</iyz>
        <izz>1.78278728118618E-06</izz>
      </inertia>
    </inertial>
    <collision name='RR_TIP_collision'>
      <pose frame=''>0 0 0 0 0 0</pose>
      <geometry>
        <sphere>
          <radius> .026 </radius>
        </sphere>
      </geometry>
      <surface>
        <bounce>
          <restitution_coefficient> 0 </restitution_coefficient>
        </bounce>
        <friction>
          <ode>
            <mu>  1  </mu>
            <mu2> 1  </mu2>
          </ode>
        </friction>
        <contact>
          <ode>
            <!--<soft_erp> 0.1 </soft_erp>
            <soft_cfm> 1E-4 </soft_cfm>-->
            <kp>5000000</kp>
            <kd>5000</kd>
            <max_vel>0.1</max_vel>
            <min_depth>0.0001</min_depth>
          </ode>
        </contact>
      </surface>
    </collision>
    <visual name='RR_TIP_visual'>
      <pose frame=''>0 0 0 0 0 0</pose>
      <geometry>
        <mesh>
          <uri>model://PONGBOT_Q_V2/meshes/RR_TIP.STL</uri>
          <scale>1 1 1</scale>
        </mesh>
      </geometry>
    </visual>
  </link>
  <joint name="RR_TIP_JOINT" type="fixed">
    <child>RR_TIP</child>
    <parent>RR_CALF</parent>
    <sensor name="RR_FT_SENSOR" type="force_torque">
      <force_torque>
        <frame>child</frame>
        <measure_direction>child_to_parent</measure_direction>
      </force_torque>
<visualize>true</visualize>
    </sensor>
  </joint>

  <link name='FRONT_BODY'>
    <pose frame=''>0.35 0 0.035238 0 -0 0</pose>
    <inertial>
      <pose frame=''>0.2266 -0.0002 0.0015 0 -0 0</pose>
      <mass>8.9472</mass>
      <inertia>
        <ixx>0.0895</ixx>
        <ixy>0.0002</ixy>
        <ixz>-0.0077</ixz>
        <iyy>0.1228</iyy>
        <iyz>0</iyz>
        <izz>0.1674</izz>
      </inertia>
    </inertial>
  <!--  <collision name='FRONT_BODY_collision'>
      <pose frame=''>0 0 0 0 -0 0</pose>
      <geometry>
        <mesh>
          <scale>1 1 1</scale>
          <uri>model://PONGBOT_Q_V2/meshes/FRONT_BODY.STL</uri>
        </mesh>
      </geometry>
    </collision>-->
    <visual name='FRONT_BODY_visual'>
      <pose frame=''>0 0 0 0 -0 0</pose>
      <geometry>
        <mesh>
          <scale>1 1 1</scale>
          <uri>model://PONGBOT_Q_V2/meshes/FRONT_BODY.STL</uri>
        </mesh>
      </geometry>
      <material>
        <ambient>97 97 97 1</ambient>
        <diffuse>1 1 1 1</diffuse>
        <emissive>0 0 0 1</emissive>
        <specular>0 0 0 0</specular>
      </material>
    </visual>
  </link>
  <joint name='WAIST_JOINT' type='revolute'>
    <child>FRONT_BODY</child>
    <parent>REAR_BODY</parent>
    <axis>
      <xyz>-0 -0 1</xyz>
      <limit>
        <lower>-3.141592</lower>
        <upper>3.141592</upper>
      </limit>
      <dynamics>
        <spring_reference>0</spring_reference>
        <spring_stiffness>0</spring_stiffness>
      </dynamics>
      <use_parent_model_frame>1</use_parent_model_frame>
    </axis>
  </joint>
  <link name='FL_HIP'>
    <pose frame=''>0.7 0.11502 -0.000312 0 -0 -0</pose>
    <inertial>
      <pose frame=''>0.0009 0.0001 -0.0002 0 -0 0</pose>
      <mass>1.1163</mass>
      <inertia>
        <ixx>0.0011</ixx>
        <ixy>0</ixy>
        <ixz>0</ixz>
        <iyy>0.0012</iyy>
        <iyz>0</iyz>
        <izz>0.0012</izz>
      </inertia>
    </inertial>
<!--    <collision name='FL_HIP_collision'>
      <pose frame=''>0 0 0 0 -0 0</pose>
      <geometry>
        <mesh>
          <scale>1 1 1</scale>
          <uri>model://PONGBOT_Q_V2/meshes/FL_HIP.STL</uri>
        </mesh>
      </geometry>
    </collision>-->
    <visual name='FL_HIP_visual'>
      <pose frame=''>0 0 0 0 -0 0</pose>
      <geometry>
        <mesh>
          <scale>1 1 1</scale>
          <uri>model://PONGBOT_Q_V2/meshes/FL_HIP.STL</uri>
        </mesh>
      </geometry>
      <material>
        <ambient>213 0 0 1</ambient>
        <diffuse>1 1 1 1</diffuse>
        <emissive>0 0 0 1</emissive>
        <specular>0 0 0 0</specular>
      </material>
    </visual>
  </link>
  <joint name='FL_HIP_JOINT' type='revolute'>
    <child>FL_HIP</child>
    <parent>FRONT_BODY</parent>
    <axis>
      <xyz>1 0 -0</xyz>
      <limit>
        <lower>-3.141592</lower>
        <upper>3.141592</upper>
      </limit>
      <dynamics>
        <spring_reference>0</spring_reference>
        <spring_stiffness>0</spring_stiffness>
      </dynamics>
      <use_parent_model_frame>1</use_parent_model_frame>
    </axis>
  </joint>
  <link name='FL_THIGH'>
    <pose frame=''>0.7 0.22002 -0.000312 0 -0 -0</pose>
    <inertial>
      <pose frame=''>0.0017 -0.01 -0.0422 0 -0 0</pose>
      <mass>2.1516</mass>
      <inertia>
        <ixx>0.0193</ixx>
        <ixy>0.0002</ixy>
        <ixz>-0.0006</ixz>
        <iyy>0.0193</iyy>
        <iyz>-0.0023</iyz>
        <izz>0.0024</izz>
      </inertia>
    </inertial>
 <!--   <collision name='FL_THIGH_collision'>
      <pose frame=''>0 0 0 0 -0 0</pose>
      <geometry>
        <mesh>
          <scale>1 1 1</scale>
          <uri>model://PONGBOT_Q_V2/meshes/FL_THIGH.STL</uri>
        </mesh>
      </geometry>
    </collision>-->
    <visual name='FL_THIGH_visual'>
      <pose frame=''>0 0 0 0 -0 0</pose>
      <geometry>
        <mesh>
          <scale>1 1 1</scale>
          <uri>model://PONGBOT_Q_V2/meshes/FL_THIGH.STL</uri>
        </mesh>
      </geometry>
      <material>
        <ambient>213 0 0 1</ambient>
        <diffuse>1 1 1 1</diffuse>
        <emissive>0 0 0 1</emissive>
        <specular>0 0 0 0</specular>
      </material>
    </visual>
  </link>
  <joint name='FL_THIGH_JOINT' type='revolute'>
    <child>FL_THIGH</child>
    <parent>FL_HIP</parent>
    <axis>
      <xyz>-0 1 0</xyz>
      <limit>
        <lower>-3.141592</lower>
        <upper>3.141592</upper>
      </limit>
      <dynamics>
        <spring_reference>0</spring_reference>
        <spring_stiffness>0</spring_stiffness>
      </dynamics>
      <use_parent_model_frame>1</use_parent_model_frame>
    </axis>
  </joint>
  <link name='FL_CALF'>
    <pose frame=''>0.7 0.22002 -0.305312 0 -0 -0</pose>
    <inertial>
      <pose frame=''>-0.0012 0.0019 -0.0897 0 -0 0</pose>
      <mass>0.402</mass>
      <inertia>
        <ixx>0.0052</ixx>
        <ixy>0</ixy>
        <ixz>0.0002</ixz>
        <iyy>0.0051</iyy>
        <iyz>0</iyz>
        <izz>0.0002</izz>
      </inertia>
    </inertial>
<!--    <collision name='FL_CALF_collision'>
      <pose frame=''>0 0 0 0 -0 0</pose>
      <geometry>
        <mesh>
          <scale>1 1 1</scale>
          <uri>model://PONGBOT_Q_V2/meshes/FL_CALF.STL</uri>
        </mesh>
      </geometry>
    </collision>-->
    <visual name='FL_CALF_visual'>
      <pose frame=''>0 0 0 0 -0 0</pose>
      <geometry>
        <mesh>
          <scale>1 1 1</scale>
          <uri>model://PONGBOT_Q_V2/meshes/FL_CALF.STL</uri>
        </mesh>
      </geometry>
      <material>
        <ambient>33 33 33 1</ambient>
        <diffuse>1 1 1 1</diffuse>
        <emissive>0 0 0 1</emissive>
        <specular>0 0 0 0</specular>
      </material>
    </visual>
  </link>
  <joint name='FL_CALF_JOINT' type='revolute'>
    <child>FL_CALF</child>
    <parent>FL_THIGH</parent>
    <axis>
      <xyz>-0 1 0</xyz>
      <limit>
        <lower>-3.141592</lower>
        <upper>3.141592</upper>
      </limit>
      <dynamics>
        <spring_reference>0</spring_reference>
        <spring_stiffness>0</spring_stiffness>
      </dynamics>
      <use_parent_model_frame>1</use_parent_model_frame>
    </axis>
  </joint>

  <link name='FL_TIP'>
    <pose frame=''>0.685 0.22 -0.5935 0 0.7854 0</pose>
    <inertial>
      <pose frame=''>0 0 0 0 0 0</pose>
      <mass>0.01</mass>
      <inertia>
        <ixx>1.78278728118618E-06</ixx>
        <ixy>1.78278728118618E-06</ixy>
        <ixz>1.78278728118618E-06</ixz>
        <iyy>1.78278728118618E-06</iyy>
        <iyz>1.78278728118618E-06</iyz>
        <izz>1.78278728118618E-06</izz>
      </inertia>
    </inertial>
    <collision name='FL_TIP_collision'>
      <pose frame=''>0 0 0 0 0 0</pose>
      <geometry>
        <sphere>
          <radius> .026 </radius>
        </sphere>
      </geometry>
      <surface>
        <bounce>
          <restitution_coefficient> 0 </restitution_coefficient>
        </bounce>
        <friction>
          <ode>
            <mu>  1  </mu>
            <mu2> 1  </mu2>
          </ode>
        </friction>
        <contact>
          <ode>
            <!--<soft_erp> 0.1 </soft_erp>
            <soft_cfm> 1E-4 </soft_cfm>-->
            <kp>5000000</kp>
            <kd>5000</kd>
            <max_vel>0.1</max_vel>
            <min_depth>0.0001</min_depth>
          </ode>
        </contact>
      </surface>
    </collision>
    <visual name='FL_TIP_visual'>
      <pose frame=''>0 0 0 0 0 0</pose>
      <geometry>
        <mesh>
          <uri>model://PONGBOT_Q_V2/meshes/FL_TIP.STL</uri>
          <scale>1 1 1</scale>
        </mesh>
      </geometry>
    </visual>
  </link>
  <joint name="FL_TIP_JOINT" type="fixed">
    <child>FL_TIP</child>
    <parent>FL_CALF</parent>
    <sensor name="FL_FT_SENSOR" type="force_torque">
      <force_torque>
        <frame>child</frame>
        <measure_direction>child_to_parent</measure_direction>
      </force_torque>
<visualize>true</visualize>
    </sensor>
  </joint>

  <link name='FR_HIP'>
    <pose frame=''>0.7 -0.11502 -0.000312 0 -0 -0</pose>
    <inertial>
      <pose frame=''>0.0009 -0.0001 0.0002 0 -0 0</pose>
      <mass>1.1163</mass>
      <inertia>
        <ixx>0.0011</ixx>
        <ixy>0</ixy>
        <ixz>0</ixz>
        <iyy>0.0012</iyy>
        <iyz>0</iyz>
        <izz>0.0012</izz>
      </inertia>
    </inertial>
<!--    <collision name='FR_HIP_collision'>
      <pose frame=''>0 0 0 0 -0 0</pose>
      <geometry>
        <mesh>
          <scale>1 1 1</scale>
          <uri>model://PONGBOT_Q_V2/meshes/FR_HIP.STL</uri>
        </mesh>
      </geometry>
    </collision>-->
    <visual name='FR_HIP_visual'>
      <pose frame=''>0 0 0 0 -0 0</pose>
      <geometry>
        <mesh>
          <scale>1 1 1</scale>
          <uri>model://PONGBOT_Q_V2/meshes/FR_HIP.STL</uri>
        </mesh>
      </geometry>
      <material>
        <ambient>213 0 0 1</ambient>
        <diffuse>1 1 1 1</diffuse>
        <emissive>0 0 0 1</emissive>
        <specular>0 0 0 0</specular>
      </material>
    </visual>
  </link>
  <joint name='FR_HIP_JOINT' type='revolute'>
    <child>FR_HIP</child>
    <parent>FRONT_BODY</parent>
    <axis>
      <xyz>1 0 -0</xyz>
      <limit>
        <lower>-3.141592</lower>
        <upper>3.141592</upper>
      </limit>
      <dynamics>
        <spring_reference>0</spring_reference>
        <spring_stiffness>0</spring_stiffness>
      </dynamics>
      <use_parent_model_frame>1</use_parent_model_frame>
    </axis>
  </joint>
  <link name='FR_THIGH'>
    <pose frame=''>0.7 -0.22002 -0.000312 0 -0 -0</pose>
    <inertial>
      <pose frame=''>0.0017 0.01 -0.0422 0 -0 0</pose>
      <mass>2.1516</mass>
      <inertia>
        <ixx>0.0193</ixx>
        <ixy>-0.0002</ixy>
        <ixz>-0.0005</ixz>
        <iyy>0.0193</iyy>
        <iyz>0.0023</iyz>
        <izz>0.0024</izz>
      </inertia>
    </inertial>
<!--    <collision name='FR_THIGH_collision'>
      <pose frame=''>0 0 0 0 -0 0</pose>
      <geometry>
        <mesh>
          <scale>1 1 1</scale>
          <uri>model://PONGBOT_Q_V2/meshes/FR_THIGH.STL</uri>
        </mesh>
      </geometry>
    </collision>-->
    <visual name='FR_THIGH_visual'>
      <pose frame=''>0 0 0 0 -0 0</pose>
      <geometry>
        <mesh>
          <scale>1 1 1</scale>
          <uri>model://PONGBOT_Q_V2/meshes/FR_THIGH.STL</uri>
        </mesh>
      </geometry>
      <material>
        <ambient>213 0 0 1</ambient>
        <diffuse>1 1 1 1</diffuse>
        <emissive>0 0 0 1</emissive>
        <specular>0 0 0 0</specular>
      </material>
    </visual>
  </link>
  <joint name='FR_THIGH_JOINT' type='revolute'>
    <child>FR_THIGH</child>
    <parent>FR_HIP</parent>
    <axis>
      <xyz>-0 1 0</xyz>
      <limit>
        <lower>-3.141592</lower>
        <upper>3.141592</upper>
      </limit>
      <dynamics>
        <spring_reference>0</spring_reference>
        <spring_stiffness>0</spring_stiffness>
      </dynamics>
      <use_parent_model_frame>1</use_parent_model_frame>
    </axis>
  </joint>
  <link name='FR_CALF'>
    <pose frame=''>0.7 -0.22002 -0.305312 0 -0 -0</pose>
    <inertial>
      <pose frame=''>-0.0008 -0.0019 -0.0897 0 -0 0</pose>
      <mass>0.402</mass>
      <inertia>
        <ixx>0.0052</ixx>
        <ixy>0</ixy>
        <ixz>0.0002</ixz>
        <iyy>0.0051</iyy>
        <iyz>0</iyz>
        <izz>0.0002</izz>
      </inertia>
    </inertial>
   <!-- <collision name='FR_CALF_collision'>
      <pose frame=''>0 0 0 0 -0 0</pose>
      <geometry>
        <mesh>
          <scale>1 1 1</scale>
          <uri>model://PONGBOT_Q_V2/meshes/FR_CALF.STL</uri>
        </mesh>
      </geometry>
    </collision>-->
    <visual name='FR_CALF_visual'>
      <pose frame=''>0 0 0 0 -0 0</pose>
      <geometry>
        <mesh>
          <scale>1 1 1</scale>
          <uri>model://PONGBOT_Q_V2/meshes/FR_CALF.STL</uri>
        </mesh>
      </geometry>
      <material>
        <ambient>33 33 33 1</ambient>
        <diffuse>1 1 1 1</diffuse>
        <emissive>0 0 0 1</emissive>
        <specular>0 0 0 0</specular>
      </material>
    </visual>
  </link>
  <joint name='FR_CALF_JOINT' type='revolute'>
    <child>FR_CALF</child>
    <parent>FR_THIGH</parent>
    <axis>
      <xyz>-0 1 0</xyz>
      <limit>
        <lower>-3.141592</lower>
        <upper>3.141592</upper>
      </limit>
      <dynamics>
        <spring_reference>0</spring_reference>
        <spring_stiffness>0</spring_stiffness>
      </dynamics>
      <use_parent_model_frame>1</use_parent_model_frame>
    </axis>
  </joint>

  <link name='FR_TIP'>
    <pose frame=''>0.685-0.22 -0.5935 0 0.7854 0</pose>
    <inertial>
      <pose frame=''>0 0 0 0 0 0</pose>
      <mass>0.01</mass>
      <inertia>
        <ixx>1.78278728118618E-06</ixx>
        <ixy>1.78278728118618E-06</ixy>
        <ixz>1.78278728118618E-06</ixz>
        <iyy>1.78278728118618E-06</iyy>
        <iyz>1.78278728118618E-06</iyz>
        <izz>1.78278728118618E-06</izz>
      </inertia>
    </inertial>
    <collision name='FR_TIP_collision'>
      <pose frame=''>0 0 0 0 0 0</pose>
      <geometry>
        <sphere>
          <radius> .026 </radius>
        </sphere>
      </geometry>
      <surface>
        <bounce>
          <restitution_coefficient> 0 </restitution_coefficient>
        </bounce>
        <friction>
          <ode>
            <mu>  1  </mu>
            <mu2> 1  </mu2>
          </ode>
        </friction>
        <contact>
          <ode>
            <!--<soft_erp> 0.1 </soft_erp>
            <soft_cfm> 1E-4 </soft_cfm>-->
            <kp>5000000</kp>
            <kd>5000</kd>
            <max_vel>0.1</max_vel>
            <min_depth>0.0001</min_depth>
          </ode>
        </contact>
      </surface>
    </collision>
    <visual name='FR_TIP_visual'>
      <pose frame=''>0 0 0 0 0 0</pose>
      <geometry>
        <mesh>
          <uri>model://PONGBOT_Q_V2/meshes/FR_TIP.STL</uri>
          <scale>1 1 1</scale>
        </mesh>
      </geometry>
    </visual>
  </link>
  <joint name="FR_TIP_JOINT" type="fixed">
    <child>FR_TIP</child>
    <parent>FR_CALF</parent>
    <sensor name="FR_FT_SENSOR" type="force_torque">
      <force_torque>
        <frame>child</frame>
        <measure_direction>child_to_parent</measure_direction>
      </force_torque>
<visualize>true</visualize>
    </sensor>
  </joint>
</model>
</sdf>
