<robot
  name="SLAVE_ARM">
  <link
    name="BASE_LINK">
    <inertial>
      <origin
        xyz="0.2973 0.0488 0.1042"
        rpy="0 0 0" />
      <mass
        value="17.574" />
      <inertia
        ixx="0.41733"
        ixy="0.0168"
        ixz="-0.0017"
        iyy="0.76126"
        iyz="0"
        izz="0.9251" />
    </inertial>
    <visual>
      <origin
        xyz="0 0 0"
        rpy="0 0 0" />
      <geometry>
        <mesh
          filename="package://SLAVE_ARM/meshes/BASE_LINK.STL" />
      </geometry>
      <material
        name="">
        <color
          rgba="0.75294 0.75294 0.75294 1" />
      </material>
    </visual>
    <collision>
      <origin
        xyz="0 0 0"
        rpy="0 0 0" />
      <geometry>
        <mesh
          filename="package://SLAVE_ARM/meshes/BASE_LINK.STL" />
      </geometry>
    </collision>
  </link>
  <link
    name="LINK1">
    <inertial>
      <origin
        xyz="0.1104 0.0137 0.0189"
        rpy="0 0 0" />
      <mass
        value="10.337" />
      <inertia
        ixx="0.1694"
        ixy="0.015"
        ixz="0.0093"
        iyy="0.10174"
        iyz="-0.0021"
        izz="0.2048" />
    </inertial>
    <visual>
      <origin
        xyz="0 0 0"
        rpy="0 0 0" />
      <geometry>
        <mesh
          filename="package://SLAVE_ARM/meshes/LINK1.STL" />
      </geometry>
      <material
        name="">
        <color
          rgba="0.75294 0.75294 0.75294 1" />
      </material>
    </visual>
    <collision>
      <origin
        xyz="0 0 0"
        rpy="0 0 0" />
      <geometry>
        <mesh
          filename="package://SLAVE_ARM/meshes/LINK1.STL" />
      </geometry>
    </collision>
  </link>
  <joint
    name="LINK1_JOINT"
    type="continuous">
    <origin
      xyz="0.608 0.052 0.111"
      rpy="0 0 0" />
    <parent
      link="BASE_LINK" />
    <child
      link="LINK1" />
    <axis
      xyz="0 0 1" />
  </joint>
  <link
    name="LINK2">
    <inertial>
      <origin
        xyz="0.387 -0.0012 0.0217"
        rpy="0 0 0" />
      <mass
        value="9.5413" />
      <inertia
        ixx="0.1864"
        ixy="0.0162"
        ixz="0.0236"
        iyy="0.5195"
        iyz="0.0025"
        izz="0.6443" />
    </inertial>
    <visual>
      <origin
        xyz="0 0 0"
        rpy="0 0 0" />
      <geometry>
        <mesh
          filename="package://SLAVE_ARM/meshes/LINK2.STL" />
      </geometry>
      <material
        name="">
        <color
          rgba="0.75294 0.75294 0.75294 1" />
      </material>
    </visual>
    <collision>
      <origin
        xyz="0 0 0"
        rpy="0 0 0" />
      <geometry>
        <mesh
          filename="package://SLAVE_ARM/meshes/LINK2.STL" />
      </geometry>
    </collision>
  </link>
  <joint
    name="LINK2_JOINT"
    type="continuous">
    <origin
      xyz="0.2 0 0.09"
      rpy="0 0 0" />
    <parent
      link="LINK1" />
    <child
      link="LINK2" />
    <axis
      xyz="0 1 0" />
  </joint>
  <link
    name="LINK3">
    <inertial>
      <origin
        xyz="0.25161 -0.0058 0.0306"
        rpy="0 0 0" />
      <mass
        value="4.6229" />
      <inertia
        ixx="0.064842"
        ixy="0.0032"
        ixz="0.0043"
        iyy="0.1375"
        iyz="0.0013"
        izz="0.1805" />
    </inertial>
    <visual>
      <origin
        xyz="0 0 0"
        rpy="0 0 0" />
      <geometry>
        <mesh
          filename="package://SLAVE_ARM/meshes/LINK3.STL" />
      </geometry>
      <material
        name="">
        <color
          rgba="0.75294 0.75294 0.75294 1" />
      </material>
    </visual>
    <collision>
      <origin
        xyz="0 0 0"
        rpy="0 0 0" />
      <geometry>
        <mesh
          filename="package://SLAVE_ARM/meshes/LINK3.STL" />
      </geometry>
    </collision>
  </link>
  <joint
    name="LINK3_JOINT"
    type="continuous">
    <origin
      xyz="0.765 0 0"
      rpy="0 0 0" />
    <parent
      link="LINK2" />
    <child
      link="LINK3" />
    <axis
      xyz="0 1 0" />
  </joint>
  <link
    name="LINK4">
    <inertial>
      <origin
        xyz="0.0963 -0.006 -0.0134"
        rpy="0 0 0" />
      <mass
        value="6.0768" />
      <inertia
        ixx="0.0329"
        ixy="0.0125"
        ixz="0.0009"
        iyy="0.1067"
        iyz="-0.0011"
        izz="0.1194" />
    </inertial>
    <visual>
      <origin
        xyz="0 0 0"
        rpy="0 0 0" />
      <geometry>
        <mesh
          filename="package://SLAVE_ARM/meshes/LINK4.STL" />
      </geometry>
      <material
        name="">
        <color
          rgba="0.75294 0.75294 0.75294 1" />
      </material>
    </visual>
    <collision>
      <origin
        xyz="0 0 0"
        rpy="0 0 0" />
      <geometry>
        <mesh
          filename="package://SLAVE_ARM/meshes/LINK4.STL" />
      </geometry>
    </collision>
  </link>
  <joint
    name="LINK4_JOINT"
    type="continuous">
    <origin
      xyz="0.582 0 0"
      rpy="0 0 0" />
    <parent
      link="LINK3" />
    <child
      link="LINK4" />
    <axis
      xyz="0 1 0" />
  </joint>
  <link
    name="LINK5">
    <inertial>
      <origin
        xyz="0.1513 0 0.0022"
        rpy="0 0 0" />
      <mass
        value="7.0927" />
      <inertia
        ixx="0.0446"
        ixy="0.0005"
        ixz="-0.0008"
        iyy="0.0597"
        iyz="-0.0004"
        izz="0.0571" />
    </inertial>
    <visual>
      <origin
        xyz="0 0 0"
        rpy="0 0 0" />
      <geometry>
        <mesh
          filename="package://SLAVE_ARM/meshes/LINK5.STL" />
      </geometry>
      <material
        name="">
        <color
          rgba="0.75294 0.75294 0.75294 1" />
      </material>
    </visual>
    <collision>
      <origin
        xyz="0 0 0"
        rpy="0 0 0" />
      <geometry>
        <mesh
          filename="package://SLAVE_ARM/meshes/LINK5.STL" />
      </geometry>
    </collision>
  </link>
  <joint
    name="LINK5_JOINT"
    type="continuous">
    <origin
      xyz="0.34 0 -0.01"
      rpy="0 0 0" />
    <parent
      link="LINK4" />
    <child
      link="LINK5" />
    <axis
      xyz="0 0 1" />
  </joint>
  <link
    name="LINK6">
    <inertial>
      <origin
        xyz="0.0824 0 0"
        rpy="0 0 0" />
      <mass
        value="7.1931" />
      <inertia
        ixx="0.0555"
        ixy="0"
        ixz="0"
        iyy="0.041"
        iyz="0"
        izz="0.041" />
    </inertial>
    <visual>
      <origin
        xyz="0 0 0"
        rpy="0 0 0" />
      <geometry>
        <mesh
          filename="package://SLAVE_ARM/meshes/LINK6.STL" />
      </geometry>
      <material
        name="">
        <color
          rgba="0.79216 0.81961 0.93333 1" />
      </material>
    </visual>
    <collision>
      <origin
        xyz="0 0 0"
        rpy="0 0 0" />
      <geometry>
        <mesh
          filename="package://SLAVE_ARM/meshes/LINK6.STL" />
      </geometry>
    </collision>
  </link>
  <joint
    name="LINK6_JOINT"
    type="continuous">
    <origin
      xyz="0.29162 0 0"
      rpy="0 0 0" />
    <parent
      link="LINK5" />
    <child
      link="LINK6" />
    <axis
      xyz="1 0 0" />
  </joint>
</robot>
