<?xml version="1.0" ?>
<sdf version='1.6'>
  <model name='PONGBOT_Q_V6'>
 <joint name="fixed to ground" type="fixed">
       <parent>world</parent>
       <child>BODY</child>
     </joint>
    <link name='BODY'>
      <pose frame=''>0 0 0 0 -0 0</pose>
      <inertial>
        <pose frame=''>-0.0221 0.00034 0.05293 0 -0 0</pose>
        <mass>24.701</mass>
        <inertia>
          <ixx>0.34089</ixx>
          <ixy>-0.00272</ixy>
          <ixz>-0.08697</ixz>
          <iyy>1.8849</iyy>
          <iyz>0.00032</iyz>
          <izz>1.9898</izz>
        </inertia>
      </inertial>
      <collision name='BODY_collision'>
        <pose frame=''>0 0 0 0 -0 0</pose>
        <geometry>
          <mesh>
            <scale>1 1 1</scale>
            <uri>model://PONGBOT_Q_V6/meshes/BODY.STL</uri>
          </mesh>
        </geometry>
      </collision>
      <visual name='BODY_visual'>
        <pose frame=''>0 0 0 0 -0 0</pose>
        <geometry>
          <mesh>
            <scale>1 1 1</scale>
            <uri>model://PONGBOT_Q_V6/meshes/BODY.STL</uri>
          </mesh>
        </geometry>
      </visual>
    </link>
    <link name='FL_HIP'>
      <pose frame=''>0.35 0.11502 0 0 -0 0</pose>
      <inertial>
        <pose frame=''>0.00113 -0.00546 0.00059 0 -0 0</pose>
        <mass>1.5346</mass>
        <inertia>
          <ixx>0.00131</ixx>
          <ixy>0</ixy>
          <ixz>1e-05</ixz>
          <iyy>0.00176</iyy>
          <iyz>-1e-05</iyz>
          <izz>0.00141</izz>
        </inertia>
      </inertial>
      <collision name='FL_HIP_collision'>
        <pose frame=''>0 0 0 0 -0 0</pose>
        <geometry>
          <mesh>
            <scale>1 1 1</scale>
            <uri>model://PONGBOT_Q_V6/meshes/FL_HIP.STL</uri>
          </mesh>
        </geometry>
      </collision>
      <visual name='FL_HIP_visual'>
        <pose frame=''>0 0 0 0 -0 0</pose>
        <geometry>
          <mesh>
            <scale>1 1 1</scale>
            <uri>model://PONGBOT_Q_V6/meshes/FL_HIP.STL</uri>
          </mesh>
        </geometry>
      </visual>
    </link>
    <joint name='FL_HR_JOINT' type='revolute'>
      <child>FL_HIP</child>
      <parent>BODY</parent>
      <axis>
        <xyz>1 0 0</xyz>
        <limit>
          <lower>-1e+16</lower>
          <upper>1e+16</upper>
        </limit>
        <dynamics>
          <spring_reference>0</spring_reference>
          <spring_stiffness>0</spring_stiffness>
        </dynamics>
        <use_parent_model_frame>1</use_parent_model_frame>
      </axis>
    </joint>
    <link name='FL_THIGH'>
      <pose frame=''>0.35 0.21992 0 0 -0 0</pose>
      <inertial>
        <pose frame=''>0.00018 -0.01146 -0.02836 0 -0 0</pose>
        <mass>3.32</mass>
        <inertia>
          <ixx>0.02493</ixx>
          <ixy>-3e-05</ixy>
          <ixz>2e-05</ixz>
          <iyy>0.02533</iyy>
          <iyz>-0.001</iyz>
          <izz>0.00394</izz>
        </inertia>
      </inertial>
      <collision name='FL_THIGH_collision'>
        <pose frame=''>0 0 0 0 -0 0</pose>
        <geometry>
          <mesh>
            <scale>1 1 1</scale>
            <uri>model://PONGBOT_Q_V6/meshes/FL_THIGH.STL</uri>
          </mesh>
        </geometry>
      </collision>
      <visual name='FL_THIGH_visual'>
        <pose frame=''>0 0 0 0 -0 0</pose>
        <geometry>
          <mesh>
            <scale>1 1 1</scale>
            <uri>model://PONGBOT_Q_V6/meshes/FL_THIGH.STL</uri>
          </mesh>
        </geometry>
      </visual>
    </link>
    <joint name='FL_HP_JOINT' type='revolute'>
      <child>FL_THIGH</child>
      <parent>FL_HIP</parent>
      <axis>
        <xyz>0 1 0</xyz>
        <limit>
          <lower>-1e+16</lower>
          <upper>1e+16</upper>
        </limit>
        <dynamics>
          <spring_reference>0</spring_reference>
          <spring_stiffness>0</spring_stiffness>
        </dynamics>
        <use_parent_model_frame>1</use_parent_model_frame>
      </axis>
    </joint>
    <link name='FL_CALF'>
      <pose frame=''>0.35 0.21992 -0.305 0 -0 0</pose>
      <inertial>
        <pose frame=''>0.03375 0.00334 -0.0746 0 -0 0</pose>
        <mass>0.57335</mass>
        <inertia>
          <ixx>0.00434</ixx>
          <ixy>-7e-05</ixy>
          <ixz>-0.00216</ixz>
          <iyy>0.00538</iyy>
          <iyz>0.00018</iyz>
          <izz>0.00139</izz>
        </inertia>
      </inertial>
      <collision name='FL_CALF_collision'>
        <pose frame=''>0 0 0 0 -0 0</pose>
        <geometry>
          <mesh>
            <scale>1 1 1</scale>
            <uri>model://PONGBOT_Q_V6/meshes/FL_CALF.STL</uri>
          </mesh>
        </geometry>
      </collision>
      <visual name='FL_CALF_visual'>
        <pose frame=''>0 0 0 0 -0 0</pose>
        <geometry>
          <mesh>
            <scale>1 1 1</scale>
            <uri>model://PONGBOT_Q_V6/meshes/FL_CALF.STL</uri>
          </mesh>
        </geometry>
      </visual>
    </link>
    <joint name='FL_KN_JOINT' type='revolute'>
      <child>FL_CALF</child>
      <parent>FL_THIGH</parent>
      <axis>
        <xyz>0 1 0</xyz>
        <limit>
          <lower>-1e+16</lower>
          <upper>1e+16</upper>
        </limit>
        <dynamics>
          <spring_reference>0</spring_reference>
          <spring_stiffness>0</spring_stiffness>
        </dynamics>
        <use_parent_model_frame>1</use_parent_model_frame>
      </axis>
    </joint>
    <link name='FL_TIP'>
      <pose frame=''>0.46836 0.21992 -0.56773 0 -0 0</pose>
      <inertial>
        <pose frame=''>-0.00076 0 0.00289 0 -0 0</pose>
        <mass>0.1646</mass>
        <inertia>
          <ixx>9e-05</ixx>
          <ixy>0</ixy>
          <ixz>-1e-05</ixz>
          <iyy>9e-05</iyy>
          <iyz>0</iyz>
          <izz>8e-05</izz>
        </inertia>
      </inertial>
      <collision name='FL_TIP_collision'>
        <pose frame=''>0 0 0 0 -0 0</pose>
        <geometry>
          <mesh>
            <scale>1 1 1</scale>
            <uri>model://PONGBOT_Q_V6/meshes/FL_TIP.STL</uri>
          </mesh>
        </geometry>
      </collision>
      <visual name='FL_TIP_visual'>
        <pose frame=''>0 0 0 0 -0 0</pose>
        <geometry>
          <mesh>
            <scale>1 1 1</scale>
            <uri>model://PONGBOT_Q_V6/meshes/FL_TIP.STL</uri>
          </mesh>
        </geometry>
      </visual>
    </link>
    <joint name='FL_TIP_JOINT' type='revolute'>
      <child>FL_TIP</child>
      <parent>FL_CALF</parent>
      <axis>
        <xyz>0 1 0</xyz>
        <limit>
          <lower>-1e+16</lower>
          <upper>1e+16</upper>
        </limit>
        <dynamics>
          <spring_reference>0</spring_reference>
          <spring_stiffness>0</spring_stiffness>
        </dynamics>
        <use_parent_model_frame>1</use_parent_model_frame>
      </axis>
    </joint>
    <link name='FR_HIP'>
      <pose frame=''>0.35 -0.11502 0 0 -0 0</pose>
      <inertial>
        <pose frame=''>0.00113 0.00546 -0.00059 0 -0 0</pose>
        <mass>1.5346</mass>
        <inertia>
          <ixx>0.00131</ixx>
          <ixy>0</ixy>
          <ixz>-1e-05</ixz>
          <iyy>0.00176</iyy>
          <iyz>-1e-05</iyz>
          <izz>0.00141</izz>
        </inertia>
      </inertial>
      <collision name='FR_HIP_collision'>
        <pose frame=''>0 0 0 0 -0 0</pose>
        <geometry>
          <mesh>
            <scale>1 1 1</scale>
            <uri>model://PONGBOT_Q_V6/meshes/FR_HIP.STL</uri>
          </mesh>
        </geometry>
      </collision>
      <visual name='FR_HIP_visual'>
        <pose frame=''>0 0 0 0 -0 0</pose>
        <geometry>
          <mesh>
            <scale>1 1 1</scale>
            <uri>model://PONGBOT_Q_V6/meshes/FR_HIP.STL</uri>
          </mesh>
        </geometry>
      </visual>
    </link>
    <joint name='FR_HR_JOINT' type='revolute'>
      <child>FR_HIP</child>
      <parent>BODY</parent>
      <axis>
        <xyz>1 0 0</xyz>
        <limit>
          <lower>-1e+16</lower>
          <upper>1e+16</upper>
        </limit>
        <dynamics>
          <spring_reference>0</spring_reference>
          <spring_stiffness>0</spring_stiffness>
        </dynamics>
        <use_parent_model_frame>1</use_parent_model_frame>
      </axis>
    </joint>
    <link name='FR_THIGH'>
      <pose frame=''>0.35 -0.21992 0 0 -0 0</pose>
      <inertial>
        <pose frame=''>-0.00018 0.01146 -0.02836 0 -0 0</pose>
        <mass>3.32</mass>
        <inertia>
          <ixx>0.02493</ixx>
          <ixy>-3e-05</ixy>
          <ixz>-2e-05</ixz>
          <iyy>0.02533</iyy>
          <iyz>0.001</iyz>
          <izz>0.00394</izz>
        </inertia>
      </inertial>
      <collision name='FR_THIGH_collision'>
        <pose frame=''>0 0 0 0 -0 0</pose>
        <geometry>
          <mesh>
            <scale>1 1 1</scale>
            <uri>model://PONGBOT_Q_V6/meshes/FR_THIGH.STL</uri>
          </mesh>
        </geometry>
      </collision>
      <visual name='FR_THIGH_visual'>
        <pose frame=''>0 0 0 0 -0 0</pose>
        <geometry>
          <mesh>
            <scale>1 1 1</scale>
            <uri>model://PONGBOT_Q_V6/meshes/FR_THIGH.STL</uri>
          </mesh>
        </geometry>
      </visual>
    </link>
    <joint name='FR_HP_JOINT' type='revolute'>
      <child>FR_THIGH</child>
      <parent>FR_HIP</parent>
      <axis>
        <xyz>0 1 0</xyz>
        <limit>
          <lower>-1e+16</lower>
          <upper>1e+16</upper>
        </limit>
        <dynamics>
          <spring_reference>0</spring_reference>
          <spring_stiffness>0</spring_stiffness>
        </dynamics>
        <use_parent_model_frame>1</use_parent_model_frame>
      </axis>
    </joint>
    <link name='FR_CALF'>
      <pose frame=''>0.35 -0.21992 -0.305 0 -0 0</pose>
      <inertial>
        <pose frame=''>0.03376 -0.00334 -0.0746 0 -0 0</pose>
        <mass>0.57335</mass>
        <inertia>
          <ixx>0.00434</ixx>
          <ixy>7e-05</ixy>
          <ixz>-0.00216</ixz>
          <iyy>0.00538</iyy>
          <iyz>-0.00018</iyz>
          <izz>0.00139</izz>
        </inertia>
      </inertial>
      <collision name='FR_CALF_collision'>
        <pose frame=''>0 0 0 0 -0 0</pose>
        <geometry>
          <mesh>
            <scale>1 1 1</scale>
            <uri>model://PONGBOT_Q_V6/meshes/FR_CALF.STL</uri>
          </mesh>
        </geometry>
      </collision>
      <visual name='FR_CALF_visual'>
        <pose frame=''>0 0 0 0 -0 0</pose>
        <geometry>
          <mesh>
            <scale>1 1 1</scale>
            <uri>model://PONGBOT_Q_V6/meshes/FR_CALF.STL</uri>
          </mesh>
        </geometry>
      </visual>
    </link>
    <joint name='FR_KN_JOINT' type='revolute'>
      <child>FR_CALF</child>
      <parent>FR_THIGH</parent>
      <axis>
        <xyz>0 1 0</xyz>
        <limit>
          <lower>-1e+16</lower>
          <upper>1e+16</upper>
        </limit>
        <dynamics>
          <spring_reference>0</spring_reference>
          <spring_stiffness>0</spring_stiffness>
        </dynamics>
        <use_parent_model_frame>1</use_parent_model_frame>
      </axis>
    </joint>
    <link name='FR_TIP'>
      <pose frame=''>0.46836 -0.21992 -0.56773 0 -0 0</pose>
      <inertial>
        <pose frame=''>-0.00076 0 0.00289 0 -0 0</pose>
        <mass>0.1646</mass>
        <inertia>
          <ixx>9e-05</ixx>
          <ixy>0</ixy>
          <ixz>-1e-05</ixz>
          <iyy>9e-05</iyy>
          <iyz>0</iyz>
          <izz>8e-05</izz>
        </inertia>
      </inertial>
      <collision name='FR_TIP_collision'>
        <pose frame=''>0 0 0 0 -0 0</pose>
        <geometry>
          <mesh>
            <scale>1 1 1</scale>
            <uri>model://PONGBOT_Q_V6/meshes/FR_TIP.STL</uri>
          </mesh>
        </geometry>
      </collision>
      <visual name='FR_TIP_visual'>
        <pose frame=''>0 0 0 0 -0 0</pose>
        <geometry>
          <mesh>
            <scale>1 1 1</scale>
            <uri>model://PONGBOT_Q_V6/meshes/FR_TIP.STL</uri>
          </mesh>
        </geometry>
      </visual>
    </link>
    <joint name='FR_TIP_JOINT' type='revolute'>
      <child>FR_TIP</child>
      <parent>FR_CALF</parent>
      <axis>
        <xyz>0 1 0</xyz>
        <limit>
          <lower>-1e+16</lower>
          <upper>1e+16</upper>
        </limit>
        <dynamics>
          <spring_reference>0</spring_reference>
          <spring_stiffness>0</spring_stiffness>
        </dynamics>
        <use_parent_model_frame>1</use_parent_model_frame>
      </axis>
    </joint>
    <link name='RL_HIP'>
      <pose frame=''>-0.35 0.11502 0 0 -0 0</pose>
      <inertial>
        <pose frame=''>-0.00113 -0.00546 -0.00059 0 -0 0</pose>
        <mass>1.5346</mass>
        <inertia>
          <ixx>0.00131</ixx>
          <ixy>0</ixy>
          <ixz>1e-05</ixz>
          <iyy>0.00176</iyy>
          <iyz>1e-05</iyz>
          <izz>0.00141</izz>
        </inertia>
      </inertial>
      <collision name='RL_HIP_collision'>
        <pose frame=''>0 0 0 0 -0 0</pose>
        <geometry>
          <mesh>
            <scale>1 1 1</scale>
            <uri>model://PONGBOT_Q_V6/meshes/RL_HIP.STL</uri>
          </mesh>
        </geometry>
      </collision>
      <visual name='RL_HIP_visual'>
        <pose frame=''>0 0 0 0 -0 0</pose>
        <geometry>
          <mesh>
            <scale>1 1 1</scale>
            <uri>model://PONGBOT_Q_V6/meshes/RL_HIP.STL</uri>
          </mesh>
        </geometry>
      </visual>
    </link>
    <joint name='RL_HR_JOINT' type='revolute'>
      <child>RL_HIP</child>
      <parent>BODY</parent>
      <axis>
        <xyz>1 0 0</xyz>
        <limit>
          <lower>-1e+16</lower>
          <upper>1e+16</upper>
        </limit>
        <dynamics>
          <spring_reference>0</spring_reference>
          <spring_stiffness>0</spring_stiffness>
        </dynamics>
        <use_parent_model_frame>1</use_parent_model_frame>
      </axis>
    </joint>
    <link name='RL_THIGH'>
      <pose frame=''>-0.35 0.21992 0 0 -0 0</pose>
      <inertial>
        <pose frame=''>0.00018 -0.01146 -0.02836 0 -0 0</pose>
        <mass>3.32</mass>
        <inertia>
          <ixx>0.02493</ixx>
          <ixy>-3e-05</ixy>
          <ixz>2e-05</ixz>
          <iyy>0.02533</iyy>
          <iyz>-0.001</iyz>
          <izz>0.00394</izz>
        </inertia>
      </inertial>
      <collision name='RL_THIGH_collision'>
        <pose frame=''>0 0 0 0 -0 0</pose>
        <geometry>
          <mesh>
            <scale>1 1 1</scale>
            <uri>model://PONGBOT_Q_V6/meshes/RL_THIGH.STL</uri>
          </mesh>
        </geometry>
      </collision>
      <visual name='RL_THIGH_visual'>
        <pose frame=''>0 0 0 0 -0 0</pose>
        <geometry>
          <mesh>
            <scale>1 1 1</scale>
            <uri>model://PONGBOT_Q_V6/meshes/RL_THIGH.STL</uri>
          </mesh>
        </geometry>
      </visual>
    </link>
    <joint name='RL_HP_JOINT' type='revolute'>
      <child>RL_THIGH</child>
      <parent>RL_HIP</parent>
      <axis>
        <xyz>0 1 0</xyz>
        <limit>
          <lower>-1e+16</lower>
          <upper>1e+16</upper>
        </limit>
        <dynamics>
          <spring_reference>0</spring_reference>
          <spring_stiffness>0</spring_stiffness>
        </dynamics>
        <use_parent_model_frame>1</use_parent_model_frame>
      </axis>
    </joint>
    <link name='RL_CALF'>
      <pose frame=''>-0.35 0.21992 -0.305 0 -0 0</pose>
      <inertial>
        <pose frame=''>0.03375 0.00334 -0.0746 0 -0 0</pose>
        <mass>0.57335</mass>
        <inertia>
          <ixx>0.00434</ixx>
          <ixy>-7e-05</ixy>
          <ixz>-0.0021615</ixz>
          <iyy>0.00538</iyy>
          <iyz>0.00018</iyz>
          <izz>0.00139</izz>
        </inertia>
      </inertial>
      <collision name='RL_CALF_collision'>
        <pose frame=''>0 0 0 0 -0 0</pose>
        <geometry>
          <mesh>
            <scale>1 1 1</scale>
            <uri>model://PONGBOT_Q_V6/meshes/RL_CALF.STL</uri>
          </mesh>
        </geometry>
      </collision>
      <visual name='RL_CALF_visual'>
        <pose frame=''>0 0 0 0 -0 0</pose>
        <geometry>
          <mesh>
            <scale>1 1 1</scale>
            <uri>model://PONGBOT_Q_V6/meshes/RL_CALF.STL</uri>
          </mesh>
        </geometry>
      </visual>
    </link>
    <joint name='RL_KN_JOINT' type='revolute'>
      <child>RL_CALF</child>
      <parent>RL_THIGH</parent>
      <axis>
        <xyz>0 1 0</xyz>
        <limit>
          <lower>-1e+16</lower>
          <upper>1e+16</upper>
        </limit>
        <dynamics>
          <spring_reference>0</spring_reference>
          <spring_stiffness>0</spring_stiffness>
        </dynamics>
        <use_parent_model_frame>1</use_parent_model_frame>
      </axis>
    </joint>
    <link name='RL_TIP'>
      <pose frame=''>-0.23164 0.21992 -0.56773 0 -0 0</pose>
      <inertial>
        <pose frame=''>-0.00076 0 0.00289 0 -0 0</pose>
        <mass>0.1646</mass>
        <inertia>
          <ixx>9e-05</ixx>
          <ixy>0</ixy>
          <ixz>-1e-05</ixz>
          <iyy>9e-05</iyy>
          <iyz>0</iyz>
          <izz>8e-05</izz>
        </inertia>
      </inertial>
      <collision name='RL_TIP_collision'>
        <pose frame=''>0 0 0 0 -0 0</pose>
        <geometry>
          <mesh>
            <scale>1 1 1</scale>
            <uri>model://PONGBOT_Q_V6/meshes/RL_TIP.STL</uri>
          </mesh>
        </geometry>
      </collision>
      <visual name='RL_TIP_visual'>
        <pose frame=''>0 0 0 0 -0 0</pose>
        <geometry>
          <mesh>
            <scale>1 1 1</scale>
            <uri>model://PONGBOT_Q_V6/meshes/RL_TIP.STL</uri>
          </mesh>
        </geometry>
      </visual>
    </link>
    <joint name='RL_TIP_JOINT' type='revolute'>
      <child>RL_TIP</child>
      <parent>RL_CALF</parent>
      <axis>
        <xyz>0 -1 0</xyz>
        <limit>
          <lower>-1e+16</lower>
          <upper>1e+16</upper>
        </limit>
        <dynamics>
          <spring_reference>0</spring_reference>
          <spring_stiffness>0</spring_stiffness>
        </dynamics>
        <use_parent_model_frame>1</use_parent_model_frame>
      </axis>
    </joint>
    <link name='RR_HIP'>
      <pose frame=''>-0.35 -0.11502 0 0 -0 0</pose>
      <inertial>
        <pose frame=''>-0.00113 0.00546 0.00059 0 -0 0</pose>
        <mass>1.5346</mass>
        <inertia>
          <ixx>0.00131</ixx>
          <ixy>0</ixy>
          <ixz>-1e-05</ixz>
          <iyy>0.00176</iyy>
          <iyz>1e-05</iyz>
          <izz>0.00141</izz>
        </inertia>
      </inertial>
      <collision name='RR_HIP_collision'>
        <pose frame=''>0 0 0 0 -0 0</pose>
        <geometry>
          <mesh>
            <scale>1 1 1</scale>
            <uri>model://PONGBOT_Q_V6/meshes/RR_HIP.STL</uri>
          </mesh>
        </geometry>
      </collision>
      <visual name='RR_HIP_visual'>
        <pose frame=''>0 0 0 0 -0 0</pose>
        <geometry>
          <mesh>
            <scale>1 1 1</scale>
            <uri>model://PONGBOT_Q_V6/meshes/RR_HIP.STL</uri>
          </mesh>
        </geometry>
      </visual>
    </link>
    <joint name='RR_HR_JOINT' type='revolute'>
      <child>RR_HIP</child>
      <parent>BODY</parent>
      <axis>
        <xyz>1 0 0</xyz>
        <limit>
          <lower>-1e+16</lower>
          <upper>1e+16</upper>
        </limit>
        <dynamics>
          <spring_reference>0</spring_reference>
          <spring_stiffness>0</spring_stiffness>
        </dynamics>
        <use_parent_model_frame>1</use_parent_model_frame>
      </axis>
    </joint>
    <link name='RR_THIGH'>
      <pose frame=''>-0.35 -0.21992 0 0 -0 0</pose>
      <inertial>
        <pose frame=''>-0.00018 0.01146 -0.02836 0 -0 0</pose>
        <mass>3.32</mass>
        <inertia>
          <ixx>0.02493</ixx>
          <ixy>-3e-05</ixy>
          <ixz>-2e-05</ixz>
          <iyy>0.028</iyy>
          <iyz>0.001</iyz>
          <izz>0.00394</izz>
        </inertia>
      </inertial>
      <collision name='RR_THIGH_collision'>
        <pose frame=''>0 0 0 0 -0 0</pose>
        <geometry>
          <mesh>
            <scale>1 1 1</scale>
            <uri>model://PONGBOT_Q_V6/meshes/RR_THIGH.STL</uri>
          </mesh>
        </geometry>
      </collision>
      <visual name='RR_THIGH_visual'>
        <pose frame=''>0 0 0 0 -0 0</pose>
        <geometry>
          <mesh>
            <scale>1 1 1</scale>
            <uri>model://PONGBOT_Q_V6/meshes/RR_THIGH.STL</uri>
          </mesh>
        </geometry>
      </visual>
    </link>
    <joint name='RR_HP_JOINT' type='revolute'>
      <child>RR_THIGH</child>
      <parent>RR_HIP</parent>
      <axis>
        <xyz>0 1 0</xyz>
        <limit>
          <lower>-1e+16</lower>
          <upper>1e+16</upper>
        </limit>
        <dynamics>
          <spring_reference>0</spring_reference>
          <spring_stiffness>0</spring_stiffness>
        </dynamics>
        <use_parent_model_frame>1</use_parent_model_frame>
      </axis>
    </joint>
    <link name='RR_CALF'>
      <pose frame=''>-0.35 -0.21992 -0.305 0 -0 0</pose>
      <inertial>
        <pose frame=''>0.03376 -0.00334 -0.0746 0 -0 0</pose>
        <mass>0.57335</mass>
        <inertia>
          <ixx>0.00434</ixx>
          <ixy>7e-05</ixy>
          <ixz>-0.00216</ixz>
          <iyy>0.00538</iyy>
          <iyz>-0.00018</iyz>
          <izz>0.00139</izz>
        </inertia>
      </inertial>
      <collision name='RR_CALF_collision'>
        <pose frame=''>0 0 0 0 -0 0</pose>
        <geometry>
          <mesh>
            <scale>1 1 1</scale>
            <uri>model://PONGBOT_Q_V6/meshes/RR_CALF.STL</uri>
          </mesh>
        </geometry>
      </collision>
      <visual name='RR_CALF_visual'>
        <pose frame=''>0 0 0 0 -0 0</pose>
        <geometry>
          <mesh>
            <scale>1 1 1</scale>
            <uri>model://PONGBOT_Q_V6/meshes/RR_CALF.STL</uri>
          </mesh>
        </geometry>
      </visual>
    </link>
    <joint name='RR_KN_JOINT' type='revolute'>
      <child>RR_CALF</child>
      <parent>RR_THIGH</parent>
      <axis>
        <xyz>0 1 0</xyz>
        <limit>
          <lower>-1e+16</lower>
          <upper>1e+16</upper>
        </limit>
        <dynamics>
          <spring_reference>0</spring_reference>
          <spring_stiffness>0</spring_stiffness>
        </dynamics>
        <use_parent_model_frame>1</use_parent_model_frame>
      </axis>
    </joint>
    <link name='RR_TIP'>
      <pose frame=''>-0.23164 -0.21992 -0.56773 0 -0 0</pose>
      <inertial>
        <pose frame=''>-0.00076 0 0.00289 0 -0 0</pose>
        <mass>0.1646</mass>
        <inertia>
          <ixx>9e-05</ixx>
          <ixy>0</ixy>
          <ixz>-1e-05</ixz>
          <iyy>9e-05</iyy>
          <iyz>0</iyz>
          <izz>8e-05</izz>
        </inertia>
      </inertial>
      <collision name='RR_TIP_collision'>
        <pose frame=''>0 0 0 0 -0 0</pose>
        <geometry>
          <mesh>
            <scale>1 1 1</scale>
            <uri>model://PONGBOT_Q_V6/meshes/RR_TIP.STL</uri>
          </mesh>
        </geometry>
      </collision>
      <visual name='RR_TIP_visual'>
        <pose frame=''>0 0 0 0 -0 0</pose>
        <geometry>
          <mesh>
            <scale>1 1 1</scale>
            <uri>model://PONGBOT_Q_V6/meshes/RR_TIP.STL</uri>
          </mesh>
        </geometry>
      </visual>
    </link>
    <joint name='RR_TIP_JOINT' type='revolute'>
      <child>RR_TIP</child>
      <parent>RR_CALF</parent>
      <axis>
        <xyz>0 1 0</xyz>
        <limit>
          <lower>-1e+16</lower>
          <upper>1e+16</upper>
        </limit>
        <dynamics>
          <spring_reference>0</spring_reference>
          <spring_stiffness>0</spring_stiffness>
        </dynamics>
        <use_parent_model_frame>1</use_parent_model_frame>
      </axis>
    </joint>
  </model>
</sdf>
