<robot
  name="segway_hsk">
  <link
    name="body">
    <inertial>
      <origin
        xyz="0.0044417 0.0037232 0.1937"
        rpy="0 0 0" />
      <mass
        value="30.923" />
      <inertia
        ixx="4.4396"
        ixy="-0.016922"
        ixz="0.030132"
        iyy="4.1418"
        iyz="0.031966"
        izz="0.68573" />
    </inertial>
    <visual>
      <origin
        xyz="0 0 0"
        rpy="0 0 0" />
      <geometry>
        <mesh
          filename="package://segway_hsk/meshes/body.STL" />
      </geometry>
      <material
        name="">
        <color
          rgba="0.75294 0.75294 0.75294 1" />
      </material>
    </visual>
    <collision>
      <origin
        xyz="0 0 0"
        rpy="0 0 0" />
      <geometry>
        <mesh
          filename="package://segway_hsk/meshes/body.STL" />
      </geometry>
    </collision>
  </link>
  <link
    name="right_wheel">
    <inertial>
      <origin
        xyz="-1.87689058739338E-10 -2.95202132048755E-06 5.09023934114339E-11"
        rpy="0 0 0" />
      <mass
        value="0.848884917782349" />
      <inertia
        ixx="0.0108165340138563"
        ixy="-5.98586064755307E-12"
        ixz="-8.53897139628523E-13"
        iyy="0.0214793018135476"
        iyz="2.64444976697541E-12"
        izz="0.0108165340125372" />
    </inertial>
    <visual>
      <origin
        xyz="0 0 0"
        rpy="0 0 0" />
      <geometry>
        <mesh
          filename="package://segway_hsk/meshes/right_wheel.STL" />
      </geometry>
      <material
        name="">
        <color
          rgba="0.698039215686274 0.698039215686274 0.698039215686274 1" />
      </material>
    </visual>
    <collision>
      <origin
        xyz="0 0 0"
        rpy="0 0 0" />
      <geometry>
        <mesh
          filename="package://segway_hsk/meshes/right_wheel.STL" />
      </geometry>
    </collision>
  </link>
  <joint
    name="right_wheel_joint"
    type="continuous">
    <origin
      xyz="0 -0.28582 0"
      rpy="3.1416 1.4162 -3.1416" />
    <parent
      link="body" />
    <child
      link="right_wheel" />
    <axis
      xyz="0 1 0" />
  </joint>
  <link
    name="left_wheel">
    <inertial>
      <origin
        xyz="1.06409991929013E-10 2.95202132044592E-06 -1.62773350353973E-10"
        rpy="0 0 0" />
      <mass
        value="0.84888491778235" />
      <inertia
        ixx="0.010816534013165"
        ixy="-4.36475213520602E-12"
        ixz="-1.07849124596215E-12"
        iyy="0.0214793018135476"
        iyz="4.87571205186164E-12"
        izz="0.0108165340132284" />
    </inertial>
    <visual>
      <origin
        xyz="0 0 0"
        rpy="0 0 0" />
      <geometry>
        <mesh
          filename="package://segway_hsk/meshes/left_wheel.STL" />
      </geometry>
      <material
        name="">
        <color
          rgba="0.698039215686274 0.698039215686274 0.698039215686274 1" />
      </material>
    </visual>
    <collision>
      <origin
        xyz="0 0 0"
        rpy="0 0 0" />
      <geometry>
        <mesh
          filename="package://segway_hsk/meshes/left_wheel.STL" />
      </geometry>
    </collision>
  </link>
  <joint
    name="left_wheel_joint"
    type="continuous">
    <origin
      xyz="0 0.28582 0"
      rpy="3.1416 1.3432 3.1416" />
    <parent
      link="body" />
    <child
      link="left_wheel" />
    <axis
      xyz="0 -1 0" />
  </joint>
</robot>