<robot
  name="PONGBOT_Q_V3">
  <link
    name="REAR_BODY">
    <inertial>
      <origin
        xyz="0.11696 0 0.02213"
        rpy="0 0 0" />
      <mass
        value="8.0066" />
      <inertia
        ixx="0.07772"
        ixy="0"
        ixz="0"
        iyy="0.13680"
        iyz="0"
        izz="0.18194" />
    </inertial>
  </link>
  <link
    name="FRONT_BODY">
    <inertial>
      <origin
        xyz="0.27604 0 0.02529"
        rpy="0 0 0" />
      <mass
        value="8.97286" />
      <inertia
        ixx="0.11819"
        ixy="0"
        ixz="0"
        iyy="0.13516"
        iyz="0"
        izz="0.15248" />
    </inertial>
  </link>
  <joint
    name="WAIST_JOINT"
    type="continuous">
    <origin
      xyz="0.35 0 0.03586"
      rpy="0 0 0" />
    <parent
      link="REAR_BODY" />
    <child
      link="FRONT_BODY" />
    <axis
      xyz="0 0 1" />
  </joint>
  <link
    name="FL_HIP">
    <inertial>
      <origin
        xyz="0.00094 0.00004 0"
        rpy="0 0 0" />
      <mass
        value="1.11213" />
      <inertia
        ixx="0.00112"
        ixy="0"
        ixz="0"
        iyy="0.00121"
        iyz="0"
        izz="0.00122" />
    </inertial>
  </link>
  <joint
    name="FL_HR_JOINT"
    type="continuous">
    <origin
      xyz="0.35 0.115 -0.03555"
      rpy="0 0 0" />
    <parent
      link="FRONT_BODY" />
    <child
      link="FL_HIP" />
    <axis
      xyz="1 0 0" />
  </joint>
  <link
    name="FL_THIGH">
    <inertial>
      <origin
        xyz="-0.0017 -0.00992 -0.03383"
        rpy="0 0 0" />
      <mass
        value="2.16823" />
      <inertia
        ixx="0.01528"
        ixy="0"
        ixz="0"
        iyy="0.01528"
        iyz="0"
        izz="0.00242" />
    </inertial>
  </link>
  <joint
    name="FL_HP_JOINT"
    type="continuous">
    <origin
      xyz="0 0.105 0"
      rpy="0 0 0" />
    <parent
      link="FL_HIP" />
    <child
      link="FL_THIGH" />
    <axis
      xyz="0 1 0" />
  </joint>
  <link
    name="FL_CALF">
    <inertial>
      <origin
        xyz="-0.00251 0.00215 -0.05285"
        rpy="0 0 0" />
      <mass
        value="0.35185" />
      <inertia
        ixx="0.00338"
        ixy="0"
        ixz="0"
        iyy="0.00329"
        iyz="0"
        izz="0.00018" />
    </inertial>
  </link>
  <joint
    name="FL_KN_JOINT"
    type="continuous">
    <origin
      xyz="0 0 -0.305"
      rpy="0 0 0" />
    <parent
      link="FL_THIGH" />
    <child
      link="FL_CALF" />
    <axis
      xyz="0 1 0" />
  </joint>
  <link
    name="FL_TIP">
    <inertial>
      <origin
        xyz="-0.00459 0 -0.00459"
        rpy="0 0 0" />
      <mass
        value="0.046" />
      <inertia
        ixx="0.00002"
        ixy="0"
        ixz="0"
        iyy="0.00001"
        iyz="0"
        izz="0.00001" />
    </inertial>
  </link>
  <joint
    name="FL_TIP_JOINT"
    type="fixed">
    <origin
      xyz="-0.01555 0 -0.2945"
      rpy="0 0 0" />
    <parent
      link="FL_CALF" />
    <child
      link="FL_TIP" />
    <axis
      xyz="0.70711 0 0.70711" />
  </joint>
  <link
    name="FR_HIP">
    <inertial>
      <origin
        xyz="0.00094 -0.00004 0"
        rpy="0 0 0" />
      <mass
        value="1.11213" />
      <inertia
        ixx="0.00112"
        ixy="0"
        ixz="0"
        iyy="0.00121"
        iyz="0"
        izz="0.00122" />
    </inertial>
  </link>
  <joint
    name="FR_HR_JOINT"
    type="continuous">
    <origin
      xyz="0.35 -0.115 -0.03555"
      rpy="0 -1.4358E-31 0" />
    <parent
      link="FRONT_BODY" />
    <child
      link="FR_HIP" />
    <axis
      xyz="1 0 0" />
  </joint>
  <link
    name="FR_THIGH">
    <inertial>
      <origin
        xyz="-0.0017 0.00992 -0.03383"
        rpy="0 0 0" />
      <mass
        value="2.16823" />
      <inertia
        ixx="0.01528"
        ixy="0"
        ixz="0"
        iyy="0.01528"
        iyz="0"
        izz="0.00242" />
    </inertial>
  </link>
  <joint
    name="FR_HP_JOINT"
    type="continuous">
    <origin
      xyz="0 -0.105 0"
      rpy="0 0 0" />
    <parent
      link="FR_HIP" />
    <child
      link="FR_THIGH" />
    <axis
      xyz="0 1 0" />
  </joint>
  <link
    name="FR_CALF">
    <inertial>
      <origin
        xyz="-0.00251 -0.00215 -0.05285"
        rpy="0 0 0" />
      <mass
        value="0.35185" />
      <inertia
        ixx="0.00338"
        ixy="0"
        ixz="0"
        iyy="0.00329"
        iyz="0"
        izz="0.00018" />
    </inertial>
  </link>
  <joint
    name="FR_KN_JOINT"
    type="continuous">
    <origin
      xyz="0 0 -0.305"
      rpy="0 0 0" />
    <parent
      link="FR_THIGH" />
    <child
      link="FR_CALF" />
    <axis
      xyz="0 1 0" />
  </joint>
  <link
    name="FR_TIP">
    <inertial>
      <origin
        xyz="-0.00459 -0 -0.00459"
        rpy="0 0 0" />
      <mass
        value="0.046" />
      <inertia
        ixx="0.00002"
        ixy="0"
        ixz="0"
        iyy="0.00001"
        iyz="0"
        izz="0.00001" />
    </inertial>
  </link>
  <joint
    name="FR_TIP_JOINT"
    type="fixed">
    <origin
      xyz="-0.01555 0 -0.2945"
      rpy="0 0 0" />
    <parent
      link="FR_CALF" />
    <child
      link="FR_TIP" />
    <axis
      xyz="0.70711 0 0.70711" />
  </joint>
  <link
    name="RL_HIP">
    <inertial>
      <origin
        xyz="-0.00094 0.00004 0"
        rpy="0 0 0" />
      <mass
        value="1.11213" />
      <inertia
        ixx="0.00112"
        ixy="0"
        ixz="0"
        iyy="0.00121"
        iyz="0"
        izz="0.00122" />
    </inertial>
  </link>
  <joint
    name="RL_HR_JOINT"
    type="continuous">
    <origin
      xyz="0 0.115 0"
      rpy="0 0 0" />
    <parent
      link="REAR_BODY" />
    <child
      link="RL_HIP" />
    <axis
      xyz="1 0 0" />
  </joint>
  <link
    name="RL_THIGH">
    <inertial>
      <origin
        xyz="-0.00246 -0.00992 -0.03383"
        rpy="0 0 0" />
      <mass
        value="2.16823" />
      <inertia
        ixx="0.01528"
        ixy="0"
        ixz="0"
        iyy="0.01528"
        iyz="0"
        izz="0.00242" />
    </inertial>
  </link>
  <joint
    name="RL_HP_JOINT"
    type="continuous">
    <origin
      xyz="0 0.105 0"
      rpy="0 0 0" />
    <parent
      link="RL_HIP" />
    <child
      link="RL_THIGH" />
    <axis
      xyz="0 1 0" />
  </joint>
  <link
    name="RL_CALF">
    <inertial>
      <origin
        xyz="-0.00335 0.00215 -0.05285"
        rpy="0 0 0" />
      <mass
        value="0.35185" />
      <inertia
        ixx="0.00338"
        ixy="0"
        ixz="0"
        iyy="0.00329"
        iyz="0"
        izz="0.00018" />
    </inertial>
  </link>
  <joint
    name="RL_KN_JOINT"
    type="continuous">
    <origin
      xyz="0 0 -0.305"
      rpy="0 0 0" />
    <parent
      link="RL_THIGH" />
    <child
      link="RL_CALF" />
    <axis
      xyz="0 1 0" />
  </joint>
  <link
    name="RL_TIP">
    <inertial>
      <origin
        xyz="-0.00469 0 -0.00459"
        rpy="0 0 0" />
      <mass
        value="0.046" />
      <inertia
        ixx="0.00002"
        ixy="0"
        ixz="0"
        iyy="0.00001"
        iyz="0"
        izz="0.00001" />
    </inertial>
  </link>
  <joint
    name="RL_TIP_JOINT"
    type="fixed">
    <origin
      xyz="-0.01555 0 -0.2945"
      rpy="0 0 0" />
    <parent
      link="RL_CALF" />
    <child
      link="RL_TIP" />
    <axis
      xyz="0.70711 0 0.70711" />
  </joint>
  <link
    name="RR_HIP">
    <inertial>
      <origin
        xyz="-0.00094 -0.00004 0"
        rpy="0 0 0" />
      <mass
        value="1.11213" />
      <inertia
        ixx="0.00112"
        ixy="0"
        ixz="0"
        iyy="0.00121"
        iyz="0"
        izz="0.00122" />
    </inertial>
  </link>
  <joint
    name="RR_HR_JOINT"
    type="continuous">
    <origin
      xyz="0 -0.115 0"
      rpy="0 0 0" />
    <parent
      link="REAR_BODY" />
    <child
      link="RR_HIP" />
    <axis
      xyz="1 0 0" />
  </joint>
  <link
    name="RR_THIGH">
    <inertial>
      <origin
        xyz="-0.00246 0.00992 -0.03383"
        rpy="0 0 0" />
      <mass
        value="2.16823" />
      <inertia
        ixx="0.01528"
        ixy="0"
        ixz="0"
        iyy="0.01528"
        iyz="0"
        izz="0.00242" />
    </inertial>
  </link>
  <joint
    name="RR_HP_JOINT"
    type="continuous">
    <origin
      xyz="0 -0.105 0"
      rpy="0 0 0" />
    <parent
      link="RR_HIP" />
    <child
      link="RR_THIGH" />
    <axis
      xyz="0 1 0" />
  </joint>
  <link
    name="RR_CALF">
    <inertial>
      <origin
        xyz="-0.00335 -0.00215 -0.05285"
        rpy="0 0 0" />
      <mass
        value="0.35185" />
      <inertia
        ixx="0.00338"
        ixy="0"
        ixz="0"
        iyy="0.00329"
        iyz="0"
        izz="0.00018" />
    </inertial>
  </link>
  <joint
    name="RR_KN_JOINT"
    type="continuous">
    <origin
      xyz="0 0 -0.305"
      rpy="0 0 0" />
    <parent
      link="RR_THIGH" />
    <child
      link="RR_CALF" />
    <axis
      xyz="0 1 0" />
  </joint>
  <link
    name="RR_TIP">
    <inertial>
      <origin
        xyz="-0.00469 0 -0.00459"
        rpy="0 0 0" />
      <mass
        value="0.046" />
      <inertia
        ixx="0.00002"
        ixy="0"
        ixz="0"
        iyy="0.00001"
        iyz="0"
        izz="0.00001" />
    </inertial>
  </link>
  <joint
    name="RR_TIP_JOINT"
    type="fixed">
    <origin
      xyz="-0.01555 0 -0.2945"
      rpy="0 0 0" />
    <parent
      link="RR_CALF" />
    <child
      link="RR_TIP" />
    <axis
      xyz="0.70711 0 0.70711" />
  </joint>
</robot>
