<?xml version="1.0" ?>
<sdf version='1.6'>
  <model name='PONGBOT_Q_V3'>
    <!-- 
  <joint name="fixed to ground" type="fixed">
    <parent>world</parent>
    <child>REAR_BODY</child>
  </joint>
-->
    <link name='REAR_BODY'>
      <pose frame=''>0 0 0 0 -0 0</pose>
      <inertial>
        <pose frame=''>0.11696 0 0.02213 0 -0 0</pose>
        <mass>14.0</mass>
        <inertia>
          <ixx>0.07772</ixx>
          <ixy>0</ixy>
          <ixz>0</ixz>
          <iyy>0.1368</iyy>
          <iyz>0</iyz>
          <izz>0.18194</izz>
        </inertia>
      </inertial>
      <visual name='REAR_BODY_visual'>
        <pose frame=''>0 0 0 0 -0 0</pose>
        <geometry>
          <mesh>
            <scale>1 1 1</scale>
            <uri>model://PONGBOT_Q_V3/meshes/REAR_BODY.STL</uri>
          </mesh>
        </geometry>
        <material>
          <ambient>97 97 97 1</ambient>
          <diffuse>1 1 1 1</diffuse>
          <emissive>0 0 0 0</emissive>
          <specular>0 0 0 0</specular>
        </material>
      </visual>
      <sensor name='IMU' type='imu'>
        <pose frame=''>0.354 0 -0.018 0 -0 0</pose>
        <imu>
          <angular_velocity>
            <x>
              <noise type='none'></noise>
            </x>
            <y>
              <noise type='none'></noise>
            </y>
            <z>
              <noise type='none'></noise>
            </z>
          </angular_velocity>
          <linear_acceleration>
            <x>
              <noise type='none'></noise>
            </x>
            <y>
              <noise type="none"></noise>
            </y>
            <z>
              <noise type='none'></noise>
            </z>
          </linear_acceleration>
        </imu>
        <always_on>1</always_on>
        <update_rate>1000</update_rate>
        <!-- <visualize>true</visualize> -->
      </sensor>
    </link>
    <link name='RL_HIP'>
      <pose frame=''>0 0.115 0 0 -0 0</pose>
      <inertial>
        <pose frame=''>-0.00094 4e-05 0 0 -0 0</pose>
        <mass>1.11213</mass>
        <inertia>
          <ixx>0.00112</ixx>
          <ixy>0</ixy>
          <ixz>0</ixz>
          <iyy>0.00121</iyy>
          <iyz>0</iyz>
          <izz>0.00122</izz>
        </inertia>
      </inertial>
      <visual name='RL_HIP_visual'>
        <pose frame=''>0 0 0 0 -0 0</pose>
        <geometry>
          <mesh>
            <scale>1 1 1</scale>
            <uri>model://PONGBOT_Q_V3/meshes/RL_HIP.STL</uri>
          </mesh>
        </geometry>
        <material>
          <ambient>213 0 0 1</ambient>
          <diffuse>1 1 1 1</diffuse>
          <emissive>0 0 0 1</emissive>
          <specular>0 0 0 0</specular>
        </material>
      </visual>
    </link>
    <joint name='RL_HR_JOINT' type='revolute'>
      <child>RL_HIP</child>
      <parent>REAR_BODY</parent>
      <axis>
        <xyz>1 0 0</xyz>
        <limit>
          <lower>-3.141592</lower>
          <upper>3.141592</upper>
        </limit>
        <dynamics>
          <spring_reference>0</spring_reference>
          <spring_stiffness>0</spring_stiffness>
        </dynamics>
        <use_parent_model_frame>1</use_parent_model_frame>
      </axis>
    </joint>
    <link name='RL_THIGH'>
      <pose frame=''>0 0.22 0 0 -0 0</pose>
      <inertial>
        <pose frame=''>-0.00246 -0.00992 -0.03383 0 -0 0</pose>
        <mass>2.16823</mass>
        <inertia>
          <ixx>0.01528</ixx>
          <ixy>0</ixy>
          <ixz>0</ixz>
          <iyy>0.01528</iyy>
          <iyz>0</iyz>
          <izz>0.00242</izz>
        </inertia>
      </inertial>
      <visual name='RL_THIGH_visual'>
        <pose frame=''>0 0 0 0 -0 0</pose>
        <geometry>
          <mesh>
            <scale>1 1 1</scale>
            <uri>model://PONGBOT_Q_V3/meshes/RL_THIGH.STL</uri>
          </mesh>
        </geometry>
        <material>
          <ambient>213 0 0 1</ambient>
          <diffuse>1 1 1 1</diffuse>
          <emissive>0 0 0 1</emissive>
          <specular>0 0 0 0</specular>
        </material>
      </visual>
    </link>
    <joint name='RL_HP_JOINT' type='revolute'>
      <child>RL_THIGH</child>
      <parent>RL_HIP</parent>
      <axis>
        <xyz>0 1 0</xyz>
        <limit>
          <lower>-3.141592</lower>
          <upper>3.141592</upper>
        </limit>
        <dynamics>
          <spring_reference>0</spring_reference>
          <spring_stiffness>0</spring_stiffness>
        </dynamics>
        <use_parent_model_frame>1</use_parent_model_frame>
      </axis>
    </joint>

    <link name='RL_CALF'>
      <pose frame=''>0 0.22 -0.305 0 -0 0</pose>
      <inertial>
        <pose frame=''>-0.005303 0.001901 -0.081321 0 -0 0</pose>
        <mass>0.39785</mass>
        <inertia>
          <ixx>0.00586687</ixx>
          <ixy>0</ixy>
          <ixz>0</ixz>
          <iyy>0.00577829</iyy>
          <iyz>0</iyz>
          <izz>0.000201793</izz>
        </inertia>
      </inertial>
      <visual name='RL_CALF_visual'>
        <pose frame=''>0 0 0 0 -0 0</pose>
        <geometry>
          <mesh>
            <scale>1 1 1</scale>
            <uri>model://PONGBOT_Q_V3/meshes/RL_CALF.STL</uri>
          </mesh>
        </geometry>
        <material>
          <ambient>33 33 33 1</ambient>
          <diffuse>1 1 1 1</diffuse>
          <emissive>0 0 0 1</emissive>
          <specular>0 0 0 0</specular>
        </material>
      </visual>
    </link>

    <joint name='RL_KN_JOINT' type='revolute'>
      <child>RL_CALF</child>
      <parent>RL_THIGH</parent>
      <axis>
        <xyz>0 1 0</xyz>
        <limit>
          <lower>-3.141592</lower>
          <upper>3.141592</upper>
        </limit>
        <dynamics>
          <spring_reference>0</spring_reference>
          <spring_stiffness>0</spring_stiffness>
        </dynamics>
        <use_parent_model_frame>1</use_parent_model_frame>
      </axis>
    </joint>

    <link name='RL_TIP'>
      <pose frame=''>-0.01555 0.21895 -0.59955 0 -0 0</pose>
      <inertial>
        <pose frame=''>0 0 0 0 0 0</pose>
         <mass>0.046</mass>
        <inertia>
          <ixx>0.0001</ixx>
          <ixy>0</ixy>
          <ixz>0</ixz>
          <iyy>0.0002</iyy>
          <iyz>0</iyz>
          <izz>0.0001</izz>
        </inertia>
      </inertial>
      <collision name='RL_TIP_collision'>
        <pose frame=''>0 0 0 0 0 0</pose>
        <geometry>
          <sphere>
            <radius> .015 </radius>
          </sphere>
        </geometry>
        <surface>
          <bounce>
            <restitution_coefficient> 0 </restitution_coefficient>
          </bounce>
          <friction>
            <ode>
               <mu>  1  </mu>
              <mu2> 1  </mu2>
            </ode>
          </friction>
          <contact>
            <ode>
              <!-- <soft_erp> 0.1 </soft_erp>
              <soft_cfm> 1E-4 </soft_cfm> -->
              <kp>5000000</kp>
              <kd>5000</kd>
              <max_vel>0.1</max_vel>
              <min_depth>0.0001</min_depth>
            </ode>
          </contact>
        </surface>
      </collision>
      <visual name='RL_TIP_visual'>
        <pose frame=''>0 0 0 0 0 0</pose>
        <geometry>
          <mesh>
            <uri>model://PONGBOT_Q_V3/meshes/RL_TIP.STL</uri>
            <scale>1 1 1</scale>
          </mesh>
        </geometry>
      </visual>
      <sensor name="RL_TIP_contact" type='contact'>
       <contact>
         <collision>RL_TIP_collision</collision>
       </contact>
      </sensor>
    </link>

    <joint name="RL_TIP_JOINT" type="fixed">
      <child>RL_TIP</child>
      <parent>RL_CALF</parent>
      <sensor name="RL_FT_SENSOR" type="force_torque">
        <force_torque>
          <frame>child</frame>
          <measure_direction>child_to_parent</measure_direction>
        </force_torque>
        <!-- <visualize> True </visualize> -->
      </sensor>
    </joint>

    <link name='RR_HIP'>
      <pose frame=''>0 -0.115 0 0 -0 0</pose>
      <inertial>
        <pose frame=''>-0.00094 -4e-05 0 0 -0 0</pose>
        <mass>1.11213</mass>
        <inertia>
          <ixx>0.00112</ixx>
          <ixy>0</ixy>
          <ixz>0</ixz>
          <iyy>0.00121</iyy>
          <iyz>0</iyz>
          <izz>0.00122</izz>
        </inertia>
      </inertial>
      <visual name='RR_HIP_visual'>
        <pose frame=''>0 0 0 0 -0 0</pose>
        <geometry>
          <mesh>
            <scale>1 1 1</scale>
            <uri>model://PONGBOT_Q_V3/meshes/RR_HIP.STL</uri>
          </mesh>
        </geometry>
        <material>
          <ambient>213 0 0 1</ambient>
          <diffuse>1 1 1 1</diffuse>
          <emissive>0 0 0 1</emissive>
          <specular>0 0 0 0</specular>
        </material>
      </visual>
    </link>
    <joint name='RR_HR_JOINT' type='revolute'>
      <child>RR_HIP</child>
      <parent>REAR_BODY</parent>
      <axis>
        <xyz>1 0 0</xyz>
        <limit>
          <lower>-3.141592</lower>
          <upper>3.141592</upper>
        </limit>
        <dynamics>
          <spring_reference>0</spring_reference>
          <spring_stiffness>0</spring_stiffness>
        </dynamics>
        <use_parent_model_frame>1</use_parent_model_frame>
      </axis>
    </joint>
    <link name='RR_THIGH'>
      <pose frame=''>0 -0.22 0 0 -0 0</pose>
      <inertial>
        <pose frame=''>-0.00246 0.00992 -0.03383 0 -0 0</pose>
        <mass>2.16823</mass>
        <inertia>
          <ixx>0.01528</ixx>
          <ixy>0</ixy>
          <ixz>0</ixz>
          <iyy>0.01528</iyy>
          <iyz>0</iyz>
          <izz>0.00242</izz>
        </inertia>
      </inertial>
      <visual name='RR_THIGH_visual'>
        <pose frame=''>0 0 0 0 -0 0</pose>
        <geometry>
          <mesh>
            <scale>1 1 1</scale>
            <uri>model://PONGBOT_Q_V3/meshes/RR_THIGH.STL</uri>
          </mesh>
        </geometry>
        <material>
          <ambient>213 0 0 1</ambient>
          <diffuse>1 1 1 1</diffuse>
          <emissive>0 0 0 1</emissive>
          <specular>0 0 0 0</specular>
        </material>
      </visual>
    </link>
    <joint name='RR_HP_JOINT' type='revolute'>
      <child>RR_THIGH</child>
      <parent>RR_HIP</parent>
      <axis>
        <xyz>0 1 0</xyz>
        <limit>
          <lower>-3.141592</lower>
          <upper>3.141592</upper>
        </limit>
        <dynamics>
          <spring_reference>0</spring_reference>
          <spring_stiffness>0</spring_stiffness>
        </dynamics>
        <use_parent_model_frame>1</use_parent_model_frame>
      </axis>
    </joint>
    <link name='RR_CALF'>
      <pose frame=''>0 -0.22 -0.305 0 -0 0</pose>
      <inertial>
        <pose frame=''>-0.005303 -0.001901 -0.081321 0 -0 0</pose>
        <mass>0.39785</mass>
        <inertia>
          <ixx>0.00586687</ixx>
          <ixy>0</ixy>
          <ixz>0</ixz>
          <iyy>0.00577829</iyy>
          <iyz>0</iyz>
          <izz>0.000201793</izz>
        </inertia>
      </inertial>
      <visual name='RR_CALF_visual'>
        <pose frame=''>0 0 0 0 -0 0</pose>
        <geometry>
          <mesh>
            <scale>1 1 1</scale>
            <uri>model://PONGBOT_Q_V3/meshes/RR_CALF.STL</uri>
          </mesh>
        </geometry>
        <material>
          <ambient>33 33 33 1</ambient>
          <diffuse>1 1 1 1</diffuse>
          <emissive>0 0 0 1</emissive>
          <specular>0 0 0 0</specular>
        </material>
      </visual>
    </link>
    <joint name='RR_KN_JOINT' type='revolute'>
      <child>RR_CALF</child>
      <parent>RR_THIGH</parent>
      <axis>
        <xyz>0 1 0</xyz>
        <limit>
          <lower>-3.141592</lower>
          <upper>3.141592</upper>
        </limit>
        <dynamics>
          <spring_reference>0</spring_reference>
          <spring_stiffness>0</spring_stiffness>
        </dynamics>
        <use_parent_model_frame>1</use_parent_model_frame>
      </axis>
    </joint>

    <link name='RR_TIP'>
      <pose frame=''>-0.01555 -0.21895 -0.59955 0 -0 0</pose>
      <inertial>
        <pose frame=''>0 0 0 0 0 0</pose>
         <mass>0.046</mass>
        <inertia>
          <ixx>0.0001</ixx>
          <ixy>0</ixy>
          <ixz>0</ixz>
          <iyy>0.0002</iyy>
          <iyz>0</iyz>
          <izz>0.0001</izz>
        </inertia>
      </inertial>
      <collision name='RR_TIP_collision'>
        <pose frame=''>0 0 0 0 0 0</pose>
        <geometry>
          <sphere>
            <radius> .015 </radius>
          </sphere>
        </geometry>
        <surface>
          <bounce>
            <restitution_coefficient> 0 </restitution_coefficient>
          </bounce>
          <friction>
            <ode>
               <mu>  1  </mu>
              <mu2> 1  </mu2>
            </ode>
          </friction>
          <contact>
            <ode>
              <!-- <soft_erp> 0.1 </soft_erp>
              <soft_cfm> 1E-4 </soft_cfm> -->
              <kp>5000000</kp>
              <kd>5000</kd>
              <max_vel>0.1</max_vel>
              <min_depth>0.0001</min_depth>
            </ode>
          </contact>
        </surface>
      </collision>
      <visual name='RR_TIP_visual'>
        <pose frame=''>0 0 0 0 0 0</pose>
        <geometry>
          <mesh>
            <uri>model://PONGBOT_Q_V3/meshes/RR_TIP.STL</uri>
            <scale>1 1 1</scale>
          </mesh>
        </geometry>
      </visual>
      <sensor name="RR_TIP_contact" type='contact'>
       <contact>
         <collision>RR_TIP_collision</collision>
       </contact>
      </sensor>
    </link>

    <joint name="RR_TIP_JOINT" type="fixed">
      <child>RR_TIP</child>
      <parent>RR_CALF</parent>
      <sensor name="RR_FT_SENSOR" type="force_torque">
        <force_torque>
          <frame>child</frame>
          <measure_direction>child_to_parent</measure_direction>
        </force_torque>
        <!-- <visualize> True </visualize> -->
      </sensor>
    </joint>

    <link name='FRONT_BODY'>
      <pose frame=''>0.35 0 0.03586 0 -0 0</pose>
      <inertial>
        <pose frame=''>0.27604 0 0.02529 0 -0 0</pose>
        <mass>13.00</mass>
        <inertia>
          <ixx>0.11819</ixx> 
          <ixy>0</ixy>
          <ixz>0</ixz>
          <iyy>0.13516</iyy>
          <iyz>0</iyz>
          <izz>0.15248</izz>

        </inertia>
      </inertial>
      <visual name='FRONT_BODY_visual'>
        <pose frame=''>0 0 0 0 -0 0</pose>
        <geometry>
          <mesh>
            <scale>1 1 1</scale>
            <uri>model://PONGBOT_Q_V3/meshes/FRONT_BODY.STL</uri>
          </mesh>
        </geometry>
        <material>
          <ambient>97 97 97 1</ambient>
          <diffuse>1 1 1 1</diffuse>
          <emissive>0 0 0 1</emissive>
          <specular>0 0 0 0</specular>
        </material>
      </visual>
    </link>
    <joint name='WAIST_JOINT' type='revolute'>
      <child>FRONT_BODY</child>
      <parent>REAR_BODY</parent>
      <axis>
        <xyz>0 0 1</xyz>
        <limit>
          <lower>-3.141592</lower>
          <upper>3.141592</upper>
        </limit>
        <dynamics>
          <spring_reference>0</spring_reference>
          <spring_stiffness>0</spring_stiffness>
        </dynamics>
        <use_parent_model_frame>1</use_parent_model_frame>
      </axis>
    </joint>
    <link name='FL_HIP'>
      <pose frame=''>0.7 0.115 0.00031 0 -0 0</pose>
      <inertial>
        <pose frame=''>0.00094 4e-05 0 0 -0 0</pose>
        <mass>1.11213</mass>
        <inertia>
          <ixx>0.00112</ixx>
          <ixy>0</ixy>
          <ixz>0</ixz>
          <iyy>0.00121</iyy>
          <iyz>0</iyz>
          <izz>0.00122</izz>
        </inertia>
      </inertial>
      <visual name='FL_HIP_visual'>
        <pose frame=''>0 0 0 0 -0 0</pose>
        <geometry>
          <mesh>
            <scale>1 1 1</scale>
            <uri>model://PONGBOT_Q_V3/meshes/FL_HIP.STL</uri>
          </mesh>
        </geometry>
        <material>
          <ambient>213 0 0 1</ambient>
          <diffuse>1 1 1 1</diffuse>
          <emissive>0 0 0 1</emissive>
          <specular>0 0 0 0</specular>
        </material>
      </visual>
    </link>
    <joint name='FL_HR_JOINT' type='revolute'>
      <child>FL_HIP</child>
      <parent>FRONT_BODY</parent>
      <axis>
        <xyz>1 0 0</xyz>
        <limit>
          <lower>-3.141592</lower>
          <upper>3.141592</upper>
        </limit>
        <dynamics>
          <spring_reference>0</spring_reference>
          <spring_stiffness>0</spring_stiffness>
        </dynamics>
        <use_parent_model_frame>1</use_parent_model_frame>
      </axis>
    </joint>
    <link name='FL_THIGH'>
      <pose frame=''>0.7 0.22 0.00031 0 -0 0</pose>
      <inertial>
        <pose frame=''>-0.0017 -0.00992 -0.03383 0 -0 0</pose>
        <mass>2.16823</mass>
        <inertia>
          <ixx>0.01528</ixx>
          <ixy>0</ixy>
          <ixz>0</ixz>
          <iyy>0.01528</iyy>
          <iyz>0</iyz>
          <izz>0.00242</izz>
        </inertia>
      </inertial>
      <visual name='FL_THIGH_visual'>
        <pose frame=''>0 0 0 0 -0 0</pose>
        <geometry>
          <mesh>
            <scale>1 1 1</scale>
            <uri>model://PONGBOT_Q_V3/meshes/FL_THIGH.STL</uri>
          </mesh>
        </geometry>
        <material>
          <ambient>213 0 0 1</ambient>
          <diffuse>1 1 1 1</diffuse>
          <emissive>0 0 0 1</emissive>
          <specular>0 0 0 0</specular>
        </material>
      </visual>
    </link>
    <joint name='FL_HP_JOINT' type='revolute'>
      <child>FL_THIGH</child>
      <parent>FL_HIP</parent>
      <axis>
        <xyz>0 1 0</xyz>
        <limit>
          <lower>-3.141592</lower>
          <upper>3.141592</upper>
        </limit>
        <dynamics>
          <spring_reference>0</spring_reference>
          <spring_stiffness>0</spring_stiffness>
        </dynamics>
        <use_parent_model_frame>1</use_parent_model_frame>
      </axis>
    </joint>
    <link name='FL_CALF'>
      <pose frame=''>0.7 0.22 -0.30469 0 -0 0</pose>
      <inertial>
        <pose frame=''>-0.004548 0.001901 -0.081321 0 -0 0</pose>
        <mass>0.39785</mass>
        <inertia>
          <ixx>0.00586687</ixx>
          <ixy>0</ixy>
          <ixz>0</ixz>
          <iyy>0.00577933</iyy>
          <iyz>0</iyz>
          <izz>0.000202833</izz>
        </inertia>
      </inertial>
      <visual name='FL_CALF_visual'>
        <pose frame=''>0 0 0 0 -0 0</pose>
        <geometry>
          <mesh>
            <scale>1 1 1</scale>
            <uri>model://PONGBOT_Q_V3/meshes/FL_CALF.STL</uri>
          </mesh>
        </geometry>
        <material>
          <ambient>33 33 33 1</ambient>
          <diffuse>1 1 1 1</diffuse>
          <emissive>0 0 0 1</emissive>
          <specular>0 0 0 0</specular>
        </material>
      </visual>

    </link>
    <joint name='FL_KN_JOINT' type='revolute'>
      <child>FL_CALF</child>
      <parent>FL_THIGH</parent>
      <axis>
        <xyz>0 1 0</xyz>
        <limit>
          <lower>-3.141592</lower>
          <upper>3.141592</upper>
        </limit>
        <dynamics>
          <spring_reference>0</spring_reference>
          <spring_stiffness>0</spring_stiffness>
        </dynamics>
        <use_parent_model_frame>1</use_parent_model_frame>
      </axis>
    </joint>

    <link name='FL_TIP'>
      <pose frame=''>0.68618 0.21895 -0.59955 0 -0 0</pose>
      <inertial>
        <pose frame=''>0 0 0 0 0 0</pose>
         <mass>0.046</mass>
        <inertia>
          <ixx>0.0001</ixx>
          <ixy>0</ixy>
          <ixz>0</ixz>
          <iyy>0.0002</iyy>
          <iyz>0</iyz>
          <izz>0.0001</izz>
        </inertia>
      </inertial>
      <collision name='FL_TIP_collision'>
        <pose frame=''>0 0 0 0 0 0</pose>
        <geometry>
          <sphere>
            <radius> .015 </radius>
          </sphere>
        </geometry>
        <surface>
          <bounce>
            <restitution_coefficient> 0 </restitution_coefficient>
          </bounce>
          <friction>
            <ode>
               <mu>  1  </mu>
              <mu2> 1  </mu2>
            </ode>
          </friction>
          <contact>
            <ode>
              <kp>5000000</kp>
              <kd>5000</kd>
              <max_vel>0.1</max_vel>
              <min_depth>0.0001</min_depth>
            </ode>
          </contact>
        </surface>
      </collision>
      <visual name='FL_TIP_visual'>
        <pose frame=''>0 0 0 0 0 0</pose>
        <geometry>
          <mesh>
            <uri>model://PONGBOT_Q_V3/meshes/FL_TIP.STL</uri>
            <scale>1 1 1</scale>
          </mesh>
        </geometry>
      </visual>
      <sensor name="FL_TIP_contact" type='contact'>
       <contact>
         <collision>FL_TIP_collision</collision>
       </contact>
      </sensor>
    </link>

    <joint name="FL_TIP_JOINT" type="fixed">
      <child>FL_TIP</child>
      <parent>FL_CALF</parent>
      <sensor name="FL_FT_SENSOR" type="force_torque">
        <force_torque>
          <frame>child</frame>
          <measure_direction>child_to_parent</measure_direction>
        </force_torque>
        <!-- <visualize> True </visualize> -->
      </sensor>
    </joint>

    <link name='FR_HIP'>
      <pose frame=''>0.7 -0.115 0.00031 0 -0 0</pose>
      <inertial>
        <pose frame=''>0.00094 -4e-05 0 0 -0 0</pose>
        <mass>1.11213</mass>
        <inertia>
          <ixx>0.00112</ixx>
          <ixy>0</ixy>
          <ixz>0</ixz>
          <iyy>0.00121</iyy>
          <iyz>0</iyz>
          <izz>0.00122</izz>
        </inertia>
      </inertial>
      <visual name='FR_HIP_visual'>
        <pose frame=''>0 0 0 0 -0 0</pose>
        <geometry>
          <mesh>
            <scale>1 1 1</scale>
            <uri>model://PONGBOT_Q_V3/meshes/FR_HIP.STL</uri>
          </mesh>
        </geometry>
        <material>
          <ambient>213 0 0 1</ambient>
          <diffuse>1 1 1 1</diffuse>
          <emissive>0 0 0 1</emissive>
          <specular>0 0 0 0</specular>
        </material>
      </visual>
    </link>
    <joint name='FR_HR_JOINT' type='revolute'>
      <child>FR_HIP</child>
      <parent>FRONT_BODY</parent>
      <axis>
        <xyz>1 0 0</xyz>
        <limit>
          <lower>-3.141592</lower>
          <upper>3.141592</upper>
        </limit>
        <dynamics>
          <spring_reference>0</spring_reference>
          <spring_stiffness>0</spring_stiffness>
        </dynamics>
        <use_parent_model_frame>1</use_parent_model_frame>
      </axis>
    </joint>
    <link name='FR_THIGH'>
      <pose frame=''>0.7 -0.22 0.00031 0 -0 0</pose>
      <inertial>
        <pose frame=''>-0.0017 0.00992 -0.03383 0 -0 0</pose>
        <mass>2.16823</mass>
        <inertia>
          <ixx>0.01528</ixx>
          <ixy>0</ixy>
          <ixz>0</ixz>
          <iyy>0.01528</iyy>
          <iyz>0</iyz>
          <izz>0.00242</izz>
        </inertia>
      </inertial>
      <visual name='FR_THIGH_visual'>
        <pose frame=''>0 0 0 0 -0 0</pose>
        <geometry>
          <mesh>
            <scale>1 1 1</scale>
            <uri>model://PONGBOT_Q_V3/meshes/FR_THIGH.STL</uri>
          </mesh>
        </geometry>
        <material>
          <ambient>213 0 0 1</ambient>
          <diffuse>1 1 1 1</diffuse>
          <emissive>0 0 0 1</emissive>
          <specular>0 0 0 0</specular>
        </material>
      </visual>
    </link>
    <joint name='FR_HP_JOINT' type='revolute'>
      <child>FR_THIGH</child>
      <parent>FR_HIP</parent>
      <axis>
        <xyz>0 1 0</xyz>
        <limit>
          <lower>-3.141592</lower>
          <upper>3.141592</upper>
        </limit>
        <dynamics>
          <spring_reference>0</spring_reference>
          <spring_stiffness>0</spring_stiffness>
        </dynamics>
        <use_parent_model_frame>1</use_parent_model_frame>
      </axis>
    </joint>
    <link name='FR_CALF'>
      <pose frame=''>0.7 -0.22 -0.30469 0 -0 0</pose>
      <inertial>
        <pose frame=''>-0.004548 -0.001901 -0.081321 0 -0 0</pose>
        <mass>0.39785</mass>
        <inertia>
          <ixx>0.00586687</ixx>
          <ixy>0</ixy>
          <ixz>0</ixz>
          <iyy>0.00577933</iyy>
          <iyz>0</iyz>
          <izz>0.000202833</izz>
        </inertia>
      </inertial>
      <visual name='FR_CALF_visual'>
        <pose frame=''>0 0 0 0 -0 0</pose>
        <geometry>
          <mesh>
            <scale>1 1 1</scale>
            <uri>model://PONGBOT_Q_V3/meshes/FR_CALF.STL</uri>
          </mesh>
        </geometry>
        <material>
          <ambient>33 33 33 1</ambient>
          <diffuse>1 1 1 1</diffuse>
          <emissive>0 0 0 1</emissive>
          <specular>0 0 0 0</specular>
        </material>
      </visual>
    </link>

    <joint name='FR_KN_JOINT' type='revolute'>
      <child>FR_CALF</child>
      <parent>FR_THIGH</parent>
      <axis>
        <xyz>0 1 0</xyz>
        <limit>
          <lower>-3.141592</lower>
          <upper>3.141592</upper>
        </limit>
        <dynamics>
          <spring_reference>0</spring_reference>
          <spring_stiffness>0</spring_stiffness>
        </dynamics>
        <use_parent_model_frame>1</use_parent_model_frame>
      </axis>
    </joint>

    <link name='FR_TIP'>
      <pose frame=''>0.68618 -0.21895 -0.59955 0 -0 0</pose>
      <inertial>
        <pose frame=''>0 0 0 0 0 0</pose>
         <mass>0.046</mass>
        <inertia>
          <ixx>0.0001</ixx>
          <ixy>0</ixy>
          <ixz>0</ixz>
          <iyy>0.0002</iyy>
          <iyz>0</iyz>
          <izz>0.0001</izz>
        </inertia>
      </inertial>
      <collision name='FR_TIP_collision'>
        <pose frame=''>0 0 0 0 0 0</pose>
        <geometry>
          <sphere>
            <radius> .015 </radius>
          </sphere>
        </geometry>
        <surface>
          <bounce>
            <restitution_coefficient> 0 </restitution_coefficient>
          </bounce>
          <friction>
            <ode>
               <mu>  1  </mu>
              <mu2> 1  </mu2>
            </ode>
          </friction>
          <contact>
            <ode>
              <!-- <soft_erp> 0.1 </soft_erp>
              <soft_cfm> 1E-4 </soft_cfm> -->
              <kp>5000000</kp>
              <kd>5000</kd>
              <max_vel>0.1</max_vel>
              <min_depth>0.0001</min_depth>
            </ode>
          </contact>
        </surface>
      </collision>
      <visual name='FR_TIP_visual'>
        <pose frame=''>0 0 0 0 0 0</pose>
        <geometry>
          <mesh>
            <uri>model://PONGBOT_Q_V3/meshes/FR_TIP.STL</uri>
            <scale>1 1 1</scale>
          </mesh>
        </geometry>
      </visual>
      <sensor name="FR_TIP_contact" type='contact'>
       <contact>
         <collision>FR_TIP_collision</collision>
       </contact>
      </sensor>
    </link>
    <joint name="FR_TIP_JOINT" type="fixed">
      <child>FR_TIP</child>
      <parent>FR_CALF</parent>
      <sensor name="FR_FT_SENSOR" type="force_torque">
        <force_torque>
          <frame>child</frame>
          <measure_direction>child_to_parent</measure_direction>
        </force_torque>
        <!-- <visualize> True </visualize> -->
      </sensor>
    </joint>
  </model>
</sdf>
