<robot
  name="SLOPE_GENERATOR2">
  <link
    name="BASE_LINK">
    <inertial>
      <origin
        xyz="3.4694E-18 -6.9389E-18 0"
        rpy="0 0 0" />
      <mass
        value="0.019117" />
      <inertia
        ixx="3.0675E-06"
        ixy="-3.574E-23"
        ixz="7.1668E-38"
        iyy="5.8164E-06"
        iyz="-1.6832E-22"
        izz="3.0675E-06" />
    </inertial>
    <visual>
      <origin
        xyz="0 0 0"
        rpy="0 0 0" />
      <geometry>
        <mesh
          filename="package://SLOPE_GENERATOR2/meshes/BASE_LINK.STL" />
      </geometry>
      <material
        name="">
        <color
          rgba="0.79216 0.81961 0.93333 1" />
      </material>
    </visual>
    <collision>
      <origin
        xyz="0 0 0"
        rpy="0 0 0" />
      <geometry>
        <mesh
          filename="package://SLOPE_GENERATOR2/meshes/BASE_LINK.STL" />
      </geometry>
    </collision>
  </link>
  <link
    name="MIDDLE_LINK">
    <inertial>
      <origin
        xyz="0.089812 -0.0099253 0.012851"
        rpy="0 0 0" />
      <mass
        value="3277.4" />
      <inertia
        ixx="2443.4"
        ixy="-45.032"
        ixz="-29.136"
        iyy="8865.8"
        iyz="12.397"
        izz="11258" />
    </inertial>
    <visual>
      <origin
        xyz="0 0 0"
        rpy="0 0 0" />
      <geometry>
        <mesh
          filename="package://SLOPE_GENERATOR2/meshes/MIDDLE_LINK.STL" />
      </geometry>
      <material
        name="">
        <color
          rgba="0.79216 0.81961 0.93333 1" />
      </material>
    </visual>
    <collision>
      <origin
        xyz="0 0 0"
        rpy="0 0 0" />
      <geometry>
        <mesh
          filename="package://SLOPE_GENERATOR2/meshes/MIDDLE_LINK.STL" />
      </geometry>
    </collision>
  </link>
  <joint
    name="MIDDLE_JOINT"
    type="continuous">
    <origin
      xyz="0 -1.505 0"
      rpy="-2.9266E-19 1.7347E-18 7.7289E-19" />
    <parent
      link="BASE_LINK" />
    <child
      link="MIDDLE_LINK" />
    <axis
      xyz="0 1 0" />
  </joint>
  <link
    name="INIT_LINK">
    <inertial>
      <origin
        xyz="-1.5009 -2.2204E-16 8.6736E-19"
        rpy="0 0 0" />
      <mass
        value="44.974" />
      <inertia
        ixx="33.736"
        ixy="-6.6405E-15"
        ixz="6.0958E-18"
        iyy="33.693"
        iyz="1.2777E-17"
        izz="67.429" />
    </inertial>
    <visual>
      <origin
        xyz="0 0 0"
        rpy="0 0 0" />
      <geometry>
        <mesh
          filename="package://SLOPE_GENERATOR2/meshes/INIT_LINK.STL" />
      </geometry>
      <material
        name="">
        <color
          rgba="0.79216 0.81961 0.93333 1" />
      </material>
    </visual>
    <collision>
      <origin
        xyz="0 0 0"
        rpy="0 0 0" />
      <geometry>
        <mesh
          filename="package://SLOPE_GENERATOR2/meshes/INIT_LINK.STL" />
      </geometry>
    </collision>
  </link>
  <joint
    name="INIT_JOINT"
    type="continuous">
    <origin
      xyz="-3 0 0"
      rpy="2.9266E-19 -1.7347E-18 -7.7289E-19" />
    <parent
      link="MIDDLE_LINK" />
    <child
      link="INIT_LINK" />
    <axis
      xyz="0 1 0" />
  </joint>
  <link
    name="END_LINK">
    <inertial>
      <origin
        xyz="1.5009 -4.4409E-16 8.6736E-19"
        rpy="0 0 0" />
      <mass
        value="44.974" />
      <inertia
        ixx="33.736"
        ixy="1.1363E-14"
        ixz="9.7723E-19"
        iyy="33.693"
        iyz="2.3223E-18"
        izz="67.429" />
    </inertial>
    <visual>
      <origin
        xyz="0 0 0"
        rpy="0 0 0" />
      <geometry>
        <mesh
          filename="package://SLOPE_GENERATOR2/meshes/END_LINK.STL" />
      </geometry>
      <material
        name="">
        <color
          rgba="0.79216 0.81961 0.93333 1" />
      </material>
    </visual>
    <collision>
      <origin
        xyz="0 0 0"
        rpy="0 0 0" />
      <geometry>
        <mesh
          filename="package://SLOPE_GENERATOR2/meshes/END_LINK.STL" />
      </geometry>
    </collision>
  </link>
  <joint
    name="END_JOINT"
    type="continuous">
    <origin
      xyz="3 0 0"
      rpy="0 3.7184E-35 0" />
    <parent
      link="MIDDLE_LINK" />
    <child
      link="END_LINK" />
    <axis
      xyz="0 1 0" />
  </joint>
</robot>