<sdf version='1.6'>
  <!-- <world name='ROBOT_WORLD'> -->

  <model name='SLAVE_ARM'>

   <joint name="fixed to ground" type="fixed">
      <parent>world</parent>
      <child>BASE_LINK</child>
    </joint>

    <link name='BASE_LINK'>
      <!-- <gravity>0</gravity> -->
      <pose frame=''>0 0 0 0 -0 0</pose>
      <inertial>
        <pose frame=''>0.2973 0.0488 0.1042 0 -0 0</pose>
        <mass>17.574</mass>
        <inertia>
          <ixx>0.41733</ixx>
          <ixy>0.0168</ixy>
          <ixz>-0.0017</ixz>
          <iyy>0.76126</iyy>
          <iyz>0</iyz>
          <izz>0.9251</izz>
        </inertia>
      </inertial>
      <collision name='BASE_LINK_collision'>
        <pose frame=''>0 0 0 0 -0 0</pose>
        <geometry>
          <mesh>
            <scale>1 1 1</scale>
            <uri>model://SLAVE_ARM/meshes/BASE_LINK.STL</uri>
          </mesh>
        </geometry>
      </collision>
      <visual name='BASE_LINK_visual'>
        <pose frame=''>0 0 0 0 -0 0</pose>
        <geometry>
          <mesh>
            <scale>1 1 1</scale>
            <uri>model://SLAVE_ARM/meshes/BASE_LINK.STL</uri>
          </mesh>
        </geometry>
      </visual>
    </link>
    <link name='LINK1'>
      <!-- <gravity>0</gravity> -->
      <pose frame=''>0.608 0.052 0.111 0 -0 0</pose>
      <inertial>
        <pose frame=''>0.1104 0.0137 0.0189 0 -0 0</pose>
        <mass>10.337</mass>
        <inertia>
          <ixx>0.1694</ixx>
          <ixy>0.015</ixy>
          <ixz>0.0093</ixz>
          <iyy>0.10174</iyy>
          <iyz>-0.0021</iyz>
          <izz>0.2048</izz>
        </inertia>
      </inertial>
      <collision name='LINK1_collision'>
        <pose frame=''>0 0 0 0 -0 0</pose>
        <geometry>
          <mesh>
            <scale>1 1 1</scale>
            <uri>model://SLAVE_ARM/meshes/LINK1.STL</uri>
          </mesh>
        </geometry>
      </collision>
      <visual name='LINK1_visual'>
        <pose frame=''>0 0 0 0 -0 0</pose>
        <geometry>
          <mesh>
            <scale>1 1 1</scale>
            <uri>model://SLAVE_ARM/meshes/LINK1.STL</uri>
          </mesh>
        </geometry>
      </visual>
    </link>
    <joint name='LINK1_JOINT' type='revolute'>
      <child>LINK1</child>
      <parent>BASE_LINK</parent>
      <axis>
        <xyz>0 0 1</xyz>
        <limit>
          <!-- <lower>-1.5707</lower>
          <upper>1.5707</upper> -->
          <lower>-3.141592</lower>
          <upper>3.141592</upper>
        </limit>
        <dynamics>
          <spring_reference>0</spring_reference>
          <spring_stiffness>0</spring_stiffness>
        </dynamics>
        <use_parent_model_frame>1</use_parent_model_frame>
      </axis>
    </joint>
    <link name='LINK2'>
      <!-- <gravity>0</gravity> -->
      <pose frame=''>0.808 0.052 0.201 0 -0 0</pose>
      <inertial>
        <pose frame=''>0.387 -0.0012 0.0217 0 -0 0</pose>
        <mass>9.5413</mass>
        <inertia>
          <ixx>0.1864</ixx>
          <ixy>0.0162</ixy>
          <ixz>0.0236</ixz>
          <iyy>0.5195</iyy>
          <iyz>0.0025</iyz>
          <izz>0.6443</izz>
        </inertia>
      </inertial>
      <collision name='LINK2_collision'>
        <pose frame=''>0 0 0 0 -0 0</pose>
        <geometry>
          <mesh>
            <scale>1 1 1</scale>
            <uri>model://SLAVE_ARM/meshes/LINK2.STL</uri>
          </mesh>
        </geometry>
      </collision>
      <visual name='LINK2_visual'>
        <pose frame=''>0 0 0 0 -0 0</pose>
        <geometry>
          <mesh>
            <scale>1 1 1</scale>
            <uri>model://SLAVE_ARM/meshes/LINK2.STL</uri>
          </mesh>
        </geometry>
      </visual>
    </link>
    <joint name='LINK2_JOINT' type='revolute'>
      <child>LINK2</child>
      <parent>LINK1</parent>
      <axis>
        <xyz>0 1 0</xyz>
        <limit>
          <!-- <lower>-2.6179</lower>
          <upper>-0.5235</upper> -->
          <lower>-3.141592</lower>
          <upper>3.141592</upper>
        </limit>
        <dynamics>
          <spring_reference>0</spring_reference>
          <spring_stiffness>0</spring_stiffness>
        </dynamics>
        <use_parent_model_frame>1</use_parent_model_frame>
      </axis>
    </joint>
    <link name='LINK3'>
      <!-- <gravity>0</gravity> -->
      <pose frame=''>1.573 0.052 0.201 0 -0 0</pose>
      <inertial>
        <pose frame=''>0.25161 -0.0058 0.0306 0 -0 0</pose>
        <mass>4.6229</mass>
        <inertia>
          <ixx>0.064842</ixx>
          <ixy>0.0032</ixy>
          <ixz>0.0043</ixz>
          <iyy>0.1375</iyy>
          <iyz>0.0013</iyz>
          <izz>0.1805</izz>
        </inertia>
      </inertial>
      <collision name='LINK3_collision'>
        <pose frame=''>0 0 0 0 -0 0</pose>
        <geometry>
          <mesh>
            <scale>1 1 1</scale>
            <uri>model://SLAVE_ARM/meshes/LINK3.STL</uri>
          </mesh>
        </geometry>
      </collision>
      <visual name='LINK3_visual'>
        <pose frame=''>0 0 0 0 -0 0</pose>
        <geometry>
          <mesh>
            <scale>1 1 1</scale>
            <uri>model://SLAVE_ARM/meshes/LINK3.STL</uri>
          </mesh>
        </geometry>
      </visual>
    </link>
    <joint name='LINK3_JOINT' type='revolute'>
      <child>LINK3</child>
      <parent>LINK2</parent>
      <axis>
        <xyz>0 1 0</xyz>
        <limit>
          <!-- <lower>0.5236</lower>
          <upper>2.6179</upper> -->
          <lower>-3.141592</lower>
          <upper>3.141592</upper>
        </limit>
        <dynamics>
          <spring_reference>0</spring_reference>
          <spring_stiffness>0</spring_stiffness>
        </dynamics>
        <use_parent_model_frame>1</use_parent_model_frame>
      </axis>
    </joint>
    <link name='LINK4'>
      <!-- <gravity>0</gravity> -->
      <pose frame=''>2.155 0.052 0.201 0 -0 0</pose>
      <inertial>
        <pose frame=''>0.0963 -0.006 -0.0134 0 -0 0</pose>
        <mass>6.0768</mass>
        <inertia>
          <ixx>0.0329</ixx>
          <ixy>0.0125</ixy>
          <ixz>0.0009</ixz>
          <iyy>0.1067</iyy>
          <iyz>-0.0011</iyz>
          <izz>0.1194</izz>
        </inertia>
      </inertial>
      <collision name='LINK4_collision'>
        <pose frame=''>0 0 0 0 -0 0</pose>
        <geometry>
          <mesh>
            <scale>1 1 1</scale>
            <uri>model://SLAVE_ARM/meshes/LINK4.STL</uri>
          </mesh>
        </geometry>
      </collision>
      <visual name='LINK4_visual'>
        <pose frame=''>0 0 0 0 -0 0</pose>
        <geometry>
          <mesh>
            <scale>1 1 1</scale>
            <uri>model://SLAVE_ARM/meshes/LINK4.STL</uri>
          </mesh>
        </geometry>
      </visual>
    </link>
    <joint name='LINK4_JOINT' type='revolute'>
      <child>LINK4</child>
      <parent>LINK3</parent>
      <axis>
        <xyz>0 1 0</xyz>
        <limit>
          <!-- <lower>-1.0472</lower>
          <upper>2.094</upper> -->
          <lower>-3.141592</lower>
          <upper>3.141592</upper>
        </limit>
        <dynamics>
          <spring_reference>0</spring_reference>
          <spring_stiffness>0</spring_stiffness>
        </dynamics>
        <use_parent_model_frame>1</use_parent_model_frame>
      </axis>
    </joint>
    <link name='LINK5'>
      <!-- <gravity>0</gravity> -->
      <pose frame=''>2.495 0.052 0.191 0 -0 0</pose>
      <inertial>
        <pose frame=''>0.1513 0 0.0022 0 -0 0</pose>
        <mass>7.0927</mass>
        <inertia>
          <ixx>0.0446</ixx>
          <ixy>0.0005</ixy>
          <ixz>-0.0008</ixz>
          <iyy>0.0597</iyy>
          <iyz>-0.0004</iyz>
          <izz>0.0571</izz>
        </inertia>
      </inertial>
      <collision name='LINK5_collision'>
        <pose frame=''>0 0 0 0 -0 0</pose>
        <geometry>
          <mesh>
            <scale>1 1 1</scale>
            <uri>model://SLAVE_ARM/meshes/LINK5.STL</uri>
          </mesh>
        </geometry>
      </collision>
      <visual name='LINK5_visual'>
        <pose frame=''>0 0 0 0 -0 0</pose>
        <geometry>
          <mesh>
            <scale>1 1 1</scale>
            <uri>model://SLAVE_ARM/meshes/LINK5.STL</uri>
          </mesh>
        </geometry>
      </visual>
    </link>
    <joint name='LINK5_JOINT' type='revolute'>
      <child>LINK5</child>
      <parent>LINK4</parent>
      <axis>
        <xyz>0 0 1</xyz>
        <limit>
          <lower>-2.094</lower>
          <upper>2.094</upper>
          <!-- <lower>-3.141592</lower>
          <upper>3.141592</upper> -->
        </limit>
        <dynamics>
          <spring_reference>0</spring_reference>
          <spring_stiffness>0</spring_stiffness>
        </dynamics>
        <use_parent_model_frame>1</use_parent_model_frame>
      </axis>
    </joint>
    <link name='LINK6'>
      <!-- <gravity>0</gravity> -->
      <pose frame=''>2.78662 0.052 0.191 0 -0 0</pose>
      <inertial>
        <pose frame=''>0.116214 0 0 0 -0 0</pose>
        <mass>9.3631</mass>
        <inertia>
          <ixx>0.0842</ixx>
          <ixy>0</ixy>
          <ixz>0</ixz>
          <iyy>0.107887</iyy>
          <iyz>0</iyz>
          <izz>0.0827868</izz>
        </inertia>
      </inertial>
      <collision name='LINK6_collision'>
        <pose frame=''>0 0 0 0 -0 0</pose>
        <geometry>
          <mesh>
            <scale>1 1 1</scale>
            <uri>model://SLAVE_ARM/meshes/LINK6.STL</uri>
          </mesh>
        </geometry>
      </collision>
      <collision name='LINK6_fixed_joint_lump__LINK7_collision_1'>
        <pose frame=''>0.156 0 0 0 -0 0</pose>
        <geometry>
          <mesh>
            <scale>1 1 1</scale>
            <uri>model://SLAVE_ARM/meshes/LINK7.STL</uri>
          </mesh>
        </geometry>
      </collision>
      <visual name='LINK6_visual'>
        <pose frame=''>0 0 0 0 -0 0</pose>
        <geometry>
          <mesh>
            <scale>1 1 1</scale>
            <uri>model://SLAVE_ARM/meshes/LINK6.STL</uri>
          </mesh>
        </geometry>
      </visual>
      <visual name='LINK6_fixed_joint_lump__LINK7_visual_1'>
        <pose frame=''>0.156 0 0 0 -0 0</pose>
        <geometry>
          <mesh>
            <scale>1 1 1</scale>
            <uri>model://SLAVE_ARM/meshes/LINK7.STL</uri>
          </mesh>
        </geometry>
      </visual>
    </link>
    <joint name='LINK6_JOINT' type='revolute'>
      <child>LINK6</child>
      <parent>LINK5</parent>
      <axis>
        <xyz>1 0 0</xyz>
        <limit>
          <lower>-3.141592</lower>
          <upper>3.141592</upper>
        </limit>
        <dynamics>
          <spring_reference>0</spring_reference>
          <spring_stiffness>0</spring_stiffness>
        </dynamics>
        <use_parent_model_frame>1</use_parent_model_frame>
      </axis>
    </joint>
  </model>
<!-- </world> -->
</sdf>
