<sdf version='1.6'>
  <model name='PONGBOT_Q_V4'>
     <joint name="fixed to ground" type="fixed">
       <parent>world</parent>
       <child>REAR_BODY</child>
     </joint>
      <!-- <joint name="RL fixed to ground" type="ball">
        <parent>world</parent>
        <child>RL_TIP</child>
      </joint>
      <joint name="RR fixed to ground" type="ball">
         <parent>world</parent>
         <child>RR_TIP</child>
       </joint>
        <joint name="FL fixed to ground" type="ball">
          <parent>world</parent>
          <child>FL_TIP</child>
        </joint>
       <joint name="FR fixed to ground" type="ball">
           <parent>world</parent>
           <child>FR_TIP</child>
         </joint> -->

    <link name='REAR_BODY'>
      <pose frame=''>0 0 0 0 -0 0</pose>
      <inertial>
        <pose frame=''>-0.2381 0 -0.000797 0 -0 0</pose>
        <mass>13.826</mass>
        <inertia>
          <!-- <ixx>0.15296</ixx>
          <ixy>0.002196</ixy>
          <ixz>-0.059602</ixz>
          <iyy>0.2894</iyy>
          <iyz>-0.000828</iyz>
          <izz>0.2996</izz> -->
          <ixx>0.15296</ixx>
          <ixy>0.0</ixy>
          <ixz>-0.0</ixz>
          <iyy>0.2894</iyy>
          <iyz>-0.0</iyz>
          <izz>0.2996</izz>
        </inertia>
      </inertial>
      <!-- <collision name='REAR_BODY_collision'>
        <pose frame=''>0 0 0 0 -0 0</pose>
        <geometry>
          <mesh>
            <scale>1 1 1</scale>
            <uri>model://PONGBOT_Q_V4/meshes/REAR_BODY.STL</uri>
          </mesh>
        </geometry>
      </collision> -->
      <visual name='REAR_BODY_visual'>
        <pose frame=''>0 0 0 0 -0 0</pose>
        <geometry>
          <mesh>
            <scale>1 1 1</scale>
            <uri>model://PONGBOT_Q_V4/meshes/REAR_BODY.STL</uri>
          </mesh>
        </geometry>
        <material>
          <ambient>97 97 97 1</ambient>
          <diffuse>1 1 1 1</diffuse>
          <emissive>0 0 0 0</emissive>
          <specular>0 0 0 0</specular>
        </material>
      </visual>
      <sensor name='IMU' type='imu'>
        <pose frame=''>0.0 0 -0.066 0 -0 0</pose>
        <imu>
          <angular_velocity>
            <x>
              <noise type='none'></noise>
              <!-- <noise type='gaussian'>
                <mean>0</mean>
                <stddev>0.5</stddev>
              </noise> -->
            </x>
            <y>
              <noise type='none'></noise>
              <!-- <noise type='gaussian'>
                <mean>0</mean>
                <stddev>0.5</stddev>
              </noise> -->
            </y>
            <z>
              <noise type='none'></noise>
              <!-- <noise type='gaussian'>
                <mean>0</mean>
                <stddev>0.5</stddev>
              </noise> -->
            </z>
          </angular_velocity>
          <linear_acceleration>
            <x>
              <noise type='none'></noise>
              <!-- <noise type='gaussian'>
                <mean>0</mean>
                <stddev>0.1</stddev>
              </noise> -->
            </x>
            <y>
              <noise type="none"></noise>
              <!-- <noise type='gaussian'>
                <mean>0</mean>
                <stddev>0.1</stddev>
              </noise> -->
            </y>
            <z>
              <noise type='none'></noise>
              <!-- <noise type='gaussian'>
                <mean>0</mean>
                <stddev>0.1</stddev>
              </noise> -->
            </z>
          </linear_acceleration>
        </imu>
        <always_on>1</always_on>
        <update_rate>1000</update_rate>
        <visualize>true</visualize>
      </sensor>
    </link>
    <link name='RL_HIP'>
      <pose frame=''>-0.35 0.11502 -0.053052 0 -0 0</pose>
      <inertial>
        <pose frame=''>-0.001233 -0.002933 -0.000569 0 -0 0</pose>
        <mass>1.4</mass>
        <inertia>
          <ixx>0.001133</ixx>
          <ixy>0</ixy>
          <ixz>0</ixz>
          <iyy>0.001638</iyy>
          <iyz>0</iyz>
          <izz>0.001243</izz>
        </inertia>
      </inertial>
      <!-- <collision name='RL_HIP_collision'>
        <pose frame=''>0 0 0 0 -0 0</pose>
        <geometry>
          <mesh>
            <scale>1 1 1</scale>
            <uri>model://PONGBOT_Q_V4/meshes/RL_HIP.STL</uri>
          </mesh>
        </geometry>
      </collision> -->
      <visual name='RL_HIP_visual'>
        <pose frame=''>0 0 0 0 -0 0</pose>
        <geometry>
          <mesh>
            <scale>1 1 1</scale>
            <uri>model://PONGBOT_Q_V4/meshes/RL_HIP.STL</uri>
          </mesh>
        </geometry>
        <material>
          <ambient>213 0 0 1</ambient>
          <diffuse>1 1 1 1</diffuse>
          <emissive>0 0 0 1</emissive>
          <specular>0 0 0 0</specular>
        </material>
      </visual>
    </link>
    <joint name='RL_HR_JOINT' type='revolute'>
      <child>RL_HIP</child>
      <parent>REAR_BODY</parent>
      <axis>
        <xyz>1 0 0</xyz>
        <limit>
          <lower>-3.141592</lower>
          <upper>3.141592</upper>
        </limit>
        <dynamics>
          <spring_reference>0</spring_reference>
          <spring_stiffness>0</spring_stiffness>
        </dynamics>
        <use_parent_model_frame>1</use_parent_model_frame>
      </axis>
    </joint>
    <link name='RL_THIGH'>
      <pose frame=''>-0.35 0.21952 -0.053052 0 -0 0</pose>
      <inertial>
        <pose frame=''>0.000151 -0.011407 -0.01871 0 -0 0</pose>
        <mass>3.209</mass>
        <inertia>
          <ixx>0.0179</ixx>
          <ixy>0</ixy>
          <ixz>0</ixz>
          <iyy>0.0178</iyy>
          <iyz>-0.0011</iyz>
          <izz>0.003409</izz>
        </inertia>
      </inertial>
      <!-- <collision name='RL_THIGH_collision'>
        <pose frame=''>0 0 0 0 -0 0</pose>
        <geometry>
          <mesh>
            <scale>1 1 1</scale>
            <uri>model://PONGBOT_Q_V4/meshes/RL_THIGH.STL</uri>
          </mesh>
        </geometry>
      </collision> -->
      <visual name='RL_THIGH_visual'>
        <pose frame=''>0 0 0 0 -0 0</pose>
        <geometry>
          <mesh>
            <scale>1 1 1</scale>
            <uri>model://PONGBOT_Q_V4/meshes/RL_THIGH.STL</uri>
          </mesh>
        </geometry>
        <material>
          <ambient>213 0 0 1</ambient>
          <diffuse>1 1 1 1</diffuse>
          <emissive>0 0 0 1</emissive>
          <specular>0 0 0 0</specular>
        </material>
      </visual>
    </link>
    <joint name='RL_HP_JOINT' type='revolute'>
      <child>RL_THIGH</child>
      <parent>RL_HIP</parent>
      <axis>
        <xyz>0 1 0</xyz>
        <limit>
          <lower>-3.141592</lower>
          <upper>3.141592</upper>
        </limit>
        <dynamics>
          <spring_reference>0</spring_reference>
          <spring_stiffness>0</spring_stiffness>
        </dynamics>
        <use_parent_model_frame>1</use_parent_model_frame>
      </axis>
    </joint>
    <link name='RL_CALF'>
      <pose frame=''>-0.35 0.21952 -0.358052 0 -0 0</pose>
      <inertial>
        <pose frame=''>0.04204 -0.002971 -0.093214 0 -0 0</pose>
        <mass>0.634</mass>
        <inertia>
          <ixx>0.0064</ixx>
          <ixy>5e-05</ixy>
          <ixz>-0.00173</ixz>
          <iyy>0.00783</iyy>
          <iyz>-0.000115</iyz>
          <izz>0.00178</izz>
        </inertia>
      </inertial>
      <!-- <collision name='RL_CALF_collision'>
        <pose frame=''>0 0 0 0 -0 0</pose>
        <geometry>
          <mesh>
            <scale>1 1 1</scale>
            <uri>model://PONGBOT_Q_V4/meshes/RL_CALF.STL</uri>
          </mesh>
        </geometry>
      </collision> -->
      <visual name='RL_CALF_visual'>
        <pose frame=''>0 0 0 0 -0 0</pose>
        <geometry>
          <mesh>
            <scale>1 1 1</scale>
            <uri>model://PONGBOT_Q_V4/meshes/RL_CALF.STL</uri>
          </mesh>
        </geometry>
        <material>
          <ambient>33 33 33 1</ambient>
          <diffuse>1 1 1 1</diffuse>
          <emissive>0 0 0 1</emissive>
          <specular>0 0 0 0</specular>
        </material>
      </visual>
    </link>
    <joint name='RL_KN_JOINT' type='revolute'>
      <child>RL_CALF</child>
      <parent>RL_THIGH</parent>
      <axis>
        <xyz>0 1 0</xyz>
        <limit>
          <lower>-3.141592</lower>
          <upper>3.141592</upper>
        </limit>
        <dynamics>
          <spring_reference>0</spring_reference>
          <spring_stiffness>0</spring_stiffness>
        </dynamics>
        <use_parent_model_frame>1</use_parent_model_frame>
      </axis>
    </joint>
    <link name='RL_TIP'>
      <pose frame=''>-0.23411 0.21952 -0.628392 0 -0 0</pose>
      <inertial>
        <!-- <pose frame=''>0.001412 -0.000739 0.00602 0 -0 0</pose> -->
        <pose frame=''>0.0 -0.0 0.0 0 -0 0</pose>
         <!-- <mass>0.052</mass> -->
         <mass>1.04</mass>
        <inertia>
          <!-- <ixx>0.00005</ixx>
          <ixy>0</ixy>
          <ixz>0</ixz>
          <iyy>0.00005</iyy>
          <iyz>0</iyz>
          <izz>0.00005</izz> -->
          <ixx>0.001</ixx>
          <ixy>0</ixy>
          <ixz>0</ixz>
          <iyy>0.001</iyy>
          <iyz>0</iyz>
          <izz>0.001</izz>
        </inertia>
      </inertial>

      <collision name='RL_TIP_collision'>
        <pose frame=''>0 0 0 0 -0 0</pose>
        <geometry>
          <sphere>
            <radius> .02 </radius>
          </sphere>
        </geometry>
        <surface>
          <bounce>
            <restitution_coefficient> 0 </restitution_coefficient>
          </bounce>
          <friction>
            <ode>
               <mu>  1  </mu>
              <mu2> 1  </mu2>
            </ode>
          </friction>
          <contact>
            <ode>
              <!-- <soft_erp> 0.1 </soft_erp>
              <soft_cfm> 1E-4 </soft_cfm> -->
              <kp>5000000</kp>
              <kd>5000</kd>
              <max_vel>0.1</max_vel>
              <!-- <max_vel>0.01</max_vel> -->
              <min_depth>0.0001</min_depth>
              <!-- <min_depth>0.</min_depth> -->
            </ode>
          </contact>
        </surface>
      </collision>
      <visual name='RL_TIP_visual'>
        <pose frame=''>0 0 0 0 -0 0</pose>
        <geometry>
          <mesh>
            <scale>1 1 1</scale>
            <uri>model://PONGBOT_Q_V4/meshes/RL_TIP.STL</uri>
          </mesh>
        </geometry>
      </visual>
      <sensor name="RL_TIP_contact" type='contact'>
       <contact>
         <collision>RL_TIP_collision</collision>
       </contact>
      </sensor>
    </link>

    <joint name='RL_TIP_JOINT' type='fixed'>
      <child>RL_TIP</child>
      <parent>RL_CALF</parent>
      <sensor name="RL_FT_SENSOR" type="force_torque">
        <force_torque>
          <frame>child</frame>
          <measure_direction>child_to_parent</measure_direction>
        </force_torque>
        <!-- <visualize> True </visualize> -->
      </sensor>
      <physics>
        <ode>
        <limit>
          <cfm>1</cfm>
          <erp>1</erp>
        </limit>
        </ode>
      </physics>
    </joint>

    <link name='RR_HIP'>
      <pose frame=''>-0.35 -0.11502 -0.053052 0 -0 0</pose>
      <inertial>
        <pose frame=''>-0.001233 0.002933 0.000569 0 -0 0</pose>
        <mass>1.4</mass>
        <inertia>
          <ixx>0.001133</ixx>
          <ixy>0</ixy>
          <ixz>0</ixz>
          <iyy>0.001638</iyy>
          <iyz>0</iyz>
          <izz>0.001243</izz>
        </inertia>
      </inertial>
      <!-- <collision name='RR_HIP_collision'>
        <pose frame=''>0 0 0 0 -0 0</pose>
        <geometry>
          <mesh>
            <scale>1 1 1</scale>
            <uri>model://PONGBOT_Q_V4/meshes/RR_HIP.STL</uri>
          </mesh>
        </geometry>
      </collision> -->
      <visual name='RR_HIP_visual'>
        <pose frame=''>0 0 0 0 -0 0</pose>
        <geometry>
          <mesh>
            <scale>1 1 1</scale>
            <uri>model://PONGBOT_Q_V4/meshes/RR_HIP.STL</uri>
          </mesh>
        </geometry>
        <material>
          <ambient>213 0 0 1</ambient>
          <diffuse>1 1 1 1</diffuse>
          <emissive>0 0 0 1</emissive>
          <specular>0 0 0 0</specular>
        </material>
      </visual>
    </link>
    <joint name='RR_HR_JOINT' type='revolute'>
      <child>RR_HIP</child>
      <parent>REAR_BODY</parent>
      <axis>
        <xyz>1 0 0</xyz>
        <limit>
          <lower>-3.141592</lower>
          <upper>3.141592</upper>
        </limit>
        <dynamics>
          <spring_reference>0</spring_reference>
          <spring_stiffness>0</spring_stiffness>
        </dynamics>
        <use_parent_model_frame>1</use_parent_model_frame>
      </axis>
    </joint>
    <link name='RR_THIGH'>
      <pose frame=''>-0.35 -0.21952 -0.053052 0 -0 0</pose>
      <inertial>
        <pose frame=''>-0.000151 0.011407 -0.01871 0 -0 0</pose>
        <mass>3.209</mass>
        <inertia>
          <ixx>0.0179</ixx>
          <ixy>0</ixy>
          <ixz>0</ixz>
          <iyy>0.0178</iyy>
          <iyz>0.0011</iyz>
          <izz>0.003409</izz>
        </inertia>
      </inertial>
      <!-- <collision name='RR_THIGH_collision'>
        <pose frame=''>0 0 0 0 -0 0</pose>
        <geometry>
          <mesh>
            <scale>1 1 1</scale>
            <uri>model://PONGBOT_Q_V4/meshes/RR_THIGH.STL</uri>
          </mesh>
        </geometry>
      </collision> -->
      <visual name='RR_THIGH_visual'>
        <pose frame=''>0 0 0 0 -0 0</pose>
        <geometry>
          <mesh>
            <scale>1 1 1</scale>
            <uri>model://PONGBOT_Q_V4/meshes/RR_THIGH.STL</uri>
          </mesh>
        </geometry>
        <material>
          <ambient>213 0 0 1</ambient>
          <diffuse>1 1 1 1</diffuse>
          <emissive>0 0 0 1</emissive>
          <specular>0 0 0 0</specular>
        </material>
      </visual>
    </link>
    <joint name='RR_HP_JOINT' type='revolute'>
      <child>RR_THIGH</child>
      <parent>RR_HIP</parent>
      <axis>
        <xyz>0 1 0</xyz>
        <limit>
          <lower>-3.141592</lower>
          <upper>3.141592</upper>
        </limit>
        <dynamics>
          <spring_reference>0</spring_reference>
          <spring_stiffness>0</spring_stiffness>
        </dynamics>
        <use_parent_model_frame>1</use_parent_model_frame>
      </axis>
    </joint>
    <link name='RR_CALF'>
      <pose frame=''>-0.35 -0.21952 -0.358052 0 -0 0</pose>
      <inertial>
        <pose frame=''>0.04204 0.000297 -0.093214 0 -0 0</pose>
        <mass>0.634</mass>
        <inertia>
          <ixx>0.0064</ixx>
          <ixy>-5e-05</ixy>
          <ixz>-0.00173</ixz>
          <iyy>0.00783</iyy>
          <iyz>0.000115</iyz>
          <izz>0.00178</izz>
        </inertia>
      </inertial>
      <!-- <collision name='RR_CALF_collision'>
        <pose frame=''>0 0 0 0 -0 0</pose>
        <geometry>
          <mesh>
            <scale>1 1 1</scale>
            <uri>model://PONGBOT_Q_V4/meshes/RR_CALF.STL</uri>
          </mesh>
        </geometry>
      </collision> -->
      <visual name='RR_CALF_visual'>
        <pose frame=''>0 0 0 0 -0 0</pose>
        <geometry>
          <mesh>
            <scale>1 1 1</scale>
            <uri>model://PONGBOT_Q_V4/meshes/RR_CALF.STL</uri>
          </mesh>
        </geometry>
        <material>
          <ambient>33 33 33 1</ambient>
          <diffuse>1 1 1 1</diffuse>
          <emissive>0 0 0 1</emissive>
          <specular>0 0 0 0</specular>
        </material>
      </visual>
    </link>
    <joint name='RR_KN_JOINT' type='revolute'>
      <child>RR_CALF</child>
      <parent>RR_THIGH</parent>
      <axis>
        <xyz>0 1 0</xyz>
        <limit>
          <lower>-3.141592</lower>
          <upper>3.141592</upper>
        </limit>
        <dynamics>
          <spring_reference>0</spring_reference>
          <spring_stiffness>0</spring_stiffness>
        </dynamics>
        <use_parent_model_frame>1</use_parent_model_frame>
      </axis>
    </joint>
    <link name='RR_TIP'>
      <pose frame=''>-0.23411 -0.21952 -0.628392 0 -0 0</pose>
      <inertial>
        <pose frame=''>-0.0 0.0 -0.0 0 -0 0</pose>
        <!-- <mass>0.052</mass> -->
        <mass>1.04</mass>
        <inertia>
          <!-- <ixx>0.00005</ixx>
          <ixy>0</ixy>
          <ixz>0</ixz>
          <iyy>0.00005</iyy>
          <iyz>0</iyz>
          <izz>0.00005</izz> -->
          <ixx>0.001</ixx>
          <ixy>0</ixy>
          <ixz>0</ixz>
          <iyy>0.001</iyy>
          <iyz>0</iyz>
          <izz>0.001</izz>
        </inertia>
      </inertial>
      <collision name='RR_TIP_collision'>
        <pose frame=''>0 0 0 0 -0 0</pose>
        <geometry>
          <sphere>
            <radius> .02 </radius>
          </sphere>
        </geometry>
        <surface>
          <bounce>
            <restitution_coefficient> 0 </restitution_coefficient>
          </bounce>
          <friction>
            <ode>
              <mu>  1  </mu>
             <mu2> 1  </mu2>
            </ode>
          </friction>
          <contact>
            <ode>
              <!-- <soft_erp> 0.1 </soft_erp>
              <soft_cfm> 1E-4 </soft_cfm> -->
              <kp>5000000</kp>
              <kd>5000</kd>
              <max_vel>0.1</max_vel>
              <!-- <max_vel>0.01</max_vel> -->
              <min_depth>0.0001</min_depth>
              <!-- <min_depth>0.</min_depth> -->
            </ode>
          </contact>
        </surface>
      </collision>
      <visual name='RR_TIP_visual'>
        <pose frame=''>0 0 0 0 -0 0</pose>
        <geometry>
          <mesh>
            <scale>1 1 1</scale>
            <uri>model://PONGBOT_Q_V4/meshes/RR_TIP.STL</uri>
          </mesh>
        </geometry>
      </visual>
      <sensor name="RR_TIP_contact" type='contact'>
       <contact>
         <collision>RR_TIP_collision</collision>
       </contact>
      </sensor>
    </link>
    <joint name='RR_TIP_JOINT' type='fixed'>
      <child>RR_TIP</child>
      <parent>RR_CALF</parent>
      <sensor name="RR_FT_SENSOR" type="force_torque">
        <force_torque>
          <frame>child</frame>
          <measure_direction>child_to_parent</measure_direction>
        </force_torque>
        <!-- <visualize> True </visualize> -->
      </sensor>
      <physics>
        <ode>
        <limit>
          <cfm>1</cfm>
          <erp>1</erp>
        </limit>
        </ode>
      </physics>
    </joint>
    <link name='FRONT_BODY'>
      <pose frame=''>0 0 0 0 -0 0</pose>
      <inertial>
        <pose frame=''>0.225 0 -0.0227 0 -0 0</pose>
        <mass>10.507</mass>
        <inertia>
          <!-- <ixx>0.091333</ixx>
          <ixy>0</ixy>
          <ixz>0.00107</ixz>
          <iyy>0.1341</iyy>
          <iyz>0</iyz>
          <izz>0.1877</izz> -->
          <ixx>0.091333</ixx>
          <ixy>0</ixy>
          <ixz>0.00</ixz>
          <iyy>0.1341</iyy>
          <iyz>0</iyz>
          <izz>0.1877</izz>

        </inertia>
      </inertial>
      <!-- <collision name='FRONT_BODY_collision'>
        <pose frame=''>0 0 0 0 -0 0</pose>
        <geometry>
          <mesh>
            <scale>1 1 1</scale>
            <uri>model://PONGBOT_Q_V4/meshes/FRONT_BODY.STL</uri>
          </mesh>
        </geometry>
      </collision> -->
      <visual name='FRONT_BODY_visual'>
        <pose frame=''>0 0 0 0 -0 0</pose>
        <geometry>
          <mesh>
            <scale>1 1 1</scale>
            <uri>model://PONGBOT_Q_V4/meshes/FRONT_BODY.STL</uri>
          </mesh>
        </geometry>
        <material>
          <ambient>97 97 97 1</ambient>
          <diffuse>1 1 1 1</diffuse>
          <emissive>0 0 0 1</emissive>
          <specular>0 0 0 0</specular>
        </material>
      </visual>
    </link>
    <joint name='WAIST_JOINT' type='revolute'>
      <child>FRONT_BODY</child>
      <parent>REAR_BODY</parent>
      <axis>
        <xyz>0 0 1</xyz>
        <limit>
          <lower>-3.141592</lower>
          <upper>3.141592</upper>
        </limit>
        <dynamics>
          <spring_reference>0</spring_reference>
          <spring_stiffness>0</spring_stiffness>
        </dynamics>
        <use_parent_model_frame>1</use_parent_model_frame>
      </axis>
    </joint>
    <link name='FL_HIP'>
      <pose frame=''>0.35 0.11502 -0.053052 0 -0 0</pose>
      <inertial>
        <pose frame=''>0.001233 0.002933 0.000569 0 -0 0</pose>
        <mass>1.4</mass>
        <inertia>
          <ixx>0.001121</ixx>
          <ixy>0</ixy>
          <ixz>0</ixz>
          <iyy>0.0011635</iyy>
          <iyz>0</iyz>
          <izz>0.001228</izz>
        </inertia>
      </inertial>
      <!-- <collision name='FL_HIP_collision'>
        <pose frame=''>0 0 0 0 -0 0</pose>
        <geometry>
          <mesh>
            <scale>1 1 1</scale>
            <uri>model://PONGBOT_Q_V4/meshes/FL_HIP.STL</uri>
          </mesh>
        </geometry>
      </collision> -->
      <visual name='FL_HIP_visual'>
        <pose frame=''>0 0 0 0 -0 0</pose>
        <geometry>
          <mesh>
            <scale>1 1 1</scale>
            <uri>model://PONGBOT_Q_V4/meshes/FL_HIP.STL</uri>
          </mesh>
        </geometry>
        <material>
          <ambient>213 0 0 1</ambient>
          <diffuse>1 1 1 1</diffuse>
          <emissive>0 0 0 1</emissive>
          <specular>0 0 0 0</specular>
        </material>
      </visual>
    </link>
    <joint name='FL_HR_JOINT' type='revolute'>
      <child>FL_HIP</child>
      <parent>FRONT_BODY</parent>
      <axis>
        <xyz>1 0 0</xyz>
        <limit>
          <lower>-3.141592</lower>
          <upper>3.141592</upper>
        </limit>
        <dynamics>
          <spring_reference>0</spring_reference>
          <spring_stiffness>0</spring_stiffness>
        </dynamics>
        <use_parent_model_frame>1</use_parent_model_frame>
      </axis>
    </joint>
    <link name='FL_THIGH'>
      <pose frame=''>0.35 0.21952 -0.053052 0 -0 0</pose>
      <inertial>
        <pose frame=''>0.000151 -0.011407 -0.01871 0 -0 0</pose>
        <mass>3.209</mass>
        <inertia>
          <ixx>0.0179</ixx>
          <ixy>0</ixy>
          <ixz>0</ixz>
          <iyy>0.0178</iyy>
          <iyz>-0.0011</iyz>
          <izz>0.00422</izz>
        </inertia>
      </inertial>
      <!-- <collision name='FL_THIGH_collision'>
        <pose frame=''>0 0 0 0 -0 0</pose>
        <geometry>
          <mesh>
            <scale>1 1 1</scale>
            <uri>model://PONGBOT_Q_V4/meshes/FL_THIGH.STL</uri>
          </mesh>
        </geometry>
      </collision> -->
      <visual name='FL_THIGH_visual'>
        <pose frame=''>0 0 0 0 -0 0</pose>
        <geometry>
          <mesh>
            <scale>1 1 1</scale>
            <uri>model://PONGBOT_Q_V4/meshes/FL_THIGH.STL</uri>
          </mesh>
        </geometry>
        <material>
          <ambient>213 0 0 1</ambient>
          <diffuse>1 1 1 1</diffuse>
          <emissive>0 0 0 1</emissive>
          <specular>0 0 0 0</specular>
        </material>
      </visual>
    </link>
    <joint name='FL_HP_JOINT' type='revolute'>
      <child>FL_THIGH</child>
      <parent>FL_HIP</parent>
      <axis>
        <xyz>0 1 0</xyz>
        <limit>
          <lower>-3.141592</lower>
          <upper>3.141592</upper>
        </limit>
        <dynamics>
          <spring_reference>0</spring_reference>
          <spring_stiffness>0</spring_stiffness>
        </dynamics>
        <use_parent_model_frame>1</use_parent_model_frame>
      </axis>
    </joint>
    <link name='FL_CALF'>
      <pose frame=''>0.35 0.21952 -0.358052 0 -0 0</pose>
      <inertial>
        <pose frame=''>0.042069 -0.002971 -0.093214 0 -0 0</pose>
        <mass>0.634</mass>
        <inertia>
          <ixx>0.0064</ixx>
          <ixy>5e-05</ixy>
          <ixz>-0.00173</ixz>
          <iyy>0.00783</iyy>
          <iyz>-0.000115</iyz>
          <izz>0.00178</izz>
        </inertia>
      </inertial>
      <!-- <collision name='FL_CALF_collision'>
        <pose frame=''>0 0 0 0 -0 0</pose>
        <geometry>
          <mesh>
            <scale>1 1 1</scale>
            <uri>model://PONGBOT_Q_V4/meshes/FL_CALF.STL</uri>
          </mesh>
        </geometry>
      </collision> -->
      <visual name='FL_CALF_visual'>
        <pose frame=''>0 0 0 0 -0 0</pose>
        <geometry>
          <mesh>
            <scale>1 1 1</scale>
            <uri>model://PONGBOT_Q_V4/meshes/FL_CALF.STL</uri>
          </mesh>
        </geometry>
        <material>
          <ambient>33 33 33 1</ambient>
          <diffuse>1 1 1 1</diffuse>
          <emissive>0 0 0 1</emissive>
          <specular>0 0 0 0</specular>
        </material>
      </visual>
    </link>
    <joint name='FL_KN_JOINT' type='revolute'>
      <child>FL_CALF</child>
      <parent>FL_THIGH</parent>
      <axis>
        <xyz>0 1 0</xyz>
        <limit>
          <lower>-3.141592</lower>
          <upper>3.141592</upper>
        </limit>
        <dynamics>
          <spring_reference>0</spring_reference>
          <spring_stiffness>0</spring_stiffness>
        </dynamics>
        <use_parent_model_frame>1</use_parent_model_frame>
      </axis>
    </joint>
    <link name='FL_TIP'>
      <pose frame=''>0.46589 0.21952 -0.628392 0 -0 0</pose>
      <inertial>
        <!-- <pose frame=''>0.001059 0.000153 0.006135 0 -0 0</pose> -->
        <pose frame=''>0.0 0.0 0.0 0 -0 0</pose>
        <!-- <mass>0.052</mass> -->
        <mass>1.04</mass>
        <inertia>
          <!-- <ixx>0.00005</ixx>
          <ixy>0</ixy>
          <ixz>0</ixz>
          <iyy>0.00005</iyy>
          <iyz>0</iyz>
          <izz>0.00005</izz> -->
          <ixx>0.001</ixx>
          <ixy>0</ixy>
          <ixz>0</ixz>
          <iyy>0.001</iyy>
          <iyz>0</iyz>
          <izz>0.001</izz>
        </inertia>
      </inertial>
      <collision name='FL_TIP_collision'>
        <pose frame=''>0 0 0 0 -0 0</pose>
        <geometry>
          <sphere>
            <radius> .02 </radius>
          </sphere>
        </geometry>
        <surface>
          <bounce>
            <restitution_coefficient> 0 </restitution_coefficient>
          </bounce>
          <friction>
            <ode>
               <mu>  1  </mu>
              <mu2> 1  </mu2>
            </ode>
          </friction>
          <contact>
            <ode>
              <!-- <soft_erp> 0.1 </soft_erp>
              <soft_cfm> 1E-4 </soft_cfm> -->
              <kp>5000000</kp>
              <kd>5000</kd>
              <max_vel>0.1</max_vel>
              <!-- <max_vel>0.01</max_vel> -->
               <min_depth>0.0001</min_depth>
              <!-- <min_depth>0.0</min_depth> -->
            </ode>
          </contact>
        </surface>
      </collision>
      <visual name='FL_TIP_visual'>
        <pose frame=''>0 0 0 0 -0 0</pose>
        <geometry>
          <mesh>
            <scale>1 1 1</scale>
            <uri>model://PONGBOT_Q_V4/meshes/FL_TIP.STL</uri>
          </mesh>
        </geometry>
      </visual>
      <sensor name="FL_TIP_contact" type='contact'>
       <contact>
         <collision>FL_TIP_collision</collision>
       </contact>
      </sensor>
    </link>
    <joint name='FL_TIP_JOINT' type='fixed'>
      <child>FL_TIP</child>
      <parent>FL_CALF</parent>
      <sensor name="FL_FT_SENSOR" type="force_torque">
        <force_torque>
          <frame>child</frame>
          <measure_direction>child_to_parent</measure_direction>
        </force_torque>
        <!-- <visualize> True </visualize> -->
      </sensor>
      <physics>
        <ode>
        <limit>
          <cfm>1</cfm>
          <erp>1</erp>
        </limit>
        </ode>
      </physics>
    </joint>
    <link name='FR_HIP'>
      <pose frame=''>0.35 -0.11502 -0.053052 0 -0 0</pose>
      <inertial>
        <pose frame=''>0.001233 -0.002933 -0.000569 0 -0 0</pose>
        <mass>1.4</mass>
        <inertia>
          <ixx>0.001121</ixx>
          <ixy>0</ixy>
          <ixz>0</ixz>
          <iyy>0.001635</iyy>
          <iyz>0</iyz>
          <izz>0.001228</izz>
        </inertia>
      </inertial>
      <!-- <collision name='FR_HIP_collision'>
        <pose frame=''>0 0 0 0 -0 0</pose>
        <geometry>
          <mesh>
            <scale>1 1 1</scale>
            <uri>model://PONGBOT_Q_V4/meshes/FR_HIP.STL</uri>
          </mesh>
        </geometry>
      </collision> -->
      <visual name='FR_HIP_visual'>
        <pose frame=''>0 0 0 0 -0 0</pose>
        <geometry>
          <mesh>
            <scale>1 1 1</scale>
            <uri>model://PONGBOT_Q_V4/meshes/FR_HIP.STL</uri>
          </mesh>
        </geometry>
        <material>
          <ambient>213 0 0 1</ambient>
          <diffuse>1 1 1 1</diffuse>
          <emissive>0 0 0 1</emissive>
          <specular>0 0 0 0</specular>
        </material>
      </visual>
    </link>
    <joint name='FR_HR_JOINT' type='revolute'>
      <child>FR_HIP</child>
      <parent>FRONT_BODY</parent>
      <axis>
        <xyz>1 0 0</xyz>
        <limit>
          <lower>-3.141592</lower>
          <upper>3.141592</upper>
        </limit>
        <dynamics>
          <spring_reference>0</spring_reference>
          <spring_stiffness>0</spring_stiffness>
        </dynamics>
        <use_parent_model_frame>1</use_parent_model_frame>
      </axis>
    </joint>
    <link name='FR_THIGH'>
      <pose frame=''>0.35 -0.21952 -0.053052 0 -0 0</pose>
      <inertial>
        <pose frame=''>-0.000151 0.011407 -0.01871 0 -0 0</pose>
        <mass>3.209</mass>
        <inertia>
          <ixx>0.0179</ixx>
          <ixy>0</ixy>
          <ixz>0</ixz>
          <iyy>0.0178</iyy>
          <iyz>0.0011</iyz>
          <izz>0.00422</izz>
        </inertia>
      </inertial>
      <!-- <collision name='FR_THIGH_collision'>
        <pose frame=''>0 0 0 0 -0 0</pose>
        <geometry>
          <mesh>
            <scale>1 1 1</scale>
            <uri>model://PONGBOT_Q_V4/meshes/FR_THIGH.STL</uri>
          </mesh>
        </geometry>
      </collision> -->
      <visual name='FR_THIGH_visual'>
        <pose frame=''>0 0 0 0 -0 0</pose>
        <geometry>
          <mesh>
            <scale>1 1 1</scale>
            <uri>model://PONGBOT_Q_V4/meshes/FR_THIGH.STL</uri>
          </mesh>
        </geometry>
        <material>
          <ambient>213 0 0 1</ambient>
          <diffuse>1 1 1 1</diffuse>
          <emissive>0 0 0 1</emissive>
          <specular>0 0 0 0</specular>
        </material>
      </visual>
    </link>
    <joint name='FR_HP_JOINT' type='revolute'>
      <child>FR_THIGH</child>
      <parent>FR_HIP</parent>
      <axis>
        <xyz>0 1 0</xyz>
        <limit>
          <lower>-3.141592</lower>
          <upper>3.141592</upper>
        </limit>
        <dynamics>
          <spring_reference>0</spring_reference>
          <spring_stiffness>0</spring_stiffness>
        </dynamics>
        <use_parent_model_frame>1</use_parent_model_frame>
      </axis>
    </joint>
    <link name='FR_CALF'>
      <pose frame=''>0.35 -0.21952 -0.358052 0 -0 0</pose>
      <inertial>
        <pose frame=''>0.04204 0.002971 -0.093214 0 -0 0</pose>
        <mass>0.634</mass>
        <inertia>
          <ixx>0.0064</ixx>
          <ixy>-5e-05</ixy>
          <ixz>-0.00173</ixz>
          <iyy>0.00783</iyy>
          <iyz>0.000115</iyz>
          <izz>0.00178</izz>
        </inertia>
      </inertial>
      <!-- <collision name='FR_CALF_collision'>
        <pose frame=''>0 0 0 0 -0 0</pose>
        <geometry>
          <mesh>
            <scale>1 1 1</scale>
            <uri>model://PONGBOT_Q_V4/meshes/FR_CALF.STL</uri>
          </mesh>
        </geometry>
      </collision> -->
      <visual name='FR_CALF_visual'>
        <pose frame=''>0 0 0 0 -0 0</pose>
        <geometry>
          <mesh>
            <scale>1 1 1</scale>
            <uri>model://PONGBOT_Q_V4/meshes/FR_CALF.STL</uri>
          </mesh>
        </geometry>
        <material>
          <ambient>33 33 33 1</ambient>
          <diffuse>1 1 1 1</diffuse>
          <emissive>0 0 0 1</emissive>
          <specular>0 0 0 0</specular>
        </material>
      </visual>
    </link>
    <joint name='FR_KN_JOINT' type='revolute'>
      <child>FR_CALF</child>
      <parent>FR_THIGH</parent>
      <axis>
        <xyz>0 1 0</xyz>
        <limit>
          <lower>-3.141592</lower>
          <upper>3.141592</upper>
        </limit>
        <dynamics>
          <spring_reference>0</spring_reference>
          <spring_stiffness>0</spring_stiffness>
        </dynamics>
        <use_parent_model_frame>1</use_parent_model_frame>
      </axis>
    </joint>

    <link name='FR_TIP'>
      <pose frame=''>0.46589 -0.21952 -0.628392 0 -0 0</pose>
      <inertial>
        <!-- <pose frame=''>0.001642 0.000859 0.005946 0 -0 0</pose> -->
        <pose frame=''>0.0 0.0 0.0 0 -0 0</pose>
        <!-- <mass>0.052</mass> -->
        <mass>1.04</mass>
        <inertia>
          <!-- <ixx>0.00005</ixx>
          <ixy>0</ixy>
          <ixz>0</ixz>
          <iyy>0.00005</iyy>
          <iyz>0</iyz>
          <izz>0.00005</izz> -->
          <ixx>0.001</ixx>
          <ixy>0</ixy>
          <ixz>0</ixz>
          <iyy>0.001</iyy>
          <iyz>0</iyz>
          <izz>0.001</izz>
        </inertia>
      </inertial>

      <collision name='FR_TIP_collision'>
        <pose frame=''>0 0 0 0 -0 0</pose>
        <geometry>
          <sphere>
            <radius> .02 </radius>
          </sphere>
        </geometry>
        <surface>
          <bounce>
            <restitution_coefficient> 0 </restitution_coefficient>
          </bounce>
          <friction>
            <ode>
              <mu>  1  </mu>
             <mu2> 1  </mu2>
            </ode>
          </friction>
          <contact>
            <ode>
             <!-- <soft_erp> 0.1 </soft_erp>
              <soft_cfm> 1E-4 </soft_cfm> -->
              <kp>5000000</kp>
              <kd>5000</kd>
               <max_vel>0.1</max_vel>
               <!-- <max_vel>0.01</max_vel> -->
               <min_depth>0.0001</min_depth>
              <!-- <min_depth>0.000</min_depth> -->
            </ode>
          </contact>

        </surface>
      </collision>
      <visual name='FR_TIP_visual'>
        <pose frame=''>0 0 0 0 -0 0</pose>
        <geometry>
          <mesh>
            <scale>1 1 1</scale>
            <uri>model://PONGBOT_Q_V4/meshes/FR_TIP.STL</uri>
          </mesh>
        </geometry>
      </visual>
      <sensor name="FR_TIP_contact" type='contact'>
       <contact>
         <collision>FR_TIP_collision</collision>
       </contact>
      </sensor>
    </link>

    <joint name='FR_TIP_JOINT' type='fixed'>
      <child>FR_TIP</child>
      <parent>FR_CALF</parent>
      <sensor name="FR_FT_SENSOR" type="force_torque">
        <force_torque>
          <frame>child</frame>
          <measure_direction>child_to_parent</measure_direction>
        </force_torque>
        <!-- <visualize> True </visualize> -->
      </sensor>

       <physics>
        <ode>
        <limit>
          <cfm>1</cfm>
          <erp>1</erp>
        </limit>
        </ode>
      </physics>

    </joint>
  </model>
</sdf>
