<sdf version='1.6'>
  <model name='PONGBOT_Q_V3'>
    <link name='REAR_BODY'>
      <pose frame=''>0 0 0 0 -0 0</pose>
      <inertial>
        <pose frame=''>0.10445 -0.000119 0.02612 0 -0 0</pose>
        <mass>5.5101</mass>
        <inertia>
          <ixx>0.050447</ixx>
          <ixy>-1.3727e-05</ixy>
          <ixz>0.0033483</ixz>
          <iyy>0.10139</iyy>
          <iyz>-1.1894e-06</iyz>
          <izz>0.12946</izz>
        </inertia>
      </inertial>
      <collision name='REAR_BODY_collision'>
        <pose frame=''>0 0 0 0 -0 0</pose>
        <geometry>
          <mesh>
            <scale>1 1 1</scale>
            <uri>model://PONGBOT_Q_V3/meshes/REAR_BODY.STL</uri>
          </mesh>
        </geometry>
      </collision>
      <visual name='REAR_BODY_visual'>
        <pose frame=''>0 0 0 0 -0 0</pose>
        <geometry>
          <mesh>
            <scale>1 1 1</scale>
            <uri>model://PONGBOT_Q_V3/meshes/REAR_BODY.STL</uri>
          </mesh>
        </geometry>
      </visual>
    </link>
    <link name='RL_HIP'>
      <pose frame=''>0 0.11502 0.000315 0 -0 0</pose>
      <inertial>
        <pose frame=''>-0.001266 0.00609 0.000303 0 -0 0</pose>
        <mass>0.82805</mass>
        <inertia>
          <ixx>0.0008886</ixx>
          <ixy>2.7075e-05</ixy>
          <ixz>-1.5479e-05</ixz>
          <iyy>0.00098486</iyy>
          <iyz>-1.4485e-05</iyz>
          <izz>0.00099072</izz>
        </inertia>
      </inertial>
      <collision name='RL_HIP_collision'>
        <pose frame=''>0 0 0 0 -0 0</pose>
        <geometry>
          <mesh>
            <scale>1 1 1</scale>
            <uri>model://PONGBOT_Q_V3/meshes/RL_HIP.STL</uri>
          </mesh>
        </geometry>
      </collision>
      <visual name='RL_HIP_visual'>
        <pose frame=''>0 0 0 0 -0 0</pose>
        <geometry>
          <mesh>
            <scale>1 1 1</scale>
            <uri>model://PONGBOT_Q_V3/meshes/RL_HIP.STL</uri>
          </mesh>
        </geometry>
      </visual>
    </link>
    <joint name='RL_HR_JOINT' type='revolute'>
      <child>RL_HIP</child>
      <parent>REAR_BODY</parent>
      <axis>
        <xyz>-1 0 -0</xyz>
        <limit>
          <lower>-1e+16</lower>
          <upper>1e+16</upper>
        </limit>
        <dynamics>
          <spring_reference>0</spring_reference>
          <spring_stiffness>0</spring_stiffness>
        </dynamics>
        <use_parent_model_frame>1</use_parent_model_frame>
      </axis>
    </joint>
    <link name='RL_THIGH'>
      <pose frame=''>-0 0.22002 0.000602 0 -0 0</pose>
      <inertial>
        <pose frame=''>-0.000808 -0.012263 -0.037799 0 -0 0</pose>
        <mass>1.25</mass>
        <inertia>
          <ixx>0.0099481</ixx>
          <ixy>1.5953e-05</ixy>
          <ixz>-0.00019685</ixz>
          <iyy>0.010319</iyy>
          <iyz>0.00060839</iyz>
          <izz>0.0013045</izz>
        </inertia>
      </inertial>
      <collision name='RL_THIGH_collision'>
        <pose frame=''>0 0 0 0 -0 0</pose>
        <geometry>
          <mesh>
            <scale>1 1 1</scale>
            <uri>model://PONGBOT_Q_V3/meshes/RL_THIGH.STL</uri>
          </mesh>
        </geometry>
      </collision>
      <visual name='RL_THIGH_visual'>
        <pose frame=''>0 0 0 0 -0 0</pose>
        <geometry>
          <mesh>
            <scale>1 1 1</scale>
            <uri>model://PONGBOT_Q_V3/meshes/RL_THIGH.STL</uri>
          </mesh>
        </geometry>
      </visual>
    </link>
    <joint name='RL_HP_JOINT' type='revolute'>
      <child>RL_THIGH</child>
      <parent>RL_HIP</parent>
      <axis>
        <xyz>-0 1 0.002736</xyz>
        <limit>
          <lower>-1e+16</lower>
          <upper>1e+16</upper>
        </limit>
        <dynamics>
          <spring_reference>0</spring_reference>
          <spring_stiffness>0</spring_stiffness>
        </dynamics>
        <use_parent_model_frame>1</use_parent_model_frame>
      </axis>
    </joint>
    <link name='RL_CALF'>
      <pose frame=''>-0.006869 0.220854 -0.304318 0 -0 0</pose>
      <inertial>
        <pose frame=''>-0.003348 0.00229 -0.052784 0 -0 0</pose>
        <mass>0.351851</mass>
        <inertia>
          <ixx>0.00337968</ixx>
          <ixy>1.01258e-05</ixy>
          <ixz>-8.13952e-05</ixz>
          <iyy>0.00328849</iyy>
          <iyz>-8.04707e-05</iyz>
          <izz>0.000182429</izz>
        </inertia>
      </inertial>
      <collision name='RL_CALF_collision'>
        <pose frame=''>0 0 0 0 -0 0</pose>
        <geometry>
          <mesh>
            <scale>1 1 1</scale>
            <uri>model://PONGBOT_Q_V3/meshes/RL_CALF.STL</uri>
          </mesh>
        </geometry>
      </collision>
      <collision name='RL_CALF_fixed_joint_lump__RL_TIP_collision_1'>
        <pose frame=''>-0.022186 0.000805 -0.29413 0 -0 0</pose>
        <geometry>
          <mesh>
            <scale>1 1 1</scale>
            <uri>model://PONGBOT_Q_V3/meshes/RL_TIP.STL</uri>
          </mesh>
        </geometry>
      </collision>
      <visual name='RL_CALF_visual'>
        <pose frame=''>0 0 0 0 -0 0</pose>
        <geometry>
          <mesh>
            <scale>1 1 1</scale>
            <uri>model://PONGBOT_Q_V3/meshes/RL_CALF.STL</uri>
          </mesh>
        </geometry>
      </visual>
      <visual name='RL_CALF_fixed_joint_lump__RL_TIP_visual_1'>
        <pose frame=''>-0.022186 0.000805 -0.29413 0 -0 0</pose>
        <geometry>
          <mesh>
            <scale>1 1 1</scale>
            <uri>model://PONGBOT_Q_V3/meshes/RL_TIP.STL</uri>
          </mesh>
        </geometry>
      </visual>
    </link>
    <joint name='RL_KN_JOINT' type='revolute'>
      <child>RL_CALF</child>
      <parent>RL_THIGH</parent>
      <axis>
        <xyz>-0 1 0.002736</xyz>
        <limit>
          <lower>-1e+16</lower>
          <upper>1e+16</upper>
        </limit>
        <dynamics>
          <spring_reference>0</spring_reference>
          <spring_stiffness>0</spring_stiffness>
        </dynamics>
        <use_parent_model_frame>1</use_parent_model_frame>
      </axis>
    </joint>
    <link name='RR_HIP'>
      <pose frame=''>0 -0.11502 0.000315 0 -0 0</pose>
      <inertial>
        <pose frame=''>-0.001266 -0.00609 -0.000303 0 -0 0</pose>
        <mass>0.82805</mass>
        <inertia>
          <ixx>0.0008886</ixx>
          <ixy>-2.7075e-05</ixy>
          <ixz>1.5479e-05</ixz>
          <iyy>0.00098486</iyy>
          <iyz>-1.4485e-05</iyz>
          <izz>0.00099072</izz>
        </inertia>
      </inertial>
      <collision name='RR_HIP_collision'>
        <pose frame=''>0 0 0 0 -0 0</pose>
        <geometry>
          <mesh>
            <scale>1 1 1</scale>
            <uri>model://PONGBOT_Q_V3/meshes/RR_HIP.STL</uri>
          </mesh>
        </geometry>
      </collision>
      <visual name='RR_HIP_visual'>
        <pose frame=''>0 0 0 0 -0 0</pose>
        <geometry>
          <mesh>
            <scale>1 1 1</scale>
            <uri>model://PONGBOT_Q_V3/meshes/RR_HIP.STL</uri>
          </mesh>
        </geometry>
      </visual>
    </link>
    <joint name='RR_HR_JOINT' type='revolute'>
      <child>RR_HIP</child>
      <parent>REAR_BODY</parent>
      <axis>
        <xyz>-1 0 -0</xyz>
        <limit>
          <lower>-1e+16</lower>
          <upper>1e+16</upper>
        </limit>
        <dynamics>
          <spring_reference>0</spring_reference>
          <spring_stiffness>0</spring_stiffness>
        </dynamics>
        <use_parent_model_frame>1</use_parent_model_frame>
      </axis>
    </joint>
    <link name='RR_THIGH'>
      <pose frame=''>0 -0.22002 2.7e-05 0 -0 0</pose>
      <inertial>
        <pose frame=''>-0.000893 0.01247 -0.037729 0 -0 0</pose>
        <mass>1.25</mass>
        <inertia>
          <ixx>0.0099483</ixx>
          <ixy>-1.036e-05</ixy>
          <ixz>-0.00019293</ixz>
          <iyy>0.010326</iyy>
          <iyz>-0.00055914</iyz>
          <izz>0.0012979</izz>
        </inertia>
      </inertial>
      <collision name='RR_THIGH_collision'>
        <pose frame=''>0 0 0 0 -0 0</pose>
        <geometry>
          <mesh>
            <scale>1 1 1</scale>
            <uri>model://PONGBOT_Q_V3/meshes/RR_THIGH.STL</uri>
          </mesh>
        </geometry>
      </collision>
      <visual name='RR_THIGH_visual'>
        <pose frame=''>0 0 0 0 -0 0</pose>
        <geometry>
          <mesh>
            <scale>1 1 1</scale>
            <uri>model://PONGBOT_Q_V3/meshes/RR_THIGH.STL</uri>
          </mesh>
        </geometry>
      </visual>
    </link>
    <joint name='RR_HP_JOINT' type='revolute'>
      <child>RR_THIGH</child>
      <parent>RR_HIP</parent>
      <axis>
        <xyz>-0 1 0.002736</xyz>
        <limit>
          <lower>-1e+16</lower>
          <upper>1e+16</upper>
        </limit>
        <dynamics>
          <spring_reference>0</spring_reference>
          <spring_stiffness>0</spring_stiffness>
        </dynamics>
        <use_parent_model_frame>1</use_parent_model_frame>
      </axis>
    </joint>
    <link name='RR_CALF'>
      <pose frame=''>-0.006869 -0.219186 -0.304893 0 -0 0</pose>
      <inertial>
        <pose frame=''>-0.003379 -0.002011 -0.052794 0 -0 0</pose>
        <mass>0.351851</mass>
        <inertia>
          <ixx>0.00337969</ixx>
          <ixy>-9.39541e-06</ixy>
          <ixz>-8.0825e-05</ixz>
          <iyy>0.00328755</iyy>
          <iyz>9.6695e-05</iyz>
          <izz>0.000183306</izz>
        </inertia>
      </inertial>
      <collision name='RR_CALF_collision'>
        <pose frame=''>0 0 0 0 -0 0</pose>
        <geometry>
          <mesh>
            <scale>1 1 1</scale>
            <uri>model://PONGBOT_Q_V3/meshes/RR_CALF.STL</uri>
          </mesh>
        </geometry>
      </collision>
      <collision name='RR_CALF_fixed_joint_lump__RR_TIP_collision_1'>
        <pose frame=''>-0.022186 0.000805 -0.29413 0 -0 0</pose>
        <geometry>
          <mesh>
            <scale>1 1 1</scale>
            <uri>model://PONGBOT_Q_V3/meshes/RR_TIP.STL</uri>
          </mesh>
        </geometry>
      </collision>
      <visual name='RR_CALF_visual'>
        <pose frame=''>0 0 0 0 -0 0</pose>
        <geometry>
          <mesh>
            <scale>1 1 1</scale>
            <uri>model://PONGBOT_Q_V3/meshes/RR_CALF.STL</uri>
          </mesh>
        </geometry>
      </visual>
      <visual name='RR_CALF_fixed_joint_lump__RR_TIP_visual_1'>
        <pose frame=''>-0.022186 0.000805 -0.29413 0 -0 0</pose>
        <geometry>
          <mesh>
            <scale>1 1 1</scale>
            <uri>model://PONGBOT_Q_V3/meshes/RR_TIP.STL</uri>
          </mesh>
        </geometry>
      </visual>
    </link>
    <joint name='RR_KN_JOINT' type='revolute'>
      <child>RR_CALF</child>
      <parent>RR_THIGH</parent>
      <axis>
        <xyz>-0 1 0.002736</xyz>
        <limit>
          <lower>-1e+16</lower>
          <upper>1e+16</upper>
        </limit>
        <dynamics>
          <spring_reference>0</spring_reference>
          <spring_stiffness>0</spring_stiffness>
        </dynamics>
        <use_parent_model_frame>1</use_parent_model_frame>
      </axis>
    </joint>
    <link name='FRONT_BODY'>
      <pose frame=''>0.35 0 0.035866 0 -0 0</pose>
      <inertial>
        <pose frame=''>0.27411 7.8e-05 0.033559 0 -0 0</pose>
        <mass>7.0813</mass>
        <inertia>
          <ixx>0.09303</ixx>
          <ixy>-8.8354e-06</ixy>
          <ixz>-0.014229</ixz>
          <iyy>0.12083</iyy>
          <iyz>3.7596e-05</iyz>
          <izz>0.12082</izz>
        </inertia>
      </inertial>
      <collision name='FRONT_BODY_collision'>
        <pose frame=''>0 0 0 0 -0 0</pose>
        <geometry>
          <mesh>
            <scale>1 1 1</scale>
            <uri>model://PONGBOT_Q_V3/meshes/FRONT_BODY.STL</uri>
          </mesh>
        </geometry>
      </collision>
      <visual name='FRONT_BODY_visual'>
        <pose frame=''>0 0 0 0 -0 0</pose>
        <geometry>
          <mesh>
            <scale>1 1 1</scale>
            <uri>model://PONGBOT_Q_V3/meshes/FRONT_BODY.STL</uri>
          </mesh>
        </geometry>
      </visual>
    </link>
    <joint name='WAIST_JOINT' type='revolute'>
      <child>FRONT_BODY</child>
      <parent>REAR_BODY</parent>
      <axis>
        <xyz>-0 0 1</xyz>
        <limit>
          <lower>-1e+16</lower>
          <upper>1e+16</upper>
        </limit>
        <dynamics>
          <spring_reference>0</spring_reference>
          <spring_stiffness>0</spring_stiffness>
        </dynamics>
        <use_parent_model_frame>1</use_parent_model_frame>
      </axis>
    </joint>
    <link name='FL_HIP'>
      <pose frame=''>0.7 0.11502 0.000314 0 -0 0</pose>
      <inertial>
        <pose frame=''>0.001266 0.006091 -0.000287 0 -0 0</pose>
        <mass>0.82805</mass>
        <inertia>
          <ixx>0.0008886</ixx>
          <ixy>-2.7033e-05</ixy>
          <ixz>-1.5553e-05</ixz>
          <iyy>0.00098478</iyy>
          <iyz>1.4469e-05</iyz>
          <izz>0.0009908</izz>
        </inertia>
      </inertial>
      <collision name='FL_HIP_collision'>
        <pose frame=''>0 0 0 0 -0 0</pose>
        <geometry>
          <mesh>
            <scale>1 1 1</scale>
            <uri>model://PONGBOT_Q_V3/meshes/FL_HIP.STL</uri>
          </mesh>
        </geometry>
      </collision>
      <visual name='FL_HIP_visual'>
        <pose frame=''>0 0 0 0 -0 0</pose>
        <geometry>
          <mesh>
            <scale>1 1 1</scale>
            <uri>model://PONGBOT_Q_V3/meshes/FL_HIP.STL</uri>
          </mesh>
        </geometry>
      </visual>
    </link>
    <joint name='FL_HR_JOINT' type='revolute'>
      <child>FL_HIP</child>
      <parent>FRONT_BODY</parent>
      <axis>
        <xyz>-1 0 -0</xyz>
        <limit>
          <lower>-1e+16</lower>
          <upper>1e+16</upper>
        </limit>
        <dynamics>
          <spring_reference>0</spring_reference>
          <spring_stiffness>0</spring_stiffness>
        </dynamics>
        <use_parent_model_frame>1</use_parent_model_frame>
      </axis>
    </joint>
    <link name='FL_THIGH'>
      <pose frame=''>0.7 0.22002 0.000314 0 -0 0</pose>
      <inertial>
        <pose frame=''>4.2e-05 -0.012366 -0.037774 0 -0 0</pose>
        <mass>1.25</mass>
        <inertia>
          <ixx>0.0099526</ixx>
          <ixy>2.2641e-06</ixy>
          <ixz>-1.9948e-06</ixz>
          <iyy>0.010323</iyy>
          <iyz>0.00058392</iyz>
          <izz>0.0012967</izz>
        </inertia>
      </inertial>
      <collision name='FL_THIGH_collision'>
        <pose frame=''>0 0 0 0 -0 0</pose>
        <geometry>
          <mesh>
            <scale>1 1 1</scale>
            <uri>model://PONGBOT_Q_V3/meshes/FL_THIGH.STL</uri>
          </mesh>
        </geometry>
      </collision>
      <visual name='FL_THIGH_visual'>
        <pose frame=''>0 0 0 0 -0 0</pose>
        <geometry>
          <mesh>
            <scale>1 1 1</scale>
            <uri>model://PONGBOT_Q_V3/meshes/FL_THIGH.STL</uri>
          </mesh>
        </geometry>
      </visual>
    </link>
    <joint name='FL_HP_JOINT' type='revolute'>
      <child>FL_THIGH</child>
      <parent>FL_HIP</parent>
      <axis>
        <xyz>0 1 0</xyz>
        <limit>
          <lower>-1e+16</lower>
          <upper>1e+16</upper>
        </limit>
        <dynamics>
          <spring_reference>0</spring_reference>
          <spring_stiffness>0</spring_stiffness>
        </dynamics>
        <use_parent_model_frame>1</use_parent_model_frame>
      </axis>
    </joint>
    <link name='FL_CALF'>
      <pose frame=''>0.7 0.22002 -0.304686 0 -0 0</pose>
      <inertial>
        <pose frame=''>-0.002514 0.002149 -0.052851 0 -0 0</pose>
        <mass>0.351851</mass>
        <inertia>
          <ixx>0.00338161</ixx>
          <ixy>1.16651e-05</ixy>
          <ixz>-1.23383e-06</ixz>
          <iyy>0.00328741</iyy>
          <iyz>-8.84324e-05</iyz>
          <izz>0.000180256</izz>
        </inertia>
      </inertial>
      <collision name='FL_CALF_collision'>
        <pose frame=''>0 0 0 0 -0 0</pose>
        <geometry>
          <mesh>
            <scale>1 1 1</scale>
            <uri>model://PONGBOT_Q_V3/meshes/FL_CALF.STL</uri>
          </mesh>
        </geometry>
      </collision>
      <collision name='FL_CALF_fixed_joint_lump__FL_TIP_collision_1'>
        <pose frame=''>-0.015556 0 -0.29456 0 -0 0</pose>
        <geometry>
          <mesh>
            <scale>1 1 1</scale>
            <uri>model://PONGBOT_Q_V3/meshes/FL_TIP.STL</uri>
          </mesh>
        </geometry>
      </collision>
      <visual name='FL_CALF_visual'>
        <pose frame=''>0 0 0 0 -0 0</pose>
        <geometry>
          <mesh>
            <scale>1 1 1</scale>
            <uri>model://PONGBOT_Q_V3/meshes/FL_CALF.STL</uri>
          </mesh>
        </geometry>
      </visual>
      <visual name='FL_CALF_fixed_joint_lump__FL_TIP_visual_1'>
        <pose frame=''>-0.015556 0 -0.29456 0 -0 0</pose>
        <geometry>
          <mesh>
            <scale>1 1 1</scale>
            <uri>model://PONGBOT_Q_V3/meshes/FL_TIP.STL</uri>
          </mesh>
        </geometry>
      </visual>
    </link>
    <joint name='FL_KN_JOINT' type='revolute'>
      <child>FL_CALF</child>
      <parent>FL_THIGH</parent>
      <axis>
        <xyz>0 1 0</xyz>
        <limit>
          <lower>-1e+16</lower>
          <upper>1e+16</upper>
        </limit>
        <dynamics>
          <spring_reference>0</spring_reference>
          <spring_stiffness>0</spring_stiffness>
        </dynamics>
        <use_parent_model_frame>1</use_parent_model_frame>
      </axis>
    </joint>
    <link name='FR_HIP'>
      <pose frame=''>0.7 -0.11502 0.000314 0 -0 0</pose>
      <inertial>
        <pose frame=''>0.001266 -0.006091 0.000287 0 -0 0</pose>
        <mass>0.82805</mass>
        <inertia>
          <ixx>0.0008886</ixx>
          <ixy>2.7033e-05</ixy>
          <ixz>1.5553e-05</ixz>
          <iyy>0.00098478</iyy>
          <iyz>1.4469e-05</iyz>
          <izz>0.0009908</izz>
        </inertia>
      </inertial>
      <collision name='FR_HIP_collision'>
        <pose frame=''>0 0 0 0 -0 0</pose>
        <geometry>
          <mesh>
            <scale>1 1 1</scale>
            <uri>model://PONGBOT_Q_V3/meshes/FR_HIP.STL</uri>
          </mesh>
        </geometry>
      </collision>
      <visual name='FR_HIP_visual'>
        <pose frame=''>0 0 0 0 -0 0</pose>
        <geometry>
          <mesh>
            <scale>1 1 1</scale>
            <uri>model://PONGBOT_Q_V3/meshes/FR_HIP.STL</uri>
          </mesh>
        </geometry>
      </visual>
    </link>
    <joint name='FR_HR_JOINT' type='revolute'>
      <child>FR_HIP</child>
      <parent>FRONT_BODY</parent>
      <axis>
        <xyz>-1 0 -0</xyz>
        <limit>
          <lower>-1e+16</lower>
          <upper>1e+16</upper>
        </limit>
        <dynamics>
          <spring_reference>0</spring_reference>
          <spring_stiffness>0</spring_stiffness>
        </dynamics>
        <use_parent_model_frame>1</use_parent_model_frame>
      </axis>
    </joint>
    <link name='FR_THIGH'>
      <pose frame=''>0.7 -0.22002 0.000314 0 -0 0</pose>
      <inertial>
        <pose frame=''>-4.2e-05 0.012366 -0.037774 0 -0 0</pose>
        <mass>1.25</mass>
        <inertia>
          <ixx>0.0099526</ixx>
          <ixy>2.2641e-06</ixy>
          <ixz>1.9949e-06</ixz>
          <iyy>0.010323</iyy>
          <iyz>-0.00058392</iyz>
          <izz>0.0012967</izz>
        </inertia>
      </inertial>
      <collision name='FR_THIGH_collision'>
        <pose frame=''>0 0 0 0 -0 0</pose>
        <geometry>
          <mesh>
            <scale>1 1 1</scale>
            <uri>model://PONGBOT_Q_V3/meshes/FR_THIGH.STL</uri>
          </mesh>
        </geometry>
      </collision>
      <visual name='FR_THIGH_visual'>
        <pose frame=''>0 0 0 0 -0 0</pose>
        <geometry>
          <mesh>
            <scale>1 1 1</scale>
            <uri>model://PONGBOT_Q_V3/meshes/FR_THIGH.STL</uri>
          </mesh>
        </geometry>
      </visual>
    </link>
    <joint name='FR_HP_JOINT' type='revolute'>
      <child>FR_THIGH</child>
      <parent>FR_HIP</parent>
      <axis>
        <xyz>0 1 0</xyz>
        <limit>
          <lower>-1e+16</lower>
          <upper>1e+16</upper>
        </limit>
        <dynamics>
          <spring_reference>0</spring_reference>
          <spring_stiffness>0</spring_stiffness>
        </dynamics>
        <use_parent_model_frame>1</use_parent_model_frame>
      </axis>
    </joint>
    <link name='FR_CALF'>
      <pose frame=''>0.7 -0.22002 -0.304686 0 -0 0</pose>
      <inertial>
        <pose frame=''>-0.002135 -0.002153 -0.052852 0 -0 0</pose>
        <mass>0.351851</mass>
        <inertia>
          <ixx>0.00338171</ixx>
          <ixy>-1.16276e-05</ixy>
          <ixz>-3.96133e-06</ixz>
          <iyy>0.00328809</iyy>
          <iyz>8.81046e-05</iyz>
          <izz>0.000180869</izz>
        </inertia>
      </inertial>
      <collision name='FR_CALF_collision'>
        <pose frame=''>0 0 0 0 -0 0</pose>
        <geometry>
          <mesh>
            <scale>1 1 1</scale>
            <uri>model://PONGBOT_Q_V3/meshes/FR_CALF.STL</uri>
          </mesh>
        </geometry>
      </collision>
      <collision name='FR_CALF_fixed_joint_lump__FR_TIP_collision_1'>
        <pose frame=''>-0.015556 0 -0.29456 0 -0 0</pose>
        <geometry>
          <mesh>
            <scale>1 1 1</scale>
            <uri>model://PONGBOT_Q_V3/meshes/FR_TIP.STL</uri>
          </mesh>
        </geometry>
      </collision>
      <visual name='FR_CALF_visual'>
        <pose frame=''>0 0 0 0 -0 0</pose>
        <geometry>
          <mesh>
            <scale>1 1 1</scale>
            <uri>model://PONGBOT_Q_V3/meshes/FR_CALF.STL</uri>
          </mesh>
        </geometry>
      </visual>
      <visual name='FR_CALF_fixed_joint_lump__FR_TIP_visual_1'>
        <pose frame=''>-0.015556 0 -0.29456 0 -0 0</pose>
        <geometry>
          <mesh>
            <scale>1 1 1</scale>
            <uri>model://PONGBOT_Q_V3/meshes/FR_TIP.STL</uri>
          </mesh>
        </geometry>
      </visual>
    </link>
    <joint name='FR_KN_JOINT' type='revolute'>
      <child>FR_CALF</child>
      <parent>FR_THIGH</parent>
      <axis>
        <xyz>0 1 0</xyz>
        <limit>
          <lower>-1e+16</lower>
          <upper>1e+16</upper>
        </limit>
        <dynamics>
          <spring_reference>0</spring_reference>
          <spring_stiffness>0</spring_stiffness>
        </dynamics>
        <use_parent_model_frame>1</use_parent_model_frame>
      </axis>
    </joint>
  </model>
</sdf>
