<robot
  name="PONGBOT_Q_V3">
  <link
    name="REAR_BODY">
    <inertial>
      <origin
        xyz="0.10445 -0.00011862 0.02612"
        rpy="0 0 0" />
      <mass
        value="5.5101" />
      <inertia
        ixx="0.050447"
        ixy="-1.3727E-05"
        ixz="0.0033483"
        iyy="0.10139"
        iyz="-1.1894E-06"
        izz="0.12946" />
    </inertial>
    <visual>
      <origin
        xyz="0 0 0"
        rpy="0 0 0" />
      <geometry>
        <mesh
          filename="package://PONGBOT_Q_V3/meshes/REAR_BODY.STL" />
      </geometry>
      <material
        name="">
        <color
          rgba="0.89804 0.91765 0.92941 1" />
      </material>
    </visual>
    <collision>
      <origin
        xyz="0 0 0"
        rpy="0 0 0" />
      <geometry>
        <mesh
          filename="package://PONGBOT_Q_V3/meshes/REAR_BODY.STL" />
      </geometry>
    </collision>
  </link>
  <link
    name="FRONT_BODY">
    <inertial>
      <origin
        xyz="0.27411 7.8277E-05 0.033559"
        rpy="0 0 0" />
      <mass
        value="7.0813" />
      <inertia
        ixx="0.09303"
        ixy="-8.8354E-06"
        ixz="-0.014229"
        iyy="0.12083"
        iyz="3.7596E-05"
        izz="0.12082" />
    </inertial>
    <visual>
      <origin
        xyz="0 0 0"
        rpy="0 0 0" />
      <geometry>
        <mesh
          filename="package://PONGBOT_Q_V3/meshes/FRONT_BODY.STL" />
      </geometry>
      <material
        name="">
        <color
          rgba="1 0 0 1" />
      </material>
    </visual>
    <collision>
      <origin
        xyz="0 0 0"
        rpy="0 0 0" />
      <geometry>
        <mesh
          filename="package://PONGBOT_Q_V3/meshes/FRONT_BODY.STL" />
      </geometry>
    </collision>
  </link>
  <joint
    name="WAIST_JOINT"
    type="continuous">
    <origin
      xyz="0.35 0 0.035866"
      rpy="0 -8.3096E-33 0" />
    <parent
      link="REAR_BODY" />
    <child
      link="FRONT_BODY" />
    <axis
      xyz="0 0 1" />
  </joint>
  <link
    name="FL_HIP">
    <inertial>
      <origin
        xyz="0.0012658 0.0060912 -0.00028651"
        rpy="0 0 0" />
      <mass
        value="0.82805" />
      <inertia
        ixx="0.0008886"
        ixy="-2.7033E-05"
        ixz="-1.5553E-05"
        iyy="0.00098478"
        iyz="1.4469E-05"
        izz="0.0009908" />
    </inertial>
    <visual>
      <origin
        xyz="0 0 0"
        rpy="0 0 0" />
      <geometry>
        <mesh
          filename="package://PONGBOT_Q_V3/meshes/FL_HIP.STL" />
      </geometry>
      <material
        name="">
        <color
          rgba="0.75294 0.75294 0.75294 1" />
      </material>
    </visual>
    <collision>
      <origin
        xyz="0 0 0"
        rpy="0 0 0" />
      <geometry>
        <mesh
          filename="package://PONGBOT_Q_V3/meshes/FL_HIP.STL" />
      </geometry>
    </collision>
  </link>
  <joint
    name="FL_HR_JOINT"
    type="continuous">
    <origin
      xyz="0.35 0.11502 -0.035552"
      rpy="0 -8.3096E-33 0" />
    <parent
      link="FRONT_BODY" />
    <child
      link="FL_HIP" />
    <axis
      xyz="-1 0 0" />
  </joint>
  <link
    name="FL_THIGH">
    <inertial>
      <origin
        xyz="4.2486E-05 -0.012366 -0.037774"
        rpy="0 0 0" />
      <mass
        value="1.25" />
      <inertia
        ixx="0.0099526"
        ixy="2.2641E-06"
        ixz="-1.9948E-06"
        iyy="0.010323"
        iyz="0.00058392"
        izz="0.0012967" />
    </inertial>
    <visual>
      <origin
        xyz="0 0 0"
        rpy="0 0 0" />
      <geometry>
        <mesh
          filename="package://PONGBOT_Q_V3/meshes/FL_THIGH.STL" />
      </geometry>
      <material
        name="">
        <color
          rgba="0.6 0.6 0.6 1" />
      </material>
    </visual>
    <collision>
      <origin
        xyz="0 0 0"
        rpy="0 0 0" />
      <geometry>
        <mesh
          filename="package://PONGBOT_Q_V3/meshes/FL_THIGH.STL" />
      </geometry>
    </collision>
  </link>
  <joint
    name="FL_HP_JOINT"
    type="continuous">
    <origin
      xyz="0 0.105 0"
      rpy="0 -8.3096E-33 0" />
    <parent
      link="FL_HIP" />
    <child
      link="FL_THIGH" />
    <axis
      xyz="0 1 0" />
  </joint>
  <link
    name="FL_CALF">
    <inertial>
      <origin
        xyz="-0.0022059 0.0021865 -0.048548"
        rpy="0 0 0" />
      <mass
        value="0.34581" />
      <inertia
        ixx="0.0030083"
        ixy="1.1898E-05"
        ixz="2.5381E-05"
        iyy="0.0029123"
        iyz="-8.5179E-05"
        izz="0.00017792" />
    </inertial>
    <visual>
      <origin
        xyz="0 0 0"
        rpy="0 0 0" />
      <geometry>
        <mesh
          filename="package://PONGBOT_Q_V3/meshes/FL_CALF.STL" />
      </geometry>
      <material
        name="">
        <color
          rgba="0.22353 0.22353 0.22353 1" />
      </material>
    </visual>
    <collision>
      <origin
        xyz="0 0 0"
        rpy="0 0 0" />
      <geometry>
        <mesh
          filename="package://PONGBOT_Q_V3/meshes/FL_CALF.STL" />
      </geometry>
    </collision>
  </link>
  <joint
    name="FL_KN_JOINT"
    type="continuous">
    <origin
      xyz="0 0 -0.305"
      rpy="0 -8.3096E-33 0" />
    <parent
      link="FL_THIGH" />
    <child
      link="FL_CALF" />
    <axis
      xyz="0 1 0" />
  </joint>
  <link
    name="FL_TIP">
    <inertial>
      <origin
        xyz="-0.0045911 -9.992E-16 -0.0045911"
        rpy="0 0 0" />
      <mass
        value="0.0060412" />
      <inertia
        ixx="3.9614E-07"
        ixy="8.1496E-15"
        ixz="8.0767E-08"
        iyy="3.1538E-07"
        iyz="-8.1496E-15"
        izz="3.9614E-07" />
    </inertial>
    <visual>
      <origin
        xyz="0 0 0"
        rpy="0 0 0" />
      <geometry>
        <mesh
          filename="package://PONGBOT_Q_V3/meshes/FL_TIP.STL" />
      </geometry>
      <material
        name="">
        <color
          rgba="0.96863 0.031373 0 1" />
      </material>
    </visual>
    <collision>
      <origin
        xyz="0 0 0"
        rpy="0 0 0" />
      <geometry>
        <mesh
          filename="package://PONGBOT_Q_V3/meshes/FL_TIP.STL" />
      </geometry>
    </collision>
  </link>
  <joint
    name="FL_TIP_JOINT"
    type="fixed">
    <origin
      xyz="-0.015556 0 -0.29456"
      rpy="0 -8.3096E-33 0" />
    <parent
      link="FL_CALF" />
    <child
      link="FL_TIP" />
    <axis
      xyz="0 0 0" />
  </joint>
  <link
    name="FR_HIP">
    <inertial>
      <origin
        xyz="0.0012658 -0.0060912 0.00028651"
        rpy="0 0 0" />
      <mass
        value="0.82805" />
      <inertia
        ixx="0.0008886"
        ixy="2.7033E-05"
        ixz="1.5553E-05"
        iyy="0.00098478"
        iyz="1.4469E-05"
        izz="0.0009908" />
    </inertial>
    <visual>
      <origin
        xyz="0 0 0"
        rpy="0 0 0" />
      <geometry>
        <mesh
          filename="package://PONGBOT_Q_V3/meshes/FR_HIP.STL" />
      </geometry>
      <material
        name="">
        <color
          rgba="0.75294 0.75294 0.75294 1" />
      </material>
    </visual>
    <collision>
      <origin
        xyz="0 0 0"
        rpy="0 0 0" />
      <geometry>
        <mesh
          filename="package://PONGBOT_Q_V3/meshes/FR_HIP.STL" />
      </geometry>
    </collision>
  </link>
  <joint
    name="FR_HR_JOINT"
    type="continuous">
    <origin
      xyz="0.35 -0.11502 -0.035552"
      rpy="0 -8.3096E-33 0" />
    <parent
      link="FRONT_BODY" />
    <child
      link="FR_HIP" />
    <axis
      xyz="-1 0 0" />
  </joint>
  <link
    name="FR_THIGH">
    <inertial>
      <origin
        xyz="-4.2485E-05 0.012366 -0.037774"
        rpy="0 0 0" />
      <mass
        value="1.25" />
      <inertia
        ixx="0.0099526"
        ixy="2.2641E-06"
        ixz="1.9949E-06"
        iyy="0.010323"
        iyz="-0.00058392"
        izz="0.0012967" />
    </inertial>
    <visual>
      <origin
        xyz="0 0 0"
        rpy="0 0 0" />
      <geometry>
        <mesh
          filename="package://PONGBOT_Q_V3/meshes/FR_THIGH.STL" />
      </geometry>
      <material
        name="">
        <color
          rgba="0.75294 0.75294 0.75294 1" />
      </material>
    </visual>
    <collision>
      <origin
        xyz="0 0 0"
        rpy="0 0 0" />
      <geometry>
        <mesh
          filename="package://PONGBOT_Q_V3/meshes/FR_THIGH.STL" />
      </geometry>
    </collision>
  </link>
  <joint
    name="FR_HP_JOINT"
    type="continuous">
    <origin
      xyz="0 -0.105 0"
      rpy="0 -8.3096E-33 0" />
    <parent
      link="FR_HIP" />
    <child
      link="FR_THIGH" />
    <axis
      xyz="0 1 0" />
  </joint>
  <link
    name="FR_CALF">
    <inertial>
      <origin
        xyz="-0.0018204 -0.0021907 -0.048549"
        rpy="0 0 0" />
      <mass
        value="0.34581" />
      <inertia
        ixx="0.0030084"
        ixy="-1.1866E-05"
        ixz="2.3227E-05"
        iyy="0.0029129"
        iyz="8.4845E-05"
        izz="0.00017845" />
    </inertial>
    <visual>
      <origin
        xyz="0 0 0"
        rpy="0 0 0" />
      <geometry>
        <mesh
          filename="package://PONGBOT_Q_V3/meshes/FR_CALF.STL" />
      </geometry>
      <material
        name="">
        <color
          rgba="0.77647 0.75686 0.73725 1" />
      </material>
    </visual>
    <collision>
      <origin
        xyz="0 0 0"
        rpy="0 0 0" />
      <geometry>
        <mesh
          filename="package://PONGBOT_Q_V3/meshes/FR_CALF.STL" />
      </geometry>
    </collision>
  </link>
  <joint
    name="FR_KN_JOINT"
    type="continuous">
    <origin
      xyz="0 0 -0.305"
      rpy="0 -8.3096E-33 0" />
    <parent
      link="FR_THIGH" />
    <child
      link="FR_CALF" />
    <axis
      xyz="0 1 0" />
  </joint>
  <link
    name="FR_TIP">
    <inertial>
      <origin
        xyz="-0.0045911 -7.9381E-15 -0.0045911"
        rpy="0 0 0" />
      <mass
        value="0.0060412" />
      <inertia
        ixx="3.9614E-07"
        ixy="6.358E-15"
        ixz="8.0767E-08"
        iyy="3.1538E-07"
        iyz="-6.358E-15"
        izz="3.9614E-07" />
    </inertial>
    <visual>
      <origin
        xyz="0 0 0"
        rpy="0 0 0" />
      <geometry>
        <mesh
          filename="package://PONGBOT_Q_V3/meshes/FR_TIP.STL" />
      </geometry>
      <material
        name="">
        <color
          rgba="0.96863 0.031373 0 1" />
      </material>
    </visual>
    <collision>
      <origin
        xyz="0 0 0"
        rpy="0 0 0" />
      <geometry>
        <mesh
          filename="package://PONGBOT_Q_V3/meshes/FR_TIP.STL" />
      </geometry>
    </collision>
  </link>
  <joint
    name="FR_TIP_JOINT"
    type="fixed">
    <origin
      xyz="-0.015556 0 -0.29456"
      rpy="0 -8.3096E-33 0" />
    <parent
      link="FR_CALF" />
    <child
      link="FR_TIP" />
    <axis
      xyz="0 0 0" />
  </joint>
  <link
    name="RL_HIP">
    <inertial>
      <origin
        xyz="-0.0012658 0.0060904 0.00030318"
        rpy="0 0 0" />
      <mass
        value="0.82805" />
      <inertia
        ixx="0.0008886"
        ixy="2.7075E-05"
        ixz="-1.5479E-05"
        iyy="0.00098486"
        iyz="-1.4485E-05"
        izz="0.00099072" />
    </inertial>
    <visual>
      <origin
        xyz="0 0 0"
        rpy="0 0 0" />
      <geometry>
        <mesh
          filename="package://PONGBOT_Q_V3/meshes/RL_HIP.STL" />
      </geometry>
      <material
        name="">
        <color
          rgba="0.75294 0.75294 0.75294 1" />
      </material>
    </visual>
    <collision>
      <origin
        xyz="0 0 0"
        rpy="0 0 0" />
      <geometry>
        <mesh
          filename="package://PONGBOT_Q_V3/meshes/RL_HIP.STL" />
      </geometry>
    </collision>
  </link>
  <joint
    name="RL_HR_JOINT"
    type="continuous">
    <origin
      xyz="0 0.11502 0.00031464"
      rpy="0 -8.3096E-33 0" />
    <parent
      link="REAR_BODY" />
    <child
      link="RL_HIP" />
    <axis
      xyz="-1 0 0" />
  </joint>
  <link
    name="RL_THIGH">
    <inertial>
      <origin
        xyz="-0.00080826 -0.012263 -0.037799"
        rpy="0 0 0" />
      <mass
        value="1.25" />
      <inertia
        ixx="0.0099481"
        ixy="1.5953E-05"
        ixz="-0.00019685"
        iyy="0.010319"
        iyz="0.00060839"
        izz="0.0013045" />
    </inertial>
    <visual>
      <origin
        xyz="0 0 0"
        rpy="0 0 0" />
      <geometry>
        <mesh
          filename="package://PONGBOT_Q_V3/meshes/RL_THIGH.STL" />
      </geometry>
      <material
        name="">
        <color
          rgba="0.75294 0.75294 0.75294 1" />
      </material>
    </visual>
    <collision>
      <origin
        xyz="0 0 0"
        rpy="0 0 0" />
      <geometry>
        <mesh
          filename="package://PONGBOT_Q_V3/meshes/RL_THIGH.STL" />
      </geometry>
    </collision>
  </link>
  <joint
    name="RL_HP_JOINT"
    type="continuous">
    <origin
      xyz="0 0.105 0.00028723"
      rpy="0 -8.3096E-33 0" />
    <parent
      link="RL_HIP" />
    <child
      link="RL_THIGH" />
    <axis
      xyz="0 1 0.0027355" />
  </joint>
  <link
    name="RL_CALF">
    <inertial>
      <origin
        xyz="-0.0029373 0.0023154 -0.048489"
        rpy="0 0 0" />
      <mass
        value="0.34581" />
      <inertia
        ixx="0.0030078"
        ixy="1.0339E-05"
        ixz="-4.5919E-05"
        iyy="0.0029133"
        iyz="-7.8245E-05"
        izz="0.00017862" />
    </inertial>
    <visual>
      <origin
        xyz="0 0 0"
        rpy="0 0 0" />
      <geometry>
        <mesh
          filename="package://PONGBOT_Q_V3/meshes/RL_CALF.STL" />
      </geometry>
      <material
        name="">
        <color
          rgba="0.79216 0.81961 0.93333 1" />
      </material>
    </visual>
    <collision>
      <origin
        xyz="0 0 0"
        rpy="0 0 0" />
      <geometry>
        <mesh
          filename="package://PONGBOT_Q_V3/meshes/RL_CALF.STL" />
      </geometry>
    </collision>
  </link>
  <joint
    name="RL_KN_JOINT"
    type="continuous">
    <origin
      xyz="-0.0068692 0.00083411 -0.30492"
      rpy="0 -8.3096E-33 0" />
    <parent
      link="RL_THIGH" />
    <child
      link="RL_CALF" />
    <axis
      xyz="0 1 0.0027355" />
  </joint>
  <link
    name="RL_TIP">
    <inertial>
      <origin
        xyz="-0.0046933 1.2273E-05 -0.0044865"
        rpy="0 0 0" />
      <mass
        value="0.0060412" />
      <inertia
        ixx="3.9978E-07"
        ixy="-2.2071E-10"
        ixz="8.0685E-08"
        iyy="3.1538E-07"
        iyz="-2.1099E-10"
        izz="3.9251E-07" />
    </inertial>
    <visual>
      <origin
        xyz="0 0 0"
        rpy="0 0 0" />
      <geometry>
        <mesh
          filename="package://PONGBOT_Q_V3/meshes/RL_TIP.STL" />
      </geometry>
      <material
        name="">
        <color
          rgba="0.96863 0.031373 0 1" />
      </material>
    </visual>
    <collision>
      <origin
        xyz="0 0 0"
        rpy="0 0 0" />
      <geometry>
        <mesh
          filename="package://PONGBOT_Q_V3/meshes/RL_TIP.STL" />
      </geometry>
    </collision>
  </link>
  <joint
    name="RL_TIP_JOINT"
    type="fixed">
    <origin
      xyz="-0.022186 0.00080459 -0.29413"
      rpy="0 -8.3096E-33 0" />
    <parent
      link="RL_CALF" />
    <child
      link="RL_TIP" />
    <axis
      xyz="0 0 0" />
  </joint>
  <link
    name="RR_HIP">
    <inertial>
      <origin
        xyz="-0.0012658 -0.0060904 -0.00030318"
        rpy="0 0 0" />
      <mass
        value="0.82805" />
      <inertia
        ixx="0.0008886"
        ixy="-2.7075E-05"
        ixz="1.5479E-05"
        iyy="0.00098486"
        iyz="-1.4485E-05"
        izz="0.00099072" />
    </inertial>
    <visual>
      <origin
        xyz="0 0 0"
        rpy="0 0 0" />
      <geometry>
        <mesh
          filename="package://PONGBOT_Q_V3/meshes/RR_HIP.STL" />
      </geometry>
      <material
        name="">
        <color
          rgba="0.75294 0.75294 0.75294 1" />
      </material>
    </visual>
    <collision>
      <origin
        xyz="0 0 0"
        rpy="0 0 0" />
      <geometry>
        <mesh
          filename="package://PONGBOT_Q_V3/meshes/RR_HIP.STL" />
      </geometry>
    </collision>
  </link>
  <joint
    name="RR_HR_JOINT"
    type="continuous">
    <origin
      xyz="0 -0.11502 0.00031464"
      rpy="0 -8.3096E-33 0" />
    <parent
      link="REAR_BODY" />
    <child
      link="RR_HIP" />
    <axis
      xyz="-1 0 0" />
  </joint>
  <link
    name="RR_THIGH">
    <inertial>
      <origin
        xyz="-0.00089321 0.01247 -0.037729"
        rpy="0 0 0" />
      <mass
        value="1.25" />
      <inertia
        ixx="0.0099483"
        ixy="-1.036E-05"
        ixz="-0.00019293"
        iyy="0.010326"
        iyz="-0.00055914"
        izz="0.0012979" />
    </inertial>
    <visual>
      <origin
        xyz="0 0 0"
        rpy="0 0 0" />
      <geometry>
        <mesh
          filename="package://PONGBOT_Q_V3/meshes/RR_THIGH.STL" />
      </geometry>
      <material
        name="">
        <color
          rgba="0.89804 0.91765 0.92941 1" />
      </material>
    </visual>
    <collision>
      <origin
        xyz="0 0 0"
        rpy="0 0 0" />
      <geometry>
        <mesh
          filename="package://PONGBOT_Q_V3/meshes/RR_THIGH.STL" />
      </geometry>
    </collision>
  </link>
  <joint
    name="RR_HP_JOINT"
    type="continuous">
    <origin
      xyz="0 -0.105 -0.00028723"
      rpy="0 -8.3096E-33 0" />
    <parent
      link="RR_HIP" />
    <child
      link="RR_THIGH" />
    <axis
      xyz="0 1 0.0027355" />
  </joint>
  <link
    name="RR_CALF">
    <inertial>
      <origin
        xyz="-0.0029687 -0.0020599 -0.0485"
        rpy="0 0 0" />
      <mass
        value="0.34581" />
      <inertia
        ixx="0.0030078"
        ixy="-9.8036E-06"
        ixz="-4.5397E-05"
        iyy="0.0029124"
        iyz="9.2423E-05"
        izz="0.00017947" />
    </inertial>
    <visual>
      <origin
        xyz="0 0 0"
        rpy="0 0 0" />
      <geometry>
        <mesh
          filename="package://PONGBOT_Q_V3/meshes/RR_CALF.STL" />
      </geometry>
      <material
        name="">
        <color
          rgba="0.77647 0.75686 0.73725 1" />
      </material>
    </visual>
    <collision>
      <origin
        xyz="0 0 0"
        rpy="0 0 0" />
      <geometry>
        <mesh
          filename="package://PONGBOT_Q_V3/meshes/RR_CALF.STL" />
      </geometry>
    </collision>
  </link>
  <joint
    name="RR_KN_JOINT"
    type="continuous">
    <origin
      xyz="-0.0068692 0.00083411 -0.30492"
      rpy="0 -8.3096E-33 0" />
    <parent
      link="RR_THIGH" />
    <child
      link="RR_CALF" />
    <axis
      xyz="0 1 0.0027355" />
  </joint>
  <link
    name="RR_TIP">
    <inertial>
      <origin
        xyz="-0.0046933 1.2273E-05 -0.0044865"
        rpy="0 0 0" />
      <mass
        value="0.0060412" />
      <inertia
        ixx="3.9978E-07"
        ixy="-2.2072E-10"
        ixz="8.0685E-08"
        iyy="3.1538E-07"
        iyz="-2.1098E-10"
        izz="3.9251E-07" />
    </inertial>
    <visual>
      <origin
        xyz="0 0 0"
        rpy="0 0 0" />
      <geometry>
        <mesh
          filename="package://PONGBOT_Q_V3/meshes/RR_TIP.STL" />
      </geometry>
      <material
        name="">
        <color
          rgba="0.96863 0.031373 0 1" />
      </material>
    </visual>
    <collision>
      <origin
        xyz="0 0 0"
        rpy="0 0 0" />
      <geometry>
        <mesh
          filename="package://PONGBOT_Q_V3/meshes/RR_TIP.STL" />
      </geometry>
    </collision>
  </link>
  <joint
    name="RR_TIP_JOINT"
    type="fixed">
    <origin
      xyz="-0.022186 0.00080459 -0.29413"
      rpy="0 -8.3096E-33 0" />
    <parent
      link="RR_CALF" />
    <child
      link="RR_TIP" />
    <axis
      xyz="0 0 0" />
  </joint>
</robot>