<robot
  name="PONGBOT_Q_V4">
  <link
    name="REAR_BODY">
    <inertial>
      <origin
        xyz="-0.2381 0 -0.000797"
        rpy="0 0 0" />
      <mass
        value="13.826" />
      <inertia
        ixx="0.15296"
        ixy="0.002196"
        ixz="-0.059602"
        iyy="0.2894"
        iyz="-0.000828"
        izz="0.2996" />
    </inertial>
    <visual>
      <origin
        xyz="0 0 0"
        rpy="0 0 0" />
      <geometry>
        <mesh
          filename="package://PONGBOT_Q_V4/meshes/REAR_BODY.STL" />
      </geometry>
      <material
        name="">
        <color
          rgba="0.89804 0.91765 0.92941 1" />
      </material>
    </visual>
    <collision>
      <origin
        xyz="0 0 0"
        rpy="0 0 0" />
      <geometry>
        <mesh
          filename="package://PONGBOT_Q_V4/meshes/REAR_BODY.STL" />
      </geometry>
    </collision>
  </link>
  <link
    name="FRONT_BODY">
    <inertial>
      <origin
        xyz="0.225 0 -0.0227"
        rpy="0 0 0" />
      <mass
        value="10.507" />
      <inertia
        ixx="0.091333"
        ixy="0"
        ixz="0.00107"
        iyy="0.1341"
        iyz="0"
        izz="0.1877" />
    </inertial>
    <visual>
      <origin
        xyz="0 0 0"
        rpy="0 0 0" />
      <geometry>
        <mesh
          filename="package://PONGBOT_Q_V4/meshes/FRONT_BODY.STL" />
      </geometry>
      <material
        name="">
        <color
          rgba="1 0 0 1" />
      </material>
    </visual>
    <collision>
      <origin
        xyz="0 0 0"
        rpy="0 0 0" />
      <geometry>
        <mesh
          filename="package://PONGBOT_Q_V4/meshes/FRONT_BODY.STL" />
      </geometry>
    </collision>
  </link>
  <joint
    name="WAIST_JOINT"
    type="continuous">
    <origin
      xyz="0 0 0"
      rpy="0 0 0" />
    <parent
      link="REAR_BODY" />
    <child
      link="FRONT_BODY" />
    <axis
      xyz="0 0 1" />
  </joint>
  <link
    name="FL_HIP">
    <inertial>
      <origin
        xyz="0.001233 0.002933 0.000569"
        rpy="0 0 0" />
      <mass
        value="1.4" />
      <inertia
        ixx="0.001121"
        ixy="0"
        ixz="0"
        iyy="0.0011635"
        iyz="0"
        izz="0.001228" />
    </inertial>
    <visual>
      <origin
        xyz="0 0 0"
        rpy="0 0 0" />
      <geometry>
        <mesh
          filename="package://PONGBOT_Q_V4/meshes/FL_HIP.STL" />
      </geometry>
      <material
        name="">
        <color
          rgba="0.75294 0.75294 0.75294 1" />
      </material>
    </visual>
    <collision>
      <origin
        xyz="0 0 0"
        rpy="0 0 0" />
      <geometry>
        <mesh
          filename="package://PONGBOT_Q_V4/meshes/FL_HIP.STL" />
      </geometry>
    </collision>
  </link>
  <joint
    name="FL_HR_JOINT"
    type="continuous">
    <origin
      xyz="0.35 0.11502 -0.053052"
      rpy="0 0 0" />
    <parent
      link="FRONT_BODY" />
    <child
      link="FL_HIP" />
    <axis
      xyz="1 0 0" />
  </joint>
  <link
    name="FL_THIGH">
    <inertial>
      <origin
        xyz="0.000151 -0.011407 -0.01871"
        rpy="0 0 0" />
      <mass
        value="3.209" />
      <inertia
        ixx="0.0179"
        ixy="0"
        ixz="0"
        iyy="0.0178"
        iyz="-0.0011"
        izz="0.00422" />
    </inertial>
    <visual>
      <origin
        xyz="0 0 0"
        rpy="0 0 0" />
      <geometry>
        <mesh
          filename="package://PONGBOT_Q_V4/meshes/FL_THIGH.STL" />
      </geometry>
      <material
        name="">
        <color
          rgba="0.6 0.6 0.6 1" />
      </material>
    </visual>
    <collision>
      <origin
        xyz="0 0 0"
        rpy="0 0 0" />
      <geometry>
        <mesh
          filename="package://PONGBOT_Q_V4/meshes/FL_THIGH.STL" />
      </geometry>
    </collision>
  </link>
  <joint
    name="FL_HP_JOINT"
    type="continuous">
    <origin
      xyz="0 0.1045 0"
      rpy="0 0 0" />
    <parent
      link="FL_HIP" />
    <child
      link="FL_THIGH" />
    <axis
      xyz="0 1 0" />
  </joint>
  <link
    name="FL_CALF">
    <inertial>
      <origin
        xyz="0.042069 -0.002971 -0.093214"
        rpy="0 0 0" />
      <mass
        value="0.634" />
      <inertia
        ixx="0.0064"
        ixy="5E-05"
        ixz="-0.00173"
        iyy="0.00783"
        iyz="-0.000115"
        izz="0.00178" />
    </inertial>
    <visual>
      <origin
        xyz="0 0 0"
        rpy="0 0 0" />
      <geometry>
        <mesh
          filename="package://PONGBOT_Q_V4/meshes/FL_CALF.STL" />
      </geometry>
      <material
        name="">
        <color
          rgba="0.79216 0.81961 0.93333 1" />
      </material>
    </visual>
    <collision>
      <origin
        xyz="0 0 0"
        rpy="0 0 0" />
      <geometry>
        <mesh
          filename="package://PONGBOT_Q_V4/meshes/FL_CALF.STL" />
      </geometry>
    </collision>
  </link>
  <joint
    name="FL_KN_JOINT"
    type="continuous">
    <origin
      xyz="0 0 -0.305"
      rpy="0 0 0" />
    <parent
      link="FL_THIGH" />
    <child
      link="FL_CALF" />
    <axis
      xyz="0 1 0" />
  </joint>
  <link
    name="FR_HIP">
    <inertial>
      <origin
        xyz="0.001233 -0.002933 -0.000569"
        rpy="0 0 0" />
      <mass
        value="1.4" />
      <inertia
        ixx="0.001121"
        ixy="0"
        ixz="0"
        iyy="0.001635"
        iyz="0"
        izz="0.001228" />
    </inertial>
    <visual>
      <origin
        xyz="0 0 0"
        rpy="0 0 0" />
      <geometry>
        <mesh
          filename="package://PONGBOT_Q_V4/meshes/FR_HIP.STL" />
      </geometry>
      <material
        name="">
        <color
          rgba="0.75294 0.75294 0.75294 1" />
      </material>
    </visual>
    <collision>
      <origin
        xyz="0 0 0"
        rpy="0 0 0" />
      <geometry>
        <mesh
          filename="package://PONGBOT_Q_V4/meshes/FR_HIP.STL" />
      </geometry>
    </collision>
  </link>
  <joint
    name="FR_HR_JOINT"
    type="continuous">
    <origin
      xyz="0.35 -0.11502 -0.053052"
      rpy="0 0 0" />
    <parent
      link="FRONT_BODY" />
    <child
      link="FR_HIP" />
    <axis
      xyz="1 0 0" />
  </joint>
  <link
    name="FR_THIGH">
    <inertial>
      <origin
        xyz="-0.000151 0.011407 -0.01871"
        rpy="0 0 0" />
      <mass
        value="3.209" />
      <inertia
        ixx="0.0179"
        ixy="0"
        ixz="0"
        iyy="0.0178"
        iyz="0.0011"
        izz="0.00422" />
    </inertial>
    <visual>
      <origin
        xyz="0 0 0"
        rpy="0 0 0" />
      <geometry>
        <mesh
          filename="package://PONGBOT_Q_V4/meshes/FR_THIGH.STL" />
      </geometry>
      <material
        name="">
        <color
          rgba="0.6 0.6 0.6 1" />
      </material>
    </visual>
    <collision>
      <origin
        xyz="0 0 0"
        rpy="0 0 0" />
      <geometry>
        <mesh
          filename="package://PONGBOT_Q_V4/meshes/FR_THIGH.STL" />
      </geometry>
    </collision>
  </link>
  <joint
    name="FR_HP_JOINT"
    type="continuous">
    <origin
      xyz="0 -0.1045 0"
      rpy="0 0 0" />
    <parent
      link="FR_HIP" />
    <child
      link="FR_THIGH" />
    <axis
      xyz="0 1 0" />
  </joint>
  <link
    name="FR_CALF">
    <inertial>
      <origin
        xyz="0.04204 0.002971 -0.093214"
        rpy="0 0 0" />
      <mass
        value="0.634" />
      <inertia
        ixx="0.0064"
        ixy="-5E-05"
        ixz="-0.00173"
        iyy="0.00783"
        iyz="0.000115"
        izz="0.00178" />
    </inertial>
    <visual>
      <origin
        xyz="0 0 0"
        rpy="0 0 0" />
      <geometry>
        <mesh
          filename="package://PONGBOT_Q_V4/meshes/FR_CALF.STL" />
      </geometry>
      <material
        name="">
        <color
          rgba="0.89804 0.91765 0.92941 1" />
      </material>
    </visual>
    <collision>
      <origin
        xyz="0 0 0"
        rpy="0 0 0" />
      <geometry>
        <mesh
          filename="package://PONGBOT_Q_V4/meshes/FR_CALF.STL" />
      </geometry>
    </collision>
  </link>
  <joint
    name="FR_KN_JOINT"
    type="continuous">
    <origin
      xyz="0 0 -0.305"
      rpy="0 0 0" />
    <parent
      link="FR_THIGH" />
    <child
      link="FR_CALF" />
    <axis
      xyz="0 1 0" />
  </joint>
  <link
    name="RL_HIP">
    <inertial>
      <origin
        xyz="-0.001233 -0.002933 -0.000569"
        rpy="0 0 0" />
      <mass
        value="1.4" />
      <inertia
        ixx="0.001133"
        ixy="0"
        ixz="0"
        iyy="0.001638"
        iyz="0"
        izz="0.001243" />
    </inertial>
    <visual>
      <origin
        xyz="0 0 0"
        rpy="0 0 0" />
      <geometry>
        <mesh
          filename="package://PONGBOT_Q_V4/meshes/RL_HIP.STL" />
      </geometry>
      <material
        name="">
        <color
          rgba="0.75294 0.75294 0.75294 1" />
      </material>
    </visual>
    <collision>
      <origin
        xyz="0 0 0"
        rpy="0 0 0" />
      <geometry>
        <mesh
          filename="package://PONGBOT_Q_V4/meshes/RL_HIP.STL" />
      </geometry>
    </collision>
  </link>
  <joint
    name="RL_HR_JOINT"
    type="continuous">
    <origin
      xyz="-0.35 0.11502 -0.053052"
      rpy="0 0 0" />
    <parent
      link="REAR_BODY" />
    <child
      link="RL_HIP" />
    <axis
      xyz="1 0 0" />
  </joint>
  <link
    name="RL_THIGH">
    <inertial>
      <origin
        xyz="0.000151 -0.011407 -0.01871"
        rpy="0 0 0" />
      <mass
        value="3.209" />
      <inertia
        ixx="0.0179"
        ixy="0"
        ixz="0"
        iyy="0.0178"
        iyz="-0.0011"
        izz="0.003409" />
    </inertial>
    <visual>
      <origin
        xyz="0 0 0"
        rpy="0 0 0" />
      <geometry>
        <mesh
          filename="package://PONGBOT_Q_V4/meshes/RL_THIGH.STL" />
      </geometry>
      <material
        name="">
        <color
          rgba="0.6 0.6 0.6 1" />
      </material>
    </visual>
    <collision>
      <origin
        xyz="0 0 0"
        rpy="0 0 0" />
      <geometry>
        <mesh
          filename="package://PONGBOT_Q_V4/meshes/RL_THIGH.STL" />
      </geometry>
    </collision>
  </link>
  <joint
    name="RL_HP_JOINT"
    type="continuous">
    <origin
      xyz="0 0.1045 0"
      rpy="0 0 0" />
    <parent
      link="RL_HIP" />
    <child
      link="RL_THIGH" />
    <axis
      xyz="0 1 0" />
  </joint>
  <link
    name="RL_CALF">
    <inertial>
      <origin
        xyz="0.04204 -0.002971 -0.093214"
        rpy="0 0 0" />
      <mass
        value="0.634" />
      <inertia
        ixx="0.0064"
        ixy="5E-05"
        ixz="-0.00173"
        iyy="0.00783"
        iyz="-0.000115"
        izz="0.00178" />
    </inertial>
    <visual>
      <origin
        xyz="0 0 0"
        rpy="0 0 0" />
      <geometry>
        <mesh
          filename="package://PONGBOT_Q_V4/meshes/RL_CALF.STL" />
      </geometry>
      <material
        name="">
        <color
          rgba="0.79216 0.81961 0.93333 1" />
      </material>
    </visual>
    <collision>
      <origin
        xyz="0 0 0"
        rpy="0 0 0" />
      <geometry>
        <mesh
          filename="package://PONGBOT_Q_V4/meshes/RL_CALF.STL" />
      </geometry>
    </collision>
  </link>
  <joint
    name="RL_KN_JOINT"
    type="continuous">
    <origin
      xyz="0 0 -0.305"
      rpy="0 0 0" />
    <parent
      link="RL_THIGH" />
    <child
      link="RL_CALF" />
    <axis
      xyz="0 1 0" />
  </joint>
  <link
    name="RR_HIP">
    <inertial>
      <origin
        xyz="-0.001233 0.002933 0.000569"
        rpy="0 0 0" />
      <mass
        value="1.4" />
      <inertia
        ixx="0.001133"
        ixy="0"
        ixz="0"
        iyy="0.001638"
        iyz="0"
        izz="0.001243" />
    </inertial>
    <visual>
      <origin
        xyz="0 0 0"
        rpy="0 0 0" />
      <geometry>
        <mesh
          filename="package://PONGBOT_Q_V4/meshes/RR_HIP.STL" />
      </geometry>
      <material
        name="">
        <color
          rgba="0.75294 0.75294 0.75294 1" />
      </material>
    </visual>
    <collision>
      <origin
        xyz="0 0 0"
        rpy="0 0 0" />
      <geometry>
        <mesh
          filename="package://PONGBOT_Q_V4/meshes/RR_HIP.STL" />
      </geometry>
    </collision>
  </link>
  <joint
    name="RR_HR_JOINT"
    type="continuous">
    <origin
      xyz="-0.35 -0.11502 -0.053052"
      rpy="0 0 0" />
    <parent
      link="REAR_BODY" />
    <child
      link="RR_HIP" />
    <axis
      xyz="1 0 0" />
  </joint>
  <link
    name="RR_THIGH">
    <inertial>
      <origin
        xyz="-0.000151 0.011407 -0.01871"
        rpy="0 0 0" />
      <mass
        value="3.209" />
      <inertia
        ixx="0.0179"
        ixy="0"
        ixz="0"
        iyy="0.0178"
        iyz="0.0011"
        izz="0.003409" />
    </inertial>
    <visual>
      <origin
        xyz="0 0 0"
        rpy="0 0 0" />
      <geometry>
        <mesh
          filename="package://PONGBOT_Q_V4/meshes/RR_THIGH.STL" />
      </geometry>
      <material
        name="">
        <color
          rgba="0.6 0.6 0.6 1" />
      </material>
    </visual>
    <collision>
      <origin
        xyz="0 0 0"
        rpy="0 0 0" />
      <geometry>
        <mesh
          filename="package://PONGBOT_Q_V4/meshes/RR_THIGH.STL" />
      </geometry>
    </collision>
  </link>
  <joint
    name="RR_HP_JOINT"
    type="continuous">
    <origin
      xyz="0 -0.1045 0"
      rpy="0 0 0" />
    <parent
      link="RR_HIP" />
    <child
      link="RR_THIGH" />
    <axis
      xyz="0 1 0" />
  </joint>
  <link
    name="RR_CALF">
    <inertial>
      <origin
        xyz="0.04204 0.0002971 -0.093214"
        rpy="0 0 0" />
      <mass
        value="0.634" />
      <inertia
        ixx="0.0064"
        ixy="-5E-05"
        ixz="-0.00173"
        iyy="0.00783"
        iyz="0.000115"
        izz="0.00178" />
    </inertial>
    <visual>
      <origin
        xyz="0 0 0"
        rpy="0 0 0" />
      <geometry>
        <mesh
          filename="package://PONGBOT_Q_V4/meshes/RR_CALF.STL" />
      </geometry>
      <material
        name="">
        <color
          rgba="0.89804 0.91765 0.92941 1" />
      </material>
    </visual>
    <collision>
      <origin
        xyz="0 0 0"
        rpy="0 0 0" />
      <geometry>
        <mesh
          filename="package://PONGBOT_Q_V4/meshes/RR_CALF.STL" />
      </geometry>
    </collision>
  </link>
  <joint
    name="RR_KN_JOINT"
    type="continuous">
    <origin
      xyz="0 0 -0.305"
      rpy="0 0 0" />
    <parent
      link="RR_THIGH" />
    <child
      link="RR_CALF" />
    <axis
      xyz="0 1 0" />
  </joint>
</robot>
