<robot
  name="PONGBOT_LEG">
  <link
    name="thigh">
    <inertial>
      <origin
        xyz="0 -0.0162 -0.0264"
        rpy="0 0 0" />
      <mass
        value="1.8748" />
      <inertia
        ixx="0.0112"
        ixy="0"
        ixz="0"
        iyy="0.0117"
        iyz="-0.0008"
        izz="0.0017" />
    </inertial>
    <visual>
      <origin
        xyz="0 0 0"
        rpy="0 0 0" />
      <geometry>
        <mesh
          filename="package://PONGBOT_LEG/meshes/thigh.STL" />
      </geometry>
      <material
        name="">
        <color
          rgba="0.89804 0.91765 0.92941 1" />
      </material>
    </visual>
    <collision>
      <origin
        xyz="0 0 0"
        rpy="0 0 0" />
      <geometry>
        <mesh
          filename="package://PONGBOT_LEG/meshes/thigh.STL" />
      </geometry>
    </collision>
  </link>
  <link
    name="rotator1">
    <inertial>
      <origin
        xyz="0.0021 -0.0028 -0.0058"
        rpy="0 0 0" />
      <mass
        value="0.072" />
      <inertia
        ixx="0.0001"
        ixy="0"
        ixz="0"
        iyy="0.0001"
        iyz="0"
        izz="0" />
    </inertial>
    <visual>
      <origin
        xyz="0 0 0"
        rpy="0 0 0" />
      <geometry>
        <mesh
          filename="package://PONGBOT_LEG/meshes/rotator1.STL" />
      </geometry>
      <material
        name="">
        <color
          rgba="0.89804 0.91765 0.92941 1" />
      </material>
    </visual>
    <collision>
      <origin
        xyz="0 0 0"
        rpy="0 0 0" />
      <geometry>
        <mesh
          filename="package://PONGBOT_LEG/meshes/rotator1.STL" />
      </geometry>
    </collision>
  </link>
  <joint
    name="rotator1_joint"
    type="continuous">
    <origin
      xyz="0 0.02765 0"
      rpy="0 -1.1221E-46 0" />
    <parent
      link="thigh" />
    <child
      link="rotator1" />
    <axis
      xyz="0 1 0" />
  </joint>
  <link
    name="rotator2">
    <inertial>
      <origin
        xyz="0 0 -0.1525"
        rpy="0 0 0" />
      <mass
        value="0.2047" />
      <inertia
        ixx="0.0018"
        ixy="0"
        ixz="0"
        iyy="0.0018"
        iyz="0"
        izz="0" />
    </inertial>
    <visual>
      <origin
        xyz="0 0 0"
        rpy="0 0 0" />
      <geometry>
        <mesh
          filename="package://PONGBOT_LEG/meshes/rotator2.STL" />
      </geometry>
      <material
        name="">
        <color
          rgba="0.64706 0.61961 0.58824 1" />
      </material>
    </visual>
    <collision>
      <origin
        xyz="0 0 0"
        rpy="0 0 0" />
      <geometry>
        <mesh
          filename="package://PONGBOT_LEG/meshes/rotator2.STL" />
      </geometry>
    </collision>
  </link>
  <joint
    name="rotator2_joint"
    type="continuous">
    <origin
      xyz="0.017101 0.00685 -0.046985"
      rpy="0 -1.1221E-46 0" />
    <parent
      link="rotator1" />
    <child
      link="rotator2" />
    <axis
      xyz="0 1 0" />
  </joint>
  <link
    name="rotator3">
    <inertial>
      <origin
        xyz="-0.0183 -0.0326 -0.0427"
        rpy="0 0 0" />
      <mass
        value="0.402" />
      <inertia
        ixx="0.0052"
        ixy="0"
        ixz="0.0002"
        iyy="0.0051"
        iyz="0"
        izz="0.0002" />
    </inertial>
    <visual>
      <origin
        xyz="0 0 0"
        rpy="0 0 0" />
      <geometry>
        <mesh
          filename="package://PONGBOT_LEG/meshes/rotator3.STL" />
      </geometry>
      <material
        name="">
        <color
          rgba="0.75294 0.75294 0.75294 1" />
      </material>
    </visual>
    <collision>
      <origin
        xyz="0 0 0"
        rpy="0 0 0" />
      <geometry>
        <mesh
          filename="package://PONGBOT_LEG/meshes/rotator3.STL" />
      </geometry>
    </collision>
  </link>
  <joint
    name="rotator3_joint"
    type="continuous">
    <origin
      xyz="0 0 -0.305"
      rpy="0 -1.1221E-46 0" />
    <parent
      link="rotator2" />
    <child
      link="rotator3" />
    <axis
      xyz="0 1 0" />
  </joint>
</robot>